Workbook

Sheet README
A1: WHITE RUST OF MUSTARD - EXPECTED-VALUE (SIMULATION) MODEL
A2: IARI New Delhi, rabi 2025-26 | 4 sowing dates x 3 varieties | assessments 11/02, 24/02, 03/03, 13/03/2026
A4: STATUS OF THESE NUMBERS: SIMULATED / EXPECTED VALUES - NOT MEASURED DATA
A5: All values are model outputs built from published baselines, white-rust and analogous-disease effect sizes, the IARI 2025-26 daily weather, your DAS/GDD/phenology and your sampling leaf. Use them as hypotheses, expected ranges, priors for sanity-checking field data, synthetic data for testing analysis/ML pipelines, and as the 'expected' column when you discuss your results. Do NOT report them in the thesis as observations. Where your measured data exist, they replace these values.
A7: HOW THE MODEL WORKS
A8: 1. Healthy value (same treatment, date, stage, leaf) = reference value x stage factor x (1 - heat sensitivity x heat index h) x variety factor [x cold-legacy factor for anthocyanin]. LAI uses a GDD-driven canopy curve.
A9: 2. Diseased value = Healthy x (1 + R(s) x variety tolerance x lesion-age factor), where s = disease index (fraction) and R(s) is the parameter's severity-response curve (Response_Table).
A10: 3. Range = values at the lower and upper DI limit of the class, widened by +/- 1.645 x CV (approx. 90% interval) for plant-to-plant and assay variability.
A11: 4. E (transpiration) = gs x leaf-to-air VPD / P, using the measurement-time VPD from the weather of the 7 days to the assessment date, plus extra cuticular loss through ruptured pustules.
A12: 5. Thermal parameters come from an energy-balance CWSI logic: CWSI = 1 - (1 - CWSI_healthy) x E_diseased / E_healthy, Tc = Twet + CWSI x (Tdry - Twet), with Twet/Tdry baselines from flight-time air temperature and VPD.
A14: SHEETS
A15: Inputs_General - all global assumptions (blue = editable input).
... A34: - The 11/02 assessment is 6 days after inoculation; any visible disease then most likely comes from natural infection during the favourable spell of 18 Dec-4 Feb (see Weather flags).

Sheet Inputs_General
A1: GLOBAL INPUTS (blue cells on yellow are editable assumptions)
A3: Key | B3: Assumption | C3: Value | D3: Unit | E3: Basis / source
A4: Tbase | B4: Base temperature for GDD | C4: 5 | D4: deg C | E4: Rana et al. 2017 (Nanda et al. 1996) base 5 C for B. juncea
A5: EmergGDD | B5: GDD from sowing to emergence | C5: 110 | D5: deg C d | E5: Rana et al. 2017: 100-125 GDD
A6: Inoc | B6: Inoculation date | C6: 46058 | D6: date | E6: User: all treatments inoculated on 05/02/2026
A7: HeatThr | B7: Heat-index threshold (weekly mean Tmax) | C7: 27 | D7: deg C | E7: Assumption: above ~27 C Tmax late-sown mustard shows heat stress
A8: HeatSpan | B8: Heat-index span (Tmax rise giving h = 1) | C8: 8 | D8: deg C | E8: Assumption: h = (Tmax_wk - 27)/8, so h ~ 1 at 35 C
A9: fMeas | B9: Fraction of diurnal T range at IRGA time (~10:30-11:30 h) | C9: 0.8 | D9: - | E9: Assumption for leaf-to-air VPD at gas-exchange time
A10: gMeas | B10: Weight of morning RH at IRGA time | C10: 0.3 | D10: - | E10: RH_meas = RH II + g x (RH I - RH II)
A11: fFlight | B11: Fraction of diurnal T range at UAV thermal flight (~12:30 h) | C11: 0.9 | D11: - | E11: Flights 11:00-14:00 per review draft
A12: gFlight | B12: Weight of morning RH at flight time | C12: 0.15 | D12: -
A13: Patm | B13: Atmospheric pressure, New Delhi (~216 m asl) | C13: 99.3 | D13: kPa | E13: Standard atmosphere at 216 m
A14: a_wet | B14: Non-water-stressed baseline intercept (Tc - Ta at VPD = 0) | C14: 1 | D14: deg C | E14: Idso-type NWSB: Tc - Ta = a - b x VPD
A15: b_wet | B15: Non-water-stressed baseline slope | C15: 1.9 | D15: deg C/kPa | E15: Typical crop NWSB slopes 1.5-2.2 C/kPa
A16: dT_dry | B16: Upper (non-transpiring) baseline: Tdry - Ta | C16: 4 | D16: deg C | E16: Typical 3-5 C under midday radiation
A17: CWSI_V | B17: Healthy-canopy CWSI, vegetative | C17: 0.12 | D17: - | E17: Irrigated, transpiring canopy
A18: CWSI_F | B18: Healthy-canopy CWSI, flowering | C18: 0.2 | D18: - | E18: Yellow petals raise canopy temperature
A19: CWSI_P | B19: Healthy-canopy CWSI, pod formation | C19: 0.3 | D19: - | E19: Senescing lower canopy, pods
A20: CWSI_heat | B20: Extra healthy CWSI per unit heat index h | C20: 0.05 | D20: -
A21: Cuticle | B21: Extra water loss through ruptured pustules (fraction per unit s) | C21: 0.25 | D21: - | E21: Field-crop review: rust pustule rupture can raise cuticular loss
A22: z | B22: z for range (90% interval) | C22: 1.645 | D22: -
A23: TcSD0 | B23: Within-plot canopy-temperature SD, healthy | C23: 0.6 | D23: deg C | E23: Assumption for 2-cm FLIR pixels
A24: TcSDslope | B24: Increase of within-plot Tc SD per unit s | C24: 2 | D24: deg C | E24: Patchy lesions raise thermal heterogeneity
A25: gsVPDm | B25: Stomatal sensitivity to VPD: gs = gs_ref x (VPD/VPDref)^-m | C25: 0.5 | D25: - | E25: Leuning/Oren-type response; m ~0.5 for C3 crops
A26: VPDref | B26: Reference VPD for gs reference value | C26: 1 | D26: kPa | E26: gs reference value applies at ~1 kPa
A27: G50 | B27: LAI curve: GDD (from emergence) at half of LAImax | C27: 330 | D27: deg C d | E27: Calibrated so canopy closes near flowering
A28: Gscale | B28: LAI curve: logistic scale | C28: 100 | D28: deg C d
A29: Gdecl | B29: LAI decline starts (GDD from emergence) | C29: 800 | D29: deg C d | E29: Around pod initiation (Rana et al. 2017: 685-816)
A30: Gdeclsc | B30: LAI decline scale | C30: 300 | D30: deg C d

Sheet Inputs_Treatments
A1: TREATMENT INPUTS (blue on yellow = editable)
A3: Sowing | B3: Sowing date | C3: LAImax healthy | D3: Exposure factor (expected DI) | E3: Anth cold factor 11/02 | F3: Anth cold factor 24/02 | G3: Anth cold factor 03/03 | H3: Anth cold factor 13/03 | I3: Note
A4: D1 | B4: 46000 | C4: 3.4 | D4: 1 | E4: 1 | F4: 1 | G4: 1 | H4: 1 | I4: Sown 09/12/2025 (ORW slide 11 says 08/12 - DAS table fits 09/12). Inoculated at 58 DAS; >=36 DAS from 14 Jan inside the favourable spell
A5: D2 | B5: 46009 | C5: 3.2 | D5: 0.9 | E5: 1.05 | F5: 1 | G5: 1 | H5: 1 | I5: Inoculated at 49 DAS; >=36 DAS from 23 Jan
A6: D3 | B6: 46018 | C6: 2.9 | D6: 0.75 | E6: 1.2 | F6: 1.05 | G6: 1 | H6: 1 | I6: Inoculated at 40 DAS; leaves formed in Jan cold spell
A7: D4 | B7: 46031 | C7: 2.5 | D7: 0.6 | E7: 1.4 | F7: 1.15 | G7: 1 | H7: 1 | I7: Inoculated at 27 DAS; emerged during 10-17 Jan cold (Tmin 1.6-4 C) -> cold-induced anthocyanin in young leaves
A10: Variety
A11: Variety | B11: Name | C11: Reported reaction | D11: Tolerance factor on R(s) | E11: Susceptibility (expected DI) | F11: LAI factor | G11: Basis
A12: V1 | B12: Pusa Mustard 26 | C12: Susceptible (PDI 44.4) | D12: 1 | E12: 0.8 | F12: 0.95 | G12: Shrivastava et al. 2023. Early-maturing: flowered first in your phenology table
A13: V2 | B13: Pusa Vijay | C13: Highly susceptible (PDI 55.6) | D13: 1.1 | E13: 1 | F13: 1 | G13: Shrivastava et al. 2023
A14: V3 | B14: Pusa Mustard 37 | C14: Moderately resistant (UNVERIFIED) | D14: 0.85 | E14: 0.5 | F14: 1 | G14: Label from ORW slide 27; no verified source yet - treat as assumption
A17: Assessment dates
A18: Date code | B18: Date | C18: Reference expected DI (V2 x D1) | D18: Basis
A19: 11/02/2026 | B19: 46064 | C19: 3 | D19: 6 DAI: before the 8-13 d incubation of inoculated infections; only natural pre-inoculation infection visible
A20: 24/02/2026 | B20: 46077 | C20: 18 | D20: 19 DAI: first inoculated cycle sporulated; borderline-favourable week after inoculation
A21: 03/03/2026 | B21: 46084 | C21: 28 | D21: 26 DAI: secondary cycle limited by dry, warm weather (no favourable days after 5 Feb)
A22: 13/03/2026 | B22: 46094 | C22: 35 | D22: 36 DAI: near plateau; onset-to-peak ~40 d (Singh M. et al. 2024); heat (Tmax ~35 C) halts spread
A24: Expected DI = reference DI (date) x variety susceptibility x sowing exposure. It is a scenario only; overwrite column C or the factors with your observed plot DI when available.

Sheet Parameters
A1: PARAMETER BASELINES, MODIFIERS AND SEVERITY-RESPONSE COEFFICIENTS (blue on yellow = editable)
I2: Healthy-value modifiers | P2: Severity-response curve R(s) | X2: Lesion-age factor by date (damage lag behind sporulation; Chou et al. 2000)
A3: Code | B3: Parameter | C3: Unit | D3: Method | E3: Reference healthy value | F3: CV | G3: Ref range low | H3: Ref range high | I3: Stage factor V (3rd leaf) | J3: Stage factor F (5th leaf) | K3: Stage factor P (5th leaf) | L3: Heat sensitivity | M3: Variety factor V1 | N3: Variety factor V2 | O3: Variety factor V3 | P3: Response type | Q3: Sign | R3: Rmax | S3: k | T3: Logistic centre | U3: Logistic scale | V3: Hump amplitude | W3: Hump peak s | X3: 11/02/2026 | Y3: 24/02/2026 | Z3: 03/03/2026 | AA3: 13/03/2026 | AB3: Evidence level | AC3: Basis / sources
A4: RWC | B4: Relative water content | C4: % | D4: Dehydration & imbibition (Barrs & Weatherley 1962) | E4: 86 | F4: 0.04 | G4: 82 | H4: 90 | I4: 1 | J4: 0.99 | K4: 0.95 | L4: 0.05 | M4: 1 | N4: 1 | O4: 1 | P4: logistic | Q4: -1 | R4: 0.3 | S4: 0 | T4: 0.35 | U4: 0.12 | V4: 0 | W4: 0 | X4: 0.5 | Y4: 1 | Z4: 1 | AA4: 1 | AB4: E4 + E3 | AC4: Healthy 86% at flowering (Jobner field study, RGN-229); 85% max (PLOS ONE 2021 K study). Threshold decline once pustules rupture epidermis (mechanism); your ASD SWIR spectra showed lower water in diseased leaves on 03/03 and 13/03.
A5: MSI | B5: Membrane stability index | C5: % | D5: Electrolyte leakage (Sairam 1994) | E5: 72 | F5: 0.07 | G5: 62 | H5: 78 | I5: 1 | J5: 0.98 | K5: 0.92 | L5: 0.12 | M5: 1 | N5: 1 | O5: 1 | P5: logistic | Q5: -1 | R5: 0.7 | S5: 0 | T5: 0.28 | U5: 0.1 | V5: 0 | W5: 0 | X5: 0.5 | Y5: 1 | Z5: 1 | AA5: 1 | AB5: E4 + E3 | AC5: Healthy ~72% (similar-experiment HR class; PLOS ONE 2021: 57-73%). Late, steep collapse at high severity (similar-experiment S class 66 -> 31 -> 14%); heat lowers MSI independently.
A6: Pn | B6: Net photosynthetic rate | C6: umol CO2 m-2 s-1 | D6: LI-6400 | E6: 19 | F6: 0.12 | G6: 15 | H6: 24 | I6: 1 | J6: 1 | K6: 0.85 | L6: 0.12 | M6: 1 | N6: 1 | O6: 1.03 | P6: exp | Q6: -1 | R6: 0.75 | S6: 4.4 | T6: 0 | U6: 0 | V6: 0 | W6: 0 | X6: 0.8 | Y6: 1 | Z6: 1 | AA6: 1 | AB6: E2 + E3 | AC6: Healthy 15-20 (similar-experiment HR), 18-31 (Plants 2025, green B. juncea). Chou et al. 2000: whole-leaf A fell to 30% of control by 14 DAI (~30% leaf colonised); decline is non-stomatal.
A7: gs | B7: Stomatal conductance | C7: mol H2O m-2 s-1 | D7: LI-6400 | E7: 0.45 | F7: 0.18 | G7: 0.3 | H7: 0.65 | I7: 1 | J7: 1 | K7: 0.85 | L7: 0 | M7: 1 | N7: 1 | O7: 1 | P7: exp | Q7: -1 | R7: 0.65 | S7: 3 | T7: 0 | U7: 0 | V7: 0 | W7: 0 | X7: 0.8 | Y7: 1 | Z7: 1 | AA7: 1 | AB7: E2(indirect) + E3 | AC7: Healthy 0.38-0.52 (similar-experiment HR); 0.62-0.85 in pots (Plants 2025). Healthy gs declines with VPD (gs_ref x (VPD/1 kPa)^-0.5, Inputs_General). Chou et al. 2000: transpiration unchanged at 8 DAI, so gs declines later and less steeply than Pn.
A8: E | B8: Transpiration rate | C8: mmol H2O m-2 s-1 | D8: LI-6400 (derived: gs x VPD / P) | E8: 0 | F8: 0.18 | G8: 2 | H8: 7 | I8: 1 | J8: 1 | K8: 1 | L8: 0 | M8: 1 | N8: 1 | O8: 1 | P8: derived | Q8: 0 | R8: 0 | S8: 0 | T8: 0 | U8: 0 | V8: 0 | W8: 0 | X8: 0.8 | Y8: 1 | Z8: 1 | AA8: 1 | AB8: Physics + E3 | AC8: E = gs x leaf-to-air VPD / P (LI-6400 relation); extra cuticular loss through ruptured pustules. Similar-experiment HR values 4.0-6.6 rising with VPD through the season.
A9: Ci | B9: Intercellular CO2 (extra, from LI-6400) | C9: umol mol-1 | D9: LI-6400 | E9: 285 | F9: 0.06 | G9: 270 | H9: 320 | I9: 1 | J9: 1 | K9: 1.03 | L9: 0 | M9: 1 | N9: 1 | O9: 1 | P9: exp | Q9: 1 | R9: 0.3 | S9: 4 | T9: 0 | U9: 0 | V9: 0 | W9: 0 | X9: 0.8 | Y9: 1 | Z9: 1 | AA9: 1 | AB9: E3 | AC9: Healthy ~285 (similar-experiment HR). Ci rises while gs falls = non-stomatal limitation (Tatagiba et al. 2015; similar-experiment S class +27%). Not in your list but recorded by the LI-6400 - report it.
A10: LAI | B10: Leaf area index | C10: m2 m-2 | D10: Canopy analyser | E10: 0 | F10: 0.12 | G10: 0.3 | H10: 4 | I10: 1 | J10: 1 | K10: 1 | L10: 0 | M10: 1 | N10: 1 | O10: 1 | P10: exp | Q10: -1 | R10: 0.45 | S10: 2.5 | T10: 0 | U10: 0 | V10: 0 | W10: 0 | X10: 0.5 | Y10: 1 | Z10: 1 | AA10: 1 | AB10: E4 | AC10: Healthy LAI from GDD canopy curve and LAImax per sowing (Inputs_Treatments). Disease: premature senescence and defoliation (Bal & Kumar 2014: total defoliation in unsprayed plots at PDI ~70).
A11: ChlA | B11: Chlorophyll a | C11: ug mg-1 FW (= mg g-1 FW) | D11: DMSO (Wellburn 1994) | E11: 1.25 | F11: 0.1 | G11: 1 | H11: 1.6 | I11: 0.95 | J11: 1 | K11: 0.85 | L11: 0.06 | M11: 1 | N11: 1 | O11: 1.03 | P11: exp | Q11: -1 | R11: 0.65 | S11: 3.2 | T11: 0 | U11: 0 | V11: 0 | W11: 0 | X11: 0.5 | Y11: 1 | Z11: 1 | AA11: 1 | AB11: E1(qual) + E2 | AC11: Total chl 0.86-1.75 mg g-1 FW in B. juncea leaves at 45-65 DAS (phytojournal 2019). Chou et al. 2000: chl stable to 12 DAI then -60% in invaded tissue by 14 DAI. Rai et al. 2024: higher in resistant NIL.
A12: ChlB | B12: Chlorophyll b | C12: ug mg-1 FW (= mg g-1 FW) | D12: DMSO (Wellburn 1994) | E12: 0.45 | F12: 0.12 | G12: 0.35 | H12: 0.6 | I12: 0.95 | J12: 1 | K12: 0.88 | L12: 0.06 | M12: 1 | N12: 1 | O12: 1.03 | P12: exp | Q12: -1 | R12: 0.55 | S12: 3 | T12: 0 | U12: 0 | V12: 0 | W12: 0 | X12: 0.5 | Y12: 1 | Z12: 1 | AA12: 1 | AB12: E1(indirect) + E2 | AC12: a:b ~2.8 in healthy leaves. Chou et al. 2000: both a and b lost. DMSO can overestimate chl b (Quercus study) - use one extraction protocol throughout.
A13: Car | B13: Carotenoids | C13: mg g-1 FW | D13: Spectrophotometric (Wellburn 1994 DMSO eq.) | E13: 0.3 | F13: 0.12 | G13: 0.22 | H13: 0.45 | I13: 0.95 | J13: 1 | K13: 0.9 | L13: 0.03 | M13: 1 | N13: 1 | O13: 1.03 | P13: hump | Q13: -1 | R13: 0.4 | S13: 3 | T13: 0 | U13: 0 | V13: 0.1 | W13: 0.1 | X13: 0.5 | Y13: 1 | Z13: 1 | AA13: 1 | AB13: E1(qual) + E3 | AC13: Rai et al. 2024: carotenoids ROSE continuously 0-96 hpi in the susceptible line; field-crop review: Car/Chl rises at intermediate severity. Modelled as small early rise then decline.
A14: Anth | B14: Anthocyanin | C14: ug g-1 FW (cyanidin-3-glucoside eq.) | D14: pH differential (Lee et al. 2005) | E14: 15 | F14: 0.3 | G14: 5 | H14: 35 | I14: 1.1 | J14: 1 | K14: 1.15 | L14: 0 | M14: 1 | N14: 1 | O14: 1 | P14: exp | Q14: 1 | R14: 0.6 | S14: 3 | T14: 0 | U14: 0 | V14: 0 | W14: 0 | X14: 0.5 | Y14: 1 | Z14: 1 | AA14: 1 | AB14: E4 (speculative) | AC14: No white-rust data at any level. Green B. juncea leaves: anthocyanins near detection limit (PMC4992693). Rise assumed from stress/phenylpropanoid induction (field-crop review); cold (Jan) and senescence also raise it.
A15: Prot | B15: Total soluble protein | C15: ug mg-1 FW | D15: Bradford (1976), colorimetric | E15: 10 | F15: 0.12 | G15: 6 | H15: 15 | I15: 1.08 | J15: 1 | K15: 0.82 | L15: 0.06 | M15: 1.04 | N15: 1.08 | O15: 1 | P15: exp | Q15: -1 | R15: 0.15 | S15: 3 | T15: 0 | U15: 0 | V15: 0 | W15: 0 | X15: 0.5 | Y15: 1 | Z15: 1 | AA15: 1 | AB15: E1 | AC15: Mishra et al. 2009: inoculated leaves 4-10% lower than uninoculated in all 6 genotypes; susceptible genotypes have higher constitutive protein (variety factors). Conversion from %DW (Lowry) to Bradford FW basis is approximate.
A17: Response types: exp: R = sign x Rmax x (1 - exp(-k s)); logistic: R = sign x Rmax x (L(s) - L(0)) / (1 - L(0)), L(s) = 1/(1 + exp(-(s - centre)/scale)); hump: exp decline plus A x (s/peak) x exp(1 - s/peak). s = disease index as a fraction (0.18 = 18%).
A18: Evidence levels: E1 direct white rust on B. juncea; E2 A. candida on another host (Arabidopsis); E3 other Brassica / foliar pathogen; E4 mechanism or abiotic analogue only.
A19: Units: ug mg-1 FW is numerically identical to mg g-1 FW (chlorophyll, protein).

Sheet Severity_Classes
A1: DISEASE-INDEX CLASSES (plot DI = sum(x f) / (n sum f) x 100, n = 9, Bisht/AICRP 0-9 scale)
A3: Class | B3: DI range (%) | C3: s low | D3: s mid | E3: s high | F3: Class index
A4: Healthy | B4: 0 | C4: 0 | D4: 0 | E4: 0 | F4: 1
A5: Very low | B5: 1-5 | C5: 0.01 | D5: 0.03 | E5: 0.05 | F5: 2
A6: Low | B6: 6-10 | C6: 0.06 | D6: 0.08 | E6: 0.1 | F6: 3
A7: Moderate | B7: 11-25 | C7: 0.11 | D7: 0.18 | E7: 0.25 | F7: 4
A8: High | B8: 26-50 | C8: 0.26 | D8: 0.38 | E8: 0.5 | F8: 5
A9: Very high | B9: >50 | C9: 0.51 | D9: 0.65 | E9: 0.85 | F9: 6
A11: s = DI as a fraction. Mid values are used for the mean; low/high values bound the range. The sampled leaf is assumed to carry the plot-mean severity (ORW slide 23: leaves closest to plot-mean DI). The 'Very high' upper limit is capped at 85% because leaves beyond that are usually shed.

Sheet Response_Table
A1: RELATIVE CHANGE R(s) vs HEALTHY (before variety tolerance and lesion-age factors). -0.25 = 25% lower than healthy.
A3: Key | B3: Class | C3: Point | D3: s | E3: RWC | F3: MSI | G3: Pn | H3: gs | I3: Ci | J3: LAI | K3: ChlA | L3: ChlB | M3: Car | N3: Anth | O3: Prot
A4: =B4&"|"&C4 -> Healthy|low | B4: Healthy | C4: low | D4: =Severity_Classes!$C$4 -> 0 | E4: =IF(Parameters!$P$4="logistic",Parameters!$Q$4*Parameters!$R$4*((1/(1+EXP(-($D4-Parameters!$T$4)/Parameters!$U$4)))-(1/(1+EXP(Parameters!$T$4/Parameters!$U$4))))/(1-(1/(1+EXP(Parameters!$T$4/Parameters!$U$4)))),Parameters!$Q$4*Parameters!$R$4*(1-EXP(-Parameters!$S$4*$D4))+IF(Parameters!$P$4="hump",Parameters!$V$4*($D4/Parameters!$W$4)*EXP(1-$D4/Parameters!$W$4),0)) -> 0 | F4: =IF(Parameters!$P$5="logistic",Parameters!$Q$5*Parameters!$R$5*((1/(1+EXP(-($D4-Parameters!$T$5)/Parameters!$U$5)))-(1/(1+EXP(Parameters!$T$5/Parameters!$U$5))))/(1-(1/(1+EXP(Parameters!$T$5/Parameters!$U$5)))),Parameters!$Q$5*Parameters!$R$5*(1-EXP(-Parameters!$S$5*$D4))+IF(Parameters!$P$5="hump",Parameters!$V$5*($D4/Parameters!$W$5)*EXP(1-$D4/Parameters!$W$5),0)) -> 0 | G4: =IF(Parameters!$P$6="logistic",Parameters!$Q$6*Parameters!$R$6*((1/(1+EXP(-($D4-Parameters!$T$6)/Parameters!$U$6)))-(1/(1+EXP(Parameters!$T$6/Parameters!$U$6))))/(1-(1/(1+EXP(Parameters!$T$6/Parameters!$U$6)))),Parameters!$Q$6*Parameters!$R$6*(1-EXP(-Parameters!$S$6*$D4))+IF(Parameters!$P$6="hump",Parameters!$V$6*($D4/Parameters!$W$6)*EXP(1-$D4/Parameters!$W$6),0)) -> 0 | H4: =IF(Parameters!$P$7="logistic",Parameters!$Q$7*Parameters!$R$7*((1/(1+EXP(-($D4-Parameters!$T$7)/Parameters!$U$7)))-(1/(1+EXP(Parameters!$T$7/Parameters!$U$7))))/(1-(1/(1+EXP(Parameters!$T$7/Parameters!$U$7)))),Parameters!$Q$7*Parameters!$R$7*(1-EXP(-Parameters!$S$7*$D4))+IF(Parameters!$P$7="hump",Parameters!$V$7*($D4/Parameters!$W$7)*EXP(1-$D4/Parameters!$W$7),0)) -> 0 | I4: =IF(Parameters!$P$9="logistic",Parameters!$Q$9*Parameters!$R$9*((1/(1+EXP(-($D4-Parameters!$T$9)/Parameters!$U$9)))-(1/(1+EXP(Parameters!$T$9/Parameters!$U$9))))/(1-(1/(1+EXP(Parameters!$T$9/Parameters!$U$9)))),Parameters!$Q$9*Parameters!$R$9*(1-EXP(-Parameters!$S$9*$D4))+IF(Parameters!$P$9="hump",Parameters!$V$9*($D4/Parameters!$W$9)*EXP(1-$D4/Parameters!$W$9),0)) -> 0 | J4: =IF(Parameters!$P$10="logistic",Parameters!$Q$10*Parameters!$R$10*((1/(1+EXP(-($D4-Parameters!$T$10)/Parameters!$U$10)))-(1/(1+EXP(Parameters!$T$10/Parameters!$U$10))))/(1-(1/(1+EXP(Parameters!$T$10/Parameters!$U$10)))),Parameters!$Q$10*Parameters!$R$10*(1-EXP(-Parameters!$S$10*$D4))+IF(Parameters!$P$10="hump",Parameters!$V$10*($D4/Parameters!$W$10)*EXP(1-$D4/Parameters!$W$10),0)) -> 0 | K4: =IF(Parameters!$P$11="logistic",Parameters!$Q$11*Parameters!$R$11*((1/(1+EXP(-($D4-Parameters!$T$11)/Parameters!$U$11)))-(1/(1+EXP(Parameters!$T$11/Parameters!$U$11))))/(1-(1/(1+EXP(Parameters!$T$11/Parameters!$U$11)))),Parameters!$Q$11*Parameters!$R$11*(1-EXP(-Parameters!$S$11*$D4))+IF(Parameters!$P$11="hump",Parameters!$V$11*($D4/Parameters!$W$11)*EXP(1-$D4/Parameters!$W$11),0)) -> 0 | L4: =IF(Parameters!$P$12="logistic",Parameters!$Q$12*Parameters!$R$12*((1/(1+EXP(-($D4-Parameters!$T$12)/Parameters!$U$12)))-(1/(1+EXP(Parameters!$T$12/Parameters!$U$12))))/(1-(1/(1+EXP(Parameters!$T$12/Parameters!$U$12)))),Parameters!$Q$12*Parameters!$R$12*(1-EXP(-Parameters!$S$12*$D4))+IF(Parameters!$P$12="hump",Parameters!$V$12*($D4/Parameters!$W$12)*EXP(1-$D4/Parameters!$W$12),0)) -> 0 | M4: =IF(Parameters!$P$13="logistic",Parameters!$Q$13*Parameters!$R$13*((1/(1+EXP(-($D4-Parameters!$T$13)/Parameters!$U$13)))-(1/(1+EXP(Parameters!$T$13/Parameters!$U$13))))/(1-(1/(1+EXP(Parameters!$T$13/Parameters!$U$13)))),Parameters!$Q$13*Parameters!$R$13*(1-EXP(-Parameters!$S$13*$D4))+IF(Parameters!$P$13="hump",Parameters!$V$13*($D4/Parameters!$W$13)*EXP(1-$D4/Parameters!$W$13),0)) -> 0 | N4: =IF(Parameters!$P$14="logistic",Parameters!$Q$14*Parameters!$R$14*((1/(1+EXP(-($D4-Parameters!$T$14)/Parameters!$U$14)))-(1/(1+EXP(Parameters!$T$14/Parameters!$U$14))))/(1-(1/(1+EXP(Parameters!$T$14/Parameters!$U$14)))),Parameters!$Q$14*Parameters!$R$14*(1-EXP(-Parameters!$S$14*$D4))+IF(Parameters!$P$14="hump",Parameters!$V$14*($D4/Parameters!$W$14)*EXP(1-$D4/Parameters!$W$14),0)) -> 0 | O4: =IF(Parameters!$P$15="logistic",Parameters!$Q$15*Parameters!$R$15*((1/(1+EXP(-($D4-Parameters!$T$15)/Parameters!$U$15)))-(1/(1+EXP(Parameters!$T$15/Parameters!$U$15))))/(1-(1/(1+EXP(Parameters!$T$15/Parameters!$U$15)))),Parameters!$Q$15*Parameters!$R$15*(1-EXP(-Parameters!$S$15*$D4))+IF(Parameters!$P$15="hump",Parameters!$V$15*($D4/Parameters!$W$15)*EXP(1-$D4/Parameters!$W$15),0)) -> 0
A5: =B5&"|"&C5 -> Healthy|mid | B5: Healthy | C5: mid | D5: =Severity_Classes!$D$4 -> 0 | E5: =IF(Parameters!$P$4="logistic",Parameters!$Q$4*Parameters!$R$4*((1/(1+EXP(-($D5-Parameters!$T$4)/Parameters!$U$4)))-(1/(1+EXP(Parameters!$T$4/Parameters!$U$4))))/(1-(1/(1+EXP(Parameters!$T$4/Parameters!$U$4)))),Parameters!$Q$4*Parameters!$R$4*(1-EXP(-Parameters!$S$4*$D5))+IF(Parameters!$P$4="hump",Parameters!$V$4*($D5/Parameters!$W$4)*EXP(1-$D5/Parameters!$W$4),0)) -> 0 | F5: =IF(Parameters!$P$5="logistic",Parameters!$Q$5*Parameters!$R$5*((1/(1+EXP(-($D5-Parameters!$T$5)/Parameters!$U$5)))-(1/(1+EXP(Parameters!$T$5/Parameters!$U$5))))/(1-(1/(1+EXP(Parameters!$T$5/Parameters!$U$5)))),Parameters!$Q$5*Parameters!$R$5*(1-EXP(-Parameters!$S$5*$D5))+IF(Parameters!$P$5="hump",Parameters!$V$5*($D5/Parameters!$W$5)*EXP(1-$D5/Parameters!$W$5),0)) -> 0 | G5: =IF(Parameters!$P$6="logistic",Parameters!$Q$6*Parameters!$R$6*((1/(1+EXP(-($D5-Parameters!$T$6)/Parameters!$U$6)))-(1/(1+EXP(Parameters!$T$6/Parameters!$U$6))))/(1-(1/(1+EXP(Parameters!$T$6/Parameters!$U$6)))),Parameters!$Q$6*Parameters!$R$6*(1-EXP(-Parameters!$S$6*$D5))+IF(Parameters!$P$6="hump",Parameters!$V$6*($D5/Parameters!$W$6)*EXP(1-$D5/Parameters!$W$6),0)) -> 0 | H5: =IF(Parameters!$P$7="logistic",Parameters!$Q$7*Parameters!$R$7*((1/(1+EXP(-($D5-Parameters!$T$7)/Parameters!$U$7)))-(1/(1+EXP(Parameters!$T$7/Parameters!$U$7))))/(1-(1/(1+EXP(Parameters!$T$7/Parameters!$U$7)))),Parameters!$Q$7*Parameters!$R$7*(1-EXP(-Parameters!$S$7*$D5))+IF(Parameters!$P$7="hump",Parameters!$V$7*($D5/Parameters!$W$7)*EXP(1-$D5/Parameters!$W$7),0)) -> 0 | I5: =IF(Parameters!$P$9="logistic",Parameters!$Q$9*Parameters!$R$9*((1/(1+EXP(-($D5-Parameters!$T$9)/Parameters!$U$9)))-(1/(1+EXP(Parameters!$T$9/Parameters!$U$9))))/(1-(1/(1+EXP(Parameters!$T$9/Parameters!$U$9)))),Parameters!$Q$9*Parameters!$R$9*(1-EXP(-Parameters!$S$9*$D5))+IF(Parameters!$P$9="hump",Parameters!$V$9*($D5/Parameters!$W$9)*EXP(1-$D5/Parameters!$W$9),0)) -> 0 | J5: =IF(Parameters!$P$10="logistic",Parameters!$Q$10*Parameters!$R$10*((1/(1+EXP(-($D5-Parameters!$T$10)/Parameters!$U$10)))-(1/(1+EXP(Parameters!$T$10/Parameters!$U$10))))/(1-(1/(1+EXP(Parameters!$T$10/Parameters!$U$10)))),Parameters!$Q$10*Parameters!$R$10*(1-EXP(-Parameters!$S$10*$D5))+IF(Parameters!$P$10="hump",Parameters!$V$10*($D5/Parameters!$W$10)*EXP(1-$D5/Parameters!$W$10),0)) -> 0 | K5: =IF(Parameters!$P$11="logistic",Parameters!$Q$11*Parameters!$R$11*((1/(1+EXP(-($D5-Parameters!$T$11)/Parameters!$U$11)))-(1/(1+EXP(Parameters!$T$11/Parameters!$U$11))))/(1-(1/(1+EXP(Parameters!$T$11/Parameters!$U$11)))),Parameters!$Q$11*Parameters!$R$11*(1-EXP(-Parameters!$S$11*$D5))+IF(Parameters!$P$11="hump",Parameters!$V$11*($D5/Parameters!$W$11)*EXP(1-$D5/Parameters!$W$11),0)) -> 0 | L5: =IF(Parameters!$P$12="logistic",Parameters!$Q$12*Parameters!$R$12*((1/(1+EXP(-($D5-Parameters!$T$12)/Parameters!$U$12)))-(1/(1+EXP(Parameters!$T$12/Parameters!$U$12))))/(1-(1/(1+EXP(Parameters!$T$12/Parameters!$U$12)))),Parameters!$Q$12*Parameters!$R$12*(1-EXP(-Parameters!$S$12*$D5))+IF(Parameters!$P$12="hump",Parameters!$V$12*($D5/Parameters!$W$12)*EXP(1-$D5/Parameters!$W$12),0)) -> 0 | M5: =IF(Parameters!$P$13="logistic",Parameters!$Q$13*Parameters!$R$13*((1/(1+EXP(-($D5-Parameters!$T$13)/Parameters!$U$13)))-(1/(1+EXP(Parameters!$T$13/Parameters!$U$13))))/(1-(1/(1+EXP(Parameters!$T$13/Parameters!$U$13)))),Parameters!$Q$13*Parameters!$R$13*(1-EXP(-Parameters!$S$13*$D5))+IF(Parameters!$P$13="hump",Parameters!$V$13*($D5/Parameters!$W$13)*EXP(1-$D5/Parameters!$W$13),0)) -> 0 | N5: =IF(Parameters!$P$14="logistic",Parameters!$Q$14*Parameters!$R$14*((1/(1+EXP(-($D5-Parameters!$T$14)/Parameters!$U$14)))-(1/(1+EXP(Parameters!$T$14/Parameters!$U$14))))/(1-(1/(1+EXP(Parameters!$T$14/Parameters!$U$14)))),Parameters!$Q$14*Parameters!$R$14*(1-EXP(-Parameters!$S$14*$D5))+IF(Parameters!$P$14="hump",Parameters!$V$14*($D5/Parameters!$W$14)*EXP(1-$D5/Parameters!$W$14),0)) -> 0 | O5: =IF(Parameters!$P$15="logistic",Parameters!$Q$15*Parameters!$R$15*((1/(1+EXP(-($D5-Parameters!$T$15)/Parameters!$U$15)))-(1/(1+EXP(Parameters!$T$15/Parameters!$U$15))))/(1-(1/(1+EXP(Parameters!$T$15/Parameters!$U$15)))),Parameters!$Q$15*Parameters!$R$15*(1-EXP(-Parameters!$S$15*$D5))+IF(Parameters!$P$15="hump",Parameters!$V$15*($D5/Parameters!$W$15)*EXP(1-$D5/Parameters!$W$15),0)) -> 0
A6: =B6&"|"&C6 -> Healthy|high | B6: Healthy | C6: high | D6: =Severity_Classes!$E$4 -> 0 | E6: =IF(Parameters!$P$4="logistic",Parameters!$Q$4*Parameters!$R$4*((1/(1+EXP(-($D6-Parameters!$T$4)/Parameters!$U$4)))-(1/(1+EXP(Parameters!$T$4/Parameters!$U$4))))/(1-(1/(1+EXP(Parameters!$T$4/Parameters!$U$4)))),Parameters!$Q$4*Parameters!$R$4*(1-EXP(-Parameters!$S$4*$D6))+IF(Parameters!$P$4="hump",Parameters!$V$4*($D6/Parameters!$W$4)*EXP(1-$D6/Parameters!$W$4),0)) -> 0 | F6: =IF(Parameters!$P$5="logistic",Parameters!$Q$5*Parameters!$R$5*((1/(1+EXP(-($D6-Parameters!$T$5)/Parameters!$U$5)))-(1/(1+EXP(Parameters!$T$5/Parameters!$U$5))))/(1-(1/(1+EXP(Parameters!$T$5/Parameters!$U$5)))),Parameters!$Q$5*Parameters!$R$5*(1-EXP(-Parameters!$S$5*$D6))+IF(Parameters!$P$5="hump",Parameters!$V$5*($D6/Parameters!$W$5)*EXP(1-$D6/Parameters!$W$5),0)) -> 0 | G6: =IF(Parameters!$P$6="logistic",Parameters!$Q$6*Parameters!$R$6*((1/(1+EXP(-($D6-Parameters!$T$6)/Parameters!$U$6)))-(1/(1+EXP(Parameters!$T$6/Parameters!$U$6))))/(1-(1/(1+EXP(Parameters!$T$6/Parameters!$U$6)))),Parameters!$Q$6*Parameters!$R$6*(1-EXP(-Parameters!$S$6*$D6))+IF(Parameters!$P$6="hump",Parameters!$V$6*($D6/Parameters!$W$6)*EXP(1-$D6/Parameters!$W$6),0)) -> 0 | H6: =IF(Parameters!$P$7="logistic",Parameters!$Q$7*Parameters!$R$7*((1/(1+EXP(-($D6-Parameters!$T$7)/Parameters!$U$7)))-(1/(1+EXP(Parameters!$T$7/Parameters!$U$7))))/(1-(1/(1+EXP(Parameters!$T$7/Parameters!$U$7)))),Parameters!$Q$7*Parameters!$R$7*(1-EXP(-Parameters!$S$7*$D6))+IF(Parameters!$P$7="hump",Parameters!$V$7*($D6/Parameters!$W$7)*EXP(1-$D6/Parameters!$W$7),0)) -> 0 | I6: =IF(Parameters!$P$9="logistic",Parameters!$Q$9*Parameters!$R$9*((1/(1+EXP(-($D6-Parameters!$T$9)/Parameters!$U$9)))-(1/(1+EXP(Parameters!$T$9/Parameters!$U$9))))/(1-(1/(1+EXP(Parameters!$T$9/Parameters!$U$9)))),Parameters!$Q$9*Parameters!$R$9*(1-EXP(-Parameters!$S$9*$D6))+IF(Parameters!$P$9="hump",Parameters!$V$9*($D6/Parameters!$W$9)*EXP(1-$D6/Parameters!$W$9),0)) -> 0 | J6: =IF(Parameters!$P$10="logistic",Parameters!$Q$10*Parameters!$R$10*((1/(1+EXP(-($D6-Parameters!$T$10)/Parameters!$U$10)))-(1/(1+EXP(Parameters!$T$10/Parameters!$U$10))))/(1-(1/(1+EXP(Parameters!$T$10/Parameters!$U$10)))),Parameters!$Q$10*Parameters!$R$10*(1-EXP(-Parameters!$S$10*$D6))+IF(Parameters!$P$10="hump",Parameters!$V$10*($D6/Parameters!$W$10)*EXP(1-$D6/Parameters!$W$10),0)) -> 0 | K6: =IF(Parameters!$P$11="logistic",Parameters!$Q$11*Parameters!$R$11*((1/(1+EXP(-($D6-Parameters!$T$11)/Parameters!$U$11)))-(1/(1+EXP(Parameters!$T$11/Parameters!$U$11))))/(1-(1/(1+EXP(Parameters!$T$11/Parameters!$U$11)))),Parameters!$Q$11*Parameters!$R$11*(1-EXP(-Parameters!$S$11*$D6))+IF(Parameters!$P$11="hump",Parameters!$V$11*($D6/Parameters!$W$11)*EXP(1-$D6/Parameters!$W$11),0)) -> 0 | L6: =IF(Parameters!$P$12="logistic",Parameters!$Q$12*Parameters!$R$12*((1/(1+EXP(-($D6-Parameters!$T$12)/Parameters!$U$12)))-(1/(1+EXP(Parameters!$T$12/Parameters!$U$12))))/(1-(1/(1+EXP(Parameters!$T$12/Parameters!$U$12)))),Parameters!$Q$12*Parameters!$R$12*(1-EXP(-Parameters!$S$12*$D6))+IF(Parameters!$P$12="hump",Parameters!$V$12*($D6/Parameters!$W$12)*EXP(1-$D6/Parameters!$W$12),0)) -> 0 | M6: =IF(Parameters!$P$13="logistic",Parameters!$Q$13*Parameters!$R$13*((1/(1+EXP(-($D6-Parameters!$T$13)/Parameters!$U$13)))-(1/(1+EXP(Parameters!$T$13/Parameters!$U$13))))/(1-(1/(1+EXP(Parameters!$T$13/Parameters!$U$13)))),Parameters!$Q$13*Parameters!$R$13*(1-EXP(-Parameters!$S$13*$D6))+IF(Parameters!$P$13="hump",Parameters!$V$13*($D6/Parameters!$W$13)*EXP(1-$D6/Parameters!$W$13),0)) -> 0 | N6: =IF(Parameters!$P$14="logistic",Parameters!$Q$14*Parameters!$R$14*((1/(1+EXP(-($D6-Parameters!$T$14)/Parameters!$U$14)))-(1/(1+EXP(Parameters!$T$14/Parameters!$U$14))))/(1-(1/(1+EXP(Parameters!$T$14/Parameters!$U$14)))),Parameters!$Q$14*Parameters!$R$14*(1-EXP(-Parameters!$S$14*$D6))+IF(Parameters!$P$14="hump",Parameters!$V$14*($D6/Parameters!$W$14)*EXP(1-$D6/Parameters!$W$14),0)) -> 0 | O6: =IF(Parameters!$P$15="logistic",Parameters!$Q$15*Parameters!$R$15*((1/(1+EXP(-($D6-Parameters!$T$15)/Parameters!$U$15)))-(1/(1+EXP(Parameters!$T$15/Parameters!$U$15))))/(1-(1/(1+EXP(Parameters!$T$15/Parameters!$U$15)))),Parameters!$Q$15*Parameters!$R$15*(1-EXP(-Parameters!$S$15*$D6))+IF(Parameters!$P$15="hump",Parameters!$V$15*($D6/Parameters!$W$15)*EXP(1-$D6/Parameters!$W$15),0)) -> 0
A7: =B7&"|"&C7 -> Very low|low | B7: Very low | C7: low | D7: =Severity_Classes!$C$5 -> 0.01 | E7: =IF(Parameters!$P$4="logistic",Parameters!$Q$4*Parameters!$R$4*((1/(1+EXP(-($D7-Parameters!$T$4)/Parameters!$U$4)))-(1/(1+EXP(Parameters!$T$4/Parameters!$U$4))))/(1-(1/(1+EXP(Parameters!$T$4/Parameters!$U$4)))),Parameters!$Q$4*Parameters!$R$4*(1-EXP(-Parameters!$S$4*$D7))+IF(Parameters!$P$4="hump",Parameters!$V$4*($D7/Parameters!$W$4)*EXP(1-$D7/Parameters!$W$4),0)) -> -0.0013324421 | F7: =IF(Parameters!$P$5="logistic",Parameters!$Q$5*Parameters!$R$5*((1/(1+EXP(-($D7-Parameters!$T$5)/Parameters!$U$5)))-(1/(1+EXP(Parameters!$T$5/Parameters!$U$5))))/(1-(1/(1+EXP(Parameters!$T$5/Parameters!$U$5)))),Parameters!$Q$5*Parameters!$R$5*(1-EXP(-Parameters!$S$5*$D7))+IF(Parameters!$P$5="hump",Parameters!$V$5*($D7/Parameters!$W$5)*EXP(1-$D7/Parameters!$W$5),0)) -> -0.004194895 | G7: =IF(Parameters!$P$6="logistic",Parameters!$Q$6*Parameters!$R$6*((1/(1+EXP(-($D7-Parameters!$T$6)/Parameters!$U$6)))-(1/(1+EXP(Parameters!$T$6/Parameters!$U$6))))/(1-(1/(1+EXP(Parameters!$T$6/Parameters!$U$6)))),Parameters!$Q$6*Parameters!$R$6*(1-EXP(-Parameters!$S$6*$D7))+IF(Parameters!$P$6="hump",Parameters!$V$6*($D7/Parameters!$W$6)*EXP(1-$D7/Parameters!$W$6),0)) -> -0.032284532 | H7: =IF(Parameters!$P$7="logistic",Parameters!$Q$7*Parameters!$R$7*((1/(1+EXP(-($D7-Parameters!$T$7)/Parameters!$U$7)))-(1/(1+EXP(Parameters!$T$7/Parameters!$U$7))))/(1-(1/(1+EXP(Parameters!$T$7/Parameters!$U$7)))),Parameters!$Q$7*Parameters!$R$7*(1-EXP(-Parameters!$S$7*$D7))+IF(Parameters!$P$7="hump",Parameters!$V$7*($D7/Parameters!$W$7)*EXP(1-$D7/Parameters!$W$7),0)) -> -0.019210403 | I7: =IF(Parameters!$P$9="logistic",Parameters!$Q$9*Parameters!$R$9*((1/(1+EXP(-($D7-Parameters!$T$9)/Parameters!$U$9)))-(1/(1+EXP(Parameters!$T$9/Parameters!$U$9))))/(1-(1/(1+EXP(Parameters!$T$9/Parameters!$U$9)))),Parameters!$Q$9*Parameters!$R$9*(1-EXP(-Parameters!$S$9*$D7))+IF(Parameters!$P$9="hump",Parameters!$V$9*($D7/Parameters!$W$9)*EXP(1-$D7/Parameters!$W$9),0)) -> 0.011763168 | J7: =IF(Parameters!$P$10="logistic",Parameters!$Q$10*Parameters!$R$10*((1/(1+EXP(-($D7-Parameters!$T$10)/Parameters!$U$10)))-(1/(1+EXP(Parameters!$T$10/Parameters!$U$10))))/(1-(1/(1+EXP(Parameters!$T$10/Parameters!$U$10)))),Parameters!$Q$10*Parameters!$R$10*(1-EXP(-Parameters!$S$10*$D7))+IF(Parameters!$P$10="hump",Parameters!$V$10*($D7/Parameters!$W$10)*EXP(1-$D7/Parameters!$W$10),0)) -> -0.01111054 | K7: =IF(Parameters!$P$11="logistic",Parameters!$Q$11*Parameters!$R$11*((1/(1+EXP(-($D7-Parameters!$T$11)/Parameters!$U$11)))-(1/(1+EXP(Parameters!$T$11/Parameters!$U$11))))/(1-(1/(1+EXP(Parameters!$T$11/Parameters!$U$11)))),Parameters!$Q$11*Parameters!$R$11*(1-EXP(-Parameters!$S$11*$D7))+IF(Parameters!$P$11="hump",Parameters!$V$11*($D7/Parameters!$W$11)*EXP(1-$D7/Parameters!$W$11),0)) -> -0.020470722 | L7: =IF(Parameters!$P$12="logistic",Parameters!$Q$12*Parameters!$R$12*((1/(1+EXP(-($D7-Parameters!$T$12)/Parameters!$U$12)))-(1/(1+EXP(Parameters!$T$12/Parameters!$U$12))))/(1-(1/(1+EXP(Parameters!$T$12/Parameters!$U$12)))),Parameters!$Q$12*Parameters!$R$12*(1-EXP(-Parameters!$S$12*$D7))+IF(Parameters!$P$12="hump",Parameters!$V$12*($D7/Parameters!$W$12)*EXP(1-$D7/Parameters!$W$12),0)) -> -0.016254957 | M7: =IF(Parameters!$P$13="logistic",Parameters!$Q$13*Parameters!$R$13*((1/(1+EXP(-($D7-Parameters!$T$13)/Parameters!$U$13)))-(1/(1+EXP(Parameters!$T$13/Parameters!$U$13))))/(1-(1/(1+EXP(Parameters!$T$13/Parameters!$U$13)))),Parameters!$Q$13*Parameters!$R$13*(1-EXP(-Parameters!$S$13*$D7))+IF(Parameters!$P$13="hump",Parameters!$V$13*($D7/Parameters!$W$13)*EXP(1-$D7/Parameters!$W$13),0)) -> 0.012774245 | N7: =IF(Parameters!$P$14="logistic",Parameters!$Q$14*Parameters!$R$14*((1/(1+EXP(-($D7-Parameters!$T$14)/Parameters!$U$14)))-(1/(1+EXP(Parameters!$T$14/Parameters!$U$14))))/(1-(1/(1+EXP(Parameters!$T$14/Parameters!$U$14)))),Parameters!$Q$14*Parameters!$R$14*(1-EXP(-Parameters!$S$14*$D7))+IF(Parameters!$P$14="hump",Parameters!$V$14*($D7/Parameters!$W$14)*EXP(1-$D7/Parameters!$W$14),0)) -> 0.01773268 | O7: =IF(Parameters!$P$15="logistic",Parameters!$Q$15*Parameters!$R$15*((1/(1+EXP(-($D7-Parameters!$T$15)/Parameters!$U$15)))-(1/(1+EXP(Parameters!$T$15/Parameters!$U$15))))/(1-(1/(1+EXP(Parameters!$T$15/Parameters!$U$15)))),Parameters!$Q$15*Parameters!$R$15*(1-EXP(-Parameters!$S$15*$D7))+IF(Parameters!$P$15="hump",Parameters!$V$15*($D7/Parameters!$W$15)*EXP(1-$D7/Parameters!$W$15),0)) -> -0.00443317
A8: =B8&"|"&C8 -> Very low|mid | B8: Very low | C8: mid | D8: =Severity_Classes!$D$5 -> 0.03 | E8: =IF(Parameters!$P$4="logistic",Parameters!$Q$4*Parameters!$R$4*((1/(1+EXP(-($D8-Parameters!$T$4)/Parameters!$U$4)))-(1/(1+EXP(Parameters!$T$4/Parameters!$U$4))))/(1-(1/(1+EXP(Parameters!$T$4/Parameters!$U$4)))),Parameters!$Q$4*Parameters!$R$4*(1-EXP(-Parameters!$S$4*$D8))+IF(Parameters!$P$4="hump",Parameters!$V$4*($D8/Parameters!$W$4)*EXP(1-$D8/Parameters!$W$4),0)) -> -0.0043113388 | F8: =IF(Parameters!$P$5="logistic",Parameters!$Q$5*Parameters!$R$5*((1/(1+EXP(-($D8-Parameters!$T$5)/Parameters!$U$5)))-(1/(1+EXP(Parameters!$T$5/Parameters!$U$5))))/(1-(1/(1+EXP(Parameters!$T$5/Parameters!$U$5)))),Parameters!$Q$5*Parameters!$R$5*(1-EXP(-Parameters!$S$5*$D8))+IF(Parameters!$P$5="hump",Parameters!$V$5*($D8/Parameters!$W$5)*EXP(1-$D8/Parameters!$W$5),0)) -> -0.013762741 | G8: =IF(Parameters!$P$6="logistic",Parameters!$Q$6*Parameters!$R$6*((1/(1+EXP(-($D8-Parameters!$T$6)/Parameters!$U$6)))-(1/(1+EXP(Parameters!$T$6/Parameters!$U$6))))/(1-(1/(1+EXP(Parameters!$T$6/Parameters!$U$6)))),Parameters!$Q$6*Parameters!$R$6*(1-EXP(-Parameters!$S$6*$D8))+IF(Parameters!$P$6="hump",Parameters!$V$6*($D8/Parameters!$W$6)*EXP(1-$D8/Parameters!$W$6),0)) -> -0.092744254 | H8: =IF(Parameters!$P$7="logistic",Parameters!$Q$7*Parameters!$R$7*((1/(1+EXP(-($D8-Parameters!$T$7)/Parameters!$U$7)))-(1/(1+EXP(Parameters!$T$7/Parameters!$U$7))))/(1-(1/(1+EXP(Parameters!$T$7/Parameters!$U$7)))),Parameters!$Q$7*Parameters!$R$7*(1-EXP(-Parameters!$S$7*$D8))+IF(Parameters!$P$7="hump",Parameters!$V$7*($D8/Parameters!$W$7)*EXP(1-$D8/Parameters!$W$7),0)) -> -0.05594473 | I8: =IF(Parameters!$P$9="logistic",Parameters!$Q$9*Parameters!$R$9*((1/(1+EXP(-($D8-Parameters!$T$9)/Parameters!$U$9)))-(1/(1+EXP(Parameters!$T$9/Parameters!$U$9))))/(1-(1/(1+EXP(Parameters!$T$9/Parameters!$U$9)))),Parameters!$Q$9*Parameters!$R$9*(1-EXP(-Parameters!$S$9*$D8))+IF(Parameters!$P$9="hump",Parameters!$V$9*($D8/Parameters!$W$9)*EXP(1-$D8/Parameters!$W$9),0)) -> 0.033923869 | J8: =IF(Parameters!$P$10="logistic",Parameters!$Q$10*Parameters!$R$10*((1/(1+EXP(-($D8-Parameters!$T$10)/Parameters!$U$10)))-(1/(1+EXP(Parameters!$T$10/Parameters!$U$10))))/(1-(1/(1+EXP(Parameters!$T$10/Parameters!$U$10)))),Parameters!$Q$10*Parameters!$R$10*(1-EXP(-Parameters!$S$10*$D8))+IF(Parameters!$P$10="hump",Parameters!$V$10*($D8/Parameters!$W$10)*EXP(1-$D8/Parameters!$W$10),0)) -> -0.032515431 | K8: =IF(Parameters!$P$11="logistic",Parameters!$Q$11*Parameters!$R$11*((1/(1+EXP(-($D8-Parameters!$T$11)/Parameters!$U$11)))-(1/(1+EXP(Parameters!$T$11/Parameters!$U$11))))/(1-(1/(1+EXP(Parameters!$T$11/Parameters!$U$11)))),Parameters!$Q$11*Parameters!$R$11*(1-EXP(-Parameters!$S$11*$D8))+IF(Parameters!$P$11="hump",Parameters!$V$11*($D8/Parameters!$W$11)*EXP(1-$D8/Parameters!$W$11),0)) -> -0.05949839 | L8: =IF(Parameters!$P$12="logistic",Parameters!$Q$12*Parameters!$R$12*((1/(1+EXP(-($D8-Parameters!$T$12)/Parameters!$U$12)))-(1/(1+EXP(Parameters!$T$12/Parameters!$U$12))))/(1-(1/(1+EXP(Parameters!$T$12/Parameters!$U$12)))),Parameters!$Q$12*Parameters!$R$12*(1-EXP(-Parameters!$S$12*$D8))+IF(Parameters!$P$12="hump",Parameters!$V$12*($D8/Parameters!$W$12)*EXP(1-$D8/Parameters!$W$12),0)) -> -0.047337848 | M8: =IF(Parameters!$P$13="logistic",Parameters!$Q$13*Parameters!$R$13*((1/(1+EXP(-($D8-Parameters!$T$13)/Parameters!$U$13)))-(1/(1+EXP(Parameters!$T$13/Parameters!$U$13))))/(1-(1/(1+EXP(Parameters!$T$13/Parameters!$U$13)))),Parameters!$Q$13*Parameters!$R$13*(1-EXP(-Parameters!$S$13*$D8))+IF(Parameters!$P$13="hump",Parameters!$V$13*($D8/Parameters!$W$13)*EXP(1-$D8/Parameters!$W$13),0)) -> 0.025985055 | N8: =IF(Parameters!$P$14="logistic",Parameters!$Q$14*Parameters!$R$14*((1/(1+EXP(-($D8-Parameters!$T$14)/Parameters!$U$14)))-(1/(1+EXP(Parameters!$T$14/Parameters!$U$14))))/(1-(1/(1+EXP(Parameters!$T$14/Parameters!$U$14)))),Parameters!$Q$14*Parameters!$R$14*(1-EXP(-Parameters!$S$14*$D8))+IF(Parameters!$P$14="hump",Parameters!$V$14*($D8/Parameters!$W$14)*EXP(1-$D8/Parameters!$W$14),0)) -> 0.051641289 | O8: =IF(Parameters!$P$15="logistic",Parameters!$Q$15*Parameters!$R$15*((1/(1+EXP(-($D8-Parameters!$T$15)/Parameters!$U$15)))-(1/(1+EXP(Parameters!$T$15/Parameters!$U$15))))/(1-(1/(1+EXP(Parameters!$T$15/Parameters!$U$15)))),Parameters!$Q$15*Parameters!$R$15*(1-EXP(-Parameters!$S$15*$D8))+IF(Parameters!$P$15="hump",Parameters!$V$15*($D8/Parameters!$W$15)*EXP(1-$D8/Parameters!$W$15),0)) -> -0.012910322
A9: =B9&"|"&C9 -> Very low|high | B9: Very low | C9: high | D9: =Severity_Classes!$E$5 -> 0.05 | E9: =IF(Parameters!$P$4="logistic",Parameters!$Q$4*Parameters!$R$4*((1/(1+EXP(-($D9-Parameters!$T$4)/Parameters!$U$4)))-(1/(1+EXP(Parameters!$T$4/Parameters!$U$4))))/(1-(1/(1+EXP(Parameters!$T$4/Parameters!$U$4)))),Parameters!$Q$4*Parameters!$R$4*(1-EXP(-Parameters!$S$4*$D9))+IF(Parameters!$P$4="hump",Parameters!$V$4*($D9/Parameters!$W$4)*EXP(1-$D9/Parameters!$W$4),0)) -> -0.0077548157 | F9: =IF(Parameters!$P$5="logistic",Parameters!$Q$5*Parameters!$R$5*((1/(1+EXP(-($D9-Parameters!$T$5)/Parameters!$U$5)))-(1/(1+EXP(Parameters!$T$5/Parameters!$U$5))))/(1-(1/(1+EXP(Parameters!$T$5/Parameters!$U$5)))),Parameters!$Q$5*Parameters!$R$5*(1-EXP(-Parameters!$S$5*$D9))+IF(Parameters!$P$5="hump",Parameters!$V$5*($D9/Parameters!$W$5)*EXP(1-$D9/Parameters!$W$5),0)) -> -0.025097864 | G9: =IF(Parameters!$P$6="logistic",Parameters!$Q$6*Parameters!$R$6*((1/(1+EXP(-($D9-Parameters!$T$6)/Parameters!$U$6)))-(1/(1+EXP(Parameters!$T$6/Parameters!$U$6))))/(1-(1/(1+EXP(Parameters!$T$6/Parameters!$U$6)))),Parameters!$Q$6*Parameters!$R$6*(1-EXP(-Parameters!$S$6*$D9))+IF(Parameters!$P$6="hump",Parameters!$V$6*($D9/Parameters!$W$6)*EXP(1-$D9/Parameters!$W$6),0)) -> -0.1481109 | H9: =IF(Parameters!$P$7="logistic",Parameters!$Q$7*Parameters!$R$7*((1/(1+EXP(-($D9-Parameters!$T$7)/Parameters!$U$7)))-(1/(1+EXP(Parameters!$T$7/Parameters!$U$7))))/(1-(1/(1+EXP(Parameters!$T$7/Parameters!$U$7)))),Parameters!$Q$7*Parameters!$R$7*(1-EXP(-Parameters!$S$7*$D9))+IF(Parameters!$P$7="hump",Parameters!$V$7*($D9/Parameters!$W$7)*EXP(1-$D9/Parameters!$W$7),0)) -> -0.090539815 | I9: =IF(Parameters!$P$9="logistic",Parameters!$Q$9*Parameters!$R$9*((1/(1+EXP(-($D9-Parameters!$T$9)/Parameters!$U$9)))-(1/(1+EXP(Parameters!$T$9/Parameters!$U$9))))/(1-(1/(1+EXP(Parameters!$T$9/Parameters!$U$9)))),Parameters!$Q$9*Parameters!$R$9*(1-EXP(-Parameters!$S$9*$D9))+IF(Parameters!$P$9="hump",Parameters!$V$9*($D9/Parameters!$W$9)*EXP(1-$D9/Parameters!$W$9),0)) -> 0.054380774 | J9: =IF(Parameters!$P$10="logistic",Parameters!$Q$10*Parameters!$R$10*((1/(1+EXP(-($D9-Parameters!$T$10)/Parameters!$U$10)))-(1/(1+EXP(Parameters!$T$10/Parameters!$U$10))))/(1-(1/(1+EXP(Parameters!$T$10/Parameters!$U$10)))),Parameters!$Q$10*Parameters!$R$10*(1-EXP(-Parameters!$S$10*$D9))+IF(Parameters!$P$10="hump",Parameters!$V$10*($D9/Parameters!$W$10)*EXP(1-$D9/Parameters!$W$10),0)) -> -0.052876394 | K9: =IF(Parameters!$P$11="logistic",Parameters!$Q$11*Parameters!$R$11*((1/(1+EXP(-($D9-Parameters!$T$11)/Parameters!$U$11)))-(1/(1+EXP(Parameters!$T$11/Parameters!$U$11))))/(1-(1/(1+EXP(Parameters!$T$11/Parameters!$U$11)))),Parameters!$Q$11*Parameters!$R$11*(1-EXP(-Parameters!$S$11*$D9))+IF(Parameters!$P$11="hump",Parameters!$V$11*($D9/Parameters!$W$11)*EXP(1-$D9/Parameters!$W$11),0)) -> -0.096106537 | L9: =IF(Parameters!$P$12="logistic",Parameters!$Q$12*Parameters!$R$12*((1/(1+EXP(-($D9-Parameters!$T$12)/Parameters!$U$12)))-(1/(1+EXP(Parameters!$T$12/Parameters!$U$12))))/(1-(1/(1+EXP(Parameters!$T$12/Parameters!$U$12)))),Parameters!$Q$12*Parameters!$R$12*(1-EXP(-Parameters!$S$12*$D9))+IF(Parameters!$P$12="hump",Parameters!$V$12*($D9/Parameters!$W$12)*EXP(1-$D9/Parameters!$W$12),0)) -> -0.076610613 | M9: =IF(Parameters!$P$13="logistic",Parameters!$Q$13*Parameters!$R$13*((1/(1+EXP(-($D9-Parameters!$T$13)/Parameters!$U$13)))-(1/(1+EXP(Parameters!$T$13/Parameters!$U$13))))/(1-(1/(1+EXP(Parameters!$T$13/Parameters!$U$13)))),Parameters!$Q$13*Parameters!$R$13*(1-EXP(-Parameters!$S$13*$D9))+IF(Parameters!$P$13="hump",Parameters!$V$13*($D9/Parameters!$W$13)*EXP(1-$D9/Parameters!$W$13),0)) -> 0.026719254 | N9: =IF(Parameters!$P$14="logistic",Parameters!$Q$14*Parameters!$R$14*((1/(1+EXP(-($D9-Parameters!$T$14)/Parameters!$U$14)))-(1/(1+EXP(Parameters!$T$14/Parameters!$U$14))))/(1-(1/(1+EXP(Parameters!$T$14/Parameters!$U$14)))),Parameters!$Q$14*Parameters!$R$14*(1-EXP(-Parameters!$S$14*$D9))+IF(Parameters!$P$14="hump",Parameters!$V$14*($D9/Parameters!$W$14)*EXP(1-$D9/Parameters!$W$14),0)) -> 0.083575214 | O9: =IF(Parameters!$P$15="logistic",Parameters!$Q$15*Parameters!$R$15*((1/(1+EXP(-($D9-Parameters!$T$15)/Parameters!$U$15)))-(1/(1+EXP(Parameters!$T$15/Parameters!$U$15))))/(1-(1/(1+EXP(Parameters!$T$15/Parameters!$U$15)))),Parameters!$Q$15*Parameters!$R$15*(1-EXP(-Parameters!$S$15*$D9))+IF(Parameters!$P$15="hump",Parameters!$V$15*($D9/Parameters!$W$15)*EXP(1-$D9/Parameters!$W$15),0)) -> -0.020893804
A10: =B10&"|"&C10 -> Low|low | B10: Low | C10: low | D10: =Severity_Classes!$C$6 -> 0.06 | E10: =IF(Parameters!$P$4="logistic",Parameters!$Q$4*Parameters!$R$4*((1/(1+EXP(-($D10-Parameters!$T$4)/Parameters!$U$4)))-(1/(1+EXP(Parameters!$T$4/Parameters!$U$4))))/(1-(1/(1+EXP(Parameters!$T$4/Parameters!$U$4)))),Parameters!$Q$4*Parameters!$R$4*(1-EXP(-Parameters!$S$4*$D10))+IF(Parameters!$P$4="hump",Parameters!$V$4*($D10/Parameters!$W$4)*EXP(1-$D10/Parameters!$W$4),0)) -> -0.0096687902 | F10: =IF(Parameters!$P$5="logistic",Parameters!$Q$5*Parameters!$R$5*((1/(1+EXP(-($D10-Parameters!$T$5)/Parameters!$U$5)))-(1/(1+EXP(Parameters!$T$5/Parameters!$U$5))))/(1-(1/(1+EXP(Parameters!$T$5/Parameters!$U$5)))),Parameters!$Q$5*Parameters!$R$5*(1-EXP(-Parameters!$S$5*$D10))+IF(Parameters!$P$5="hump",Parameters!$V$5*($D10/Parameters!$W$5)*EXP(1-$D10/Parameters!$W$5),0)) -> -0.031504382 | G10: =IF(Parameters!$P$6="logistic",Parameters!$Q$6*Parameters!$R$6*((1/(1+EXP(-($D10-Parameters!$T$6)/Parameters!$U$6)))-(1/(1+EXP(Parameters!$T$6/Parameters!$U$6))))/(1-(1/(1+EXP(Parameters!$T$6/Parameters!$U$6)))),Parameters!$Q$6*Parameters!$R$6*(1-EXP(-Parameters!$S$6*$D10))+IF(Parameters!$P$6="hump",Parameters!$V$6*($D10/Parameters!$W$6)*EXP(1-$D10/Parameters!$W$6),0)) -> -0.17401985 | H10: =IF(Parameters!$P$7="logistic",Parameters!$Q$7*Parameters!$R$7*((1/(1+EXP(-($D10-Parameters!$T$7)/Parameters!$U$7)))-(1/(1+EXP(Parameters!$T$7/Parameters!$U$7))))/(1-(1/(1+EXP(Parameters!$T$7/Parameters!$U$7)))),Parameters!$Q$7*Parameters!$R$7*(1-EXP(-Parameters!$S$7*$D10))+IF(Parameters!$P$7="hump",Parameters!$V$7*($D10/Parameters!$W$7)*EXP(1-$D10/Parameters!$W$7),0)) -> -0.10707436 | I10: =IF(Parameters!$P$9="logistic",Parameters!$Q$9*Parameters!$R$9*((1/(1+EXP(-($D10-Parameters!$T$9)/Parameters!$U$9)))-(1/(1+EXP(Parameters!$T$9/Parameters!$U$9))))/(1-(1/(1+EXP(Parameters!$T$9/Parameters!$U$9)))),Parameters!$Q$9*Parameters!$R$9*(1-EXP(-Parameters!$S$9*$D10))+IF(Parameters!$P$9="hump",Parameters!$V$9*($D10/Parameters!$W$9)*EXP(1-$D10/Parameters!$W$9),0)) -> 0.064011642 | J10: =IF(Parameters!$P$10="logistic",Parameters!$Q$10*Parameters!$R$10*((1/(1+EXP(-($D10-Parameters!$T$10)/Parameters!$U$10)))-(1/(1+EXP(Parameters!$T$10/Parameters!$U$10))))/(1-(1/(1+EXP(Parameters!$T$10/Parameters!$U$10)))),Parameters!$Q$10*Parameters!$R$10*(1-EXP(-Parameters!$S$10*$D10))+IF(Parameters!$P$10="hump",Parameters!$V$10*($D10/Parameters!$W$10)*EXP(1-$D10/Parameters!$W$10),0)) -> -0.062681411 | K10: =IF(Parameters!$P$11="logistic",Parameters!$Q$11*Parameters!$R$11*((1/(1+EXP(-($D10-Parameters!$T$11)/Parameters!$U$11)))-(1/(1+EXP(Parameters!$T$11/Parameters!$U$11))))/(1-(1/(1+EXP(Parameters!$T$11/Parameters!$U$11)))),Parameters!$Q$11*Parameters!$R$11*(1-EXP(-Parameters!$S$11*$D10))+IF(Parameters!$P$11="hump",Parameters!$V$11*($D10/Parameters!$W$11)*EXP(1-$D10/Parameters!$W$11),0)) -> -0.11355054 | L10: =IF(Parameters!$P$12="logistic",Parameters!$Q$12*Parameters!$R$12*((1/(1+EXP(-($D10-Parameters!$T$12)/Parameters!$U$12)))-(1/(1+EXP(Parameters!$T$12/Parameters!$U$12))))/(1-(1/(1+EXP(Parameters!$T$12/Parameters!$U$12)))),Parameters!$Q$12*Parameters!$R$12*(1-EXP(-Parameters!$S$12*$D10))+IF(Parameters!$P$12="hump",Parameters!$V$12*($D10/Parameters!$W$12)*EXP(1-$D10/Parameters!$W$12),0)) -> -0.090601384 | M10: =IF(Parameters!$P$13="logistic",Parameters!$Q$13*Parameters!$R$13*((1/(1+EXP(-($D10-Parameters!$T$13)/Parameters!$U$13)))-(1/(1+EXP(Parameters!$T$13/Parameters!$U$13))))/(1-(1/(1+EXP(Parameters!$T$13/Parameters!$U$13)))),Parameters!$Q$13*Parameters!$R$13*(1-EXP(-Parameters!$S$13*$D10))+IF(Parameters!$P$13="hump",Parameters!$V$13*($D10/Parameters!$W$13)*EXP(1-$D10/Parameters!$W$13),0)) -> 0.023617566 | N10: =IF(Parameters!$P$14="logistic",Parameters!$Q$14*Parameters!$R$14*((1/(1+EXP(-($D10-Parameters!$T$14)/Parameters!$U$14)))-(1/(1+EXP(Parameters!$T$14/Parameters!$U$14))))/(1-(1/(1+EXP(Parameters!$T$14/Parameters!$U$14)))),Parameters!$Q$14*Parameters!$R$14*(1-EXP(-Parameters!$S$14*$D10))+IF(Parameters!$P$14="hump",Parameters!$V$14*($D10/Parameters!$W$14)*EXP(1-$D10/Parameters!$W$14),0)) -> 0.098837873 | O10: =IF(Parameters!$P$15="logistic",Parameters!$Q$15*Parameters!$R$15*((1/(1+EXP(-($D10-Parameters!$T$15)/Parameters!$U$15)))-(1/(1+EXP(Parameters!$T$15/Parameters!$U$15))))/(1-(1/(1+EXP(Parameters!$T$15/Parameters!$U$15)))),Parameters!$Q$15*Parameters!$R$15*(1-EXP(-Parameters!$S$15*$D10))+IF(Parameters!$P$15="hump",Parameters!$V$15*($D10/Parameters!$W$15)*EXP(1-$D10/Parameters!$W$15),0)) -> -0.024709468
A11: =B11&"|"&C11 -> Low|mid | B11: Low | C11: mid | D11: =Severity_Classes!$D$6 -> 0.08 | E11: =IF(Parameters!$P$4="logistic",Parameters!$Q$4*Parameters!$R$4*((1/(1+EXP(-($D11-Parameters!$T$4)/Parameters!$U$4)))-(1/(1+EXP(Parameters!$T$4/Parameters!$U$4))))/(1-(1/(1+EXP(Parameters!$T$4/Parameters!$U$4)))),Parameters!$Q$4*Parameters!$R$4*(1-EXP(-Parameters!$S$4*$D11))+IF(Parameters!$P$4="hump",Parameters!$V$4*($D11/Parameters!$W$4)*EXP(1-$D11/Parameters!$W$4),0)) -> -0.013918625 | F11: =IF(Parameters!$P$5="logistic",Parameters!$Q$5*Parameters!$R$5*((1/(1+EXP(-($D11-Parameters!$T$5)/Parameters!$U$5)))-(1/(1+EXP(Parameters!$T$5/Parameters!$U$5))))/(1-(1/(1+EXP(Parameters!$T$5/Parameters!$U$5)))),Parameters!$Q$5*Parameters!$R$5*(1-EXP(-Parameters!$S$5*$D11))+IF(Parameters!$P$5="hump",Parameters!$V$5*($D11/Parameters!$W$5)*EXP(1-$D11/Parameters!$W$5),0)) -> -0.045949118 | G11: =IF(Parameters!$P$6="logistic",Parameters!$Q$6*Parameters!$R$6*((1/(1+EXP(-($D11-Parameters!$T$6)/Parameters!$U$6)))-(1/(1+EXP(Parameters!$T$6/Parameters!$U$6))))/(1-(1/(1+EXP(Parameters!$T$6/Parameters!$U$6)))),Parameters!$Q$6*Parameters!$R$6*(1-EXP(-Parameters!$S$6*$D11))+IF(Parameters!$P$6="hump",Parameters!$V$6*($D11/Parameters!$W$6)*EXP(1-$D11/Parameters!$W$6),0)) -> -0.22253991 | H11: =IF(Parameters!$P$7="logistic",Parameters!$Q$7*Parameters!$R$7*((1/(1+EXP(-($D11-Parameters!$T$7)/Parameters!$U$7)))-(1/(1+EXP(Parameters!$T$7/Parameters!$U$7))))/(1-(1/(1+EXP(Parameters!$T$7/Parameters!$U$7)))),Parameters!$Q$7*Parameters!$R$7*(1-EXP(-Parameters!$S$7*$D11))+IF(Parameters!$P$7="hump",Parameters!$V$7*($D11/Parameters!$W$7)*EXP(1-$D11/Parameters!$W$7),0)) -> -0.13869189 | I11: =IF(Parameters!$P$9="logistic",Parameters!$Q$9*Parameters!$R$9*((1/(1+EXP(-($D11-Parameters!$T$9)/Parameters!$U$9)))-(1/(1+EXP(Parameters!$T$9/Parameters!$U$9))))/(1-(1/(1+EXP(Parameters!$T$9/Parameters!$U$9)))),Parameters!$Q$9*Parameters!$R$9*(1-EXP(-Parameters!$S$9*$D11))+IF(Parameters!$P$9="hump",Parameters!$V$9*($D11/Parameters!$W$9)*EXP(1-$D11/Parameters!$W$9),0)) -> 0.082155289 | J11: =IF(Parameters!$P$10="logistic",Parameters!$Q$10*Parameters!$R$10*((1/(1+EXP(-($D11-Parameters!$T$10)/Parameters!$U$10)))-(1/(1+EXP(Parameters!$T$10/Parameters!$U$10))))/(1-(1/(1+EXP(Parameters!$T$10/Parameters!$U$10)))),Parameters!$Q$10*Parameters!$R$10*(1-EXP(-Parameters!$S$10*$D11))+IF(Parameters!$P$10="hump",Parameters!$V$10*($D11/Parameters!$W$10)*EXP(1-$D11/Parameters!$W$10),0)) -> -0.081571161 | K11: =IF(Parameters!$P$11="logistic",Parameters!$Q$11*Parameters!$R$11*((1/(1+EXP(-($D11-Parameters!$T$11)/Parameters!$U$11)))-(1/(1+EXP(Parameters!$T$11/Parameters!$U$11))))/(1-(1/(1+EXP(Parameters!$T$11/Parameters!$U$11)))),Parameters!$Q$11*Parameters!$R$11*(1-EXP(-Parameters!$S$11*$D11))+IF(Parameters!$P$11="hump",Parameters!$V$11*($D11/Parameters!$W$11)*EXP(1-$D11/Parameters!$W$11),0)) -> -0.14680772 | L11: =IF(Parameters!$P$12="logistic",Parameters!$Q$12*Parameters!$R$12*((1/(1+EXP(-($D11-Parameters!$T$12)/Parameters!$U$12)))-(1/(1+EXP(Parameters!$T$12/Parameters!$U$12))))/(1-(1/(1+EXP(Parameters!$T$12/Parameters!$U$12)))),Parameters!$Q$12*Parameters!$R$12*(1-EXP(-Parameters!$S$12*$D11))+IF(Parameters!$P$12="hump",Parameters!$V$12*($D11/Parameters!$W$12)*EXP(1-$D11/Parameters!$W$12),0)) -> -0.11735468 | M11: =IF(Parameters!$P$13="logistic",Parameters!$Q$13*Parameters!$R$13*((1/(1+EXP(-($D11-Parameters!$T$13)/Parameters!$U$13)))-(1/(1+EXP(Parameters!$T$13/Parameters!$U$13))))/(1-(1/(1+EXP(Parameters!$T$13/Parameters!$U$13)))),Parameters!$Q$13*Parameters!$R$13*(1-EXP(-Parameters!$S$13*$D11))+IF(Parameters!$P$13="hump",Parameters!$V$13*($D11/Parameters!$W$13)*EXP(1-$D11/Parameters!$W$13),0)) -> 0.012363365 | N11: =IF(Parameters!$P$14="logistic",Parameters!$Q$14*Parameters!$R$14*((1/(1+EXP(-($D11-Parameters!$T$14)/Parameters!$U$14)))-(1/(1+EXP(Parameters!$T$14/Parameters!$U$14))))/(1-(1/(1+EXP(Parameters!$T$14/Parameters!$U$14)))),Parameters!$Q$14*Parameters!$R$14*(1-EXP(-Parameters!$S$14*$D11))+IF(Parameters!$P$14="hump",Parameters!$V$14*($D11/Parameters!$W$14)*EXP(1-$D11/Parameters!$W$14),0)) -> 0.12802328 | O11: =IF(Parameters!$P$15="logistic",Parameters!$Q$15*Parameters!$R$15*((1/(1+EXP(-($D11-Parameters!$T$15)/Parameters!$U$15)))-(1/(1+EXP(Parameters!$T$15/Parameters!$U$15))))/(1-(1/(1+EXP(Parameters!$T$15/Parameters!$U$15)))),Parameters!$Q$15*Parameters!$R$15*(1-EXP(-Parameters!$S$15*$D11))+IF(Parameters!$P$15="hump",Parameters!$V$15*($D11/Parameters!$W$15)*EXP(1-$D11/Parameters!$W$15),0)) -> -0.032005821
A12: =B12&"|"&C12 -> Low|high | B12: Low | C12: high | D12: =Severity_Classes!$E$6 -> 0.1 | E12: =IF(Parameters!$P$4="logistic",Parameters!$Q$4*Parameters!$R$4*((1/(1+EXP(-($D12-Parameters!$T$4)/Parameters!$U$4)))-(1/(1+EXP(Parameters!$T$4/Parameters!$U$4))))/(1-(1/(1+EXP(Parameters!$T$4/Parameters!$U$4)))),Parameters!$Q$4*Parameters!$R$4*(1-EXP(-Parameters!$S$4*$D12))+IF(Parameters!$P$4="hump",Parameters!$V$4*($D12/Parameters!$W$4)*EXP(1-$D12/Parameters!$W$4),0)) -> -0.018781627 | F12: =IF(Parameters!$P$5="logistic",Parameters!$Q$5*Parameters!$R$5*((1/(1+EXP(-($D12-Parameters!$T$5)/Parameters!$U$5)))-(1/(1+EXP(Parameters!$T$5/Parameters!$U$5))))/(1-(1/(1+EXP(Parameters!$T$5/Parameters!$U$5)))),Parameters!$Q$5*Parameters!$R$5*(1-EXP(-Parameters!$S$5*$D12))+IF(Parameters!$P$5="hump",Parameters!$V$5*($D12/Parameters!$W$5)*EXP(1-$D12/Parameters!$W$5),0)) -> -0.062766882 | G12: =IF(Parameters!$P$6="logistic",Parameters!$Q$6*Parameters!$R$6*((1/(1+EXP(-($D12-Parameters!$T$6)/Parameters!$U$6)))-(1/(1+EXP(Parameters!$T$6/Parameters!$U$6))))/(1-(1/(1+EXP(Parameters!$T$6/Parameters!$U$6)))),Parameters!$Q$6*Parameters!$R$6*(1-EXP(-Parameters!$S$6*$D12))+IF(Parameters!$P$6="hump",Parameters!$V$6*($D12/Parameters!$W$6)*EXP(1-$D12/Parameters!$W$6),0)) -> -0.26697268 | H12: =IF(Parameters!$P$7="logistic",Parameters!$Q$7*Parameters!$R$7*((1/(1+EXP(-($D12-Parameters!$T$7)/Parameters!$U$7)))-(1/(1+EXP(Parameters!$T$7/Parameters!$U$7))))/(1-(1/(1+EXP(Parameters!$T$7/Parameters!$U$7)))),Parameters!$Q$7*Parameters!$R$7*(1-EXP(-Parameters!$S$7*$D12))+IF(Parameters!$P$7="hump",Parameters!$V$7*($D12/Parameters!$W$7)*EXP(1-$D12/Parameters!$W$7),0)) -> -0.16846816 | I12: =IF(Parameters!$P$9="logistic",Parameters!$Q$9*Parameters!$R$9*((1/(1+EXP(-($D12-Parameters!$T$9)/Parameters!$U$9)))-(1/(1+EXP(Parameters!$T$9/Parameters!$U$9))))/(1-(1/(1+EXP(Parameters!$T$9/Parameters!$U$9)))),Parameters!$Q$9*Parameters!$R$9*(1-EXP(-Parameters!$S$9*$D12))+IF(Parameters!$P$9="hump",Parameters!$V$9*($D12/Parameters!$W$9)*EXP(1-$D12/Parameters!$W$9),0)) -> 0.098903986 | J12: =IF(Parameters!$P$10="logistic",Parameters!$Q$10*Parameters!$R$10*((1/(1+EXP(-($D12-Parameters!$T$10)/Parameters!$U$10)))-(1/(1+EXP(Parameters!$T$10/Parameters!$U$10))))/(1-(1/(1+EXP(Parameters!$T$10/Parameters!$U$10)))),Parameters!$Q$10*Parameters!$R$10*(1-EXP(-Parameters!$S$10*$D12))+IF(Parameters!$P$10="hump",Parameters!$V$10*($D12/Parameters!$W$10)*EXP(1-$D12/Parameters!$W$10),0)) -> -0.099539648 | K12: =IF(Parameters!$P$11="logistic",Parameters!$Q$11*Parameters!$R$11*((1/(1+EXP(-($D12-Parameters!$T$11)/Parameters!$U$11)))-(1/(1+EXP(Parameters!$T$11/Parameters!$U$11))))/(1-(1/(1+EXP(Parameters!$T$11/Parameters!$U$11)))),Parameters!$Q$11*Parameters!$R$11*(1-EXP(-Parameters!$S$11*$D12))+IF(Parameters!$P$11="hump",Parameters!$V$11*($D12/Parameters!$W$11)*EXP(1-$D12/Parameters!$W$11),0)) -> -0.17800313 | L12: =IF(Parameters!$P$12="logistic",Parameters!$Q$12*Parameters!$R$12*((1/(1+EXP(-($D12-Parameters!$T$12)/Parameters!$U$12)))-(1/(1+EXP(Parameters!$T$12/Parameters!$U$12))))/(1-(1/(1+EXP(Parameters!$T$12/Parameters!$U$12)))),Parameters!$Q$12*Parameters!$R$12*(1-EXP(-Parameters!$S$12*$D12))+IF(Parameters!$P$12="hump",Parameters!$V$12*($D12/Parameters!$W$12)*EXP(1-$D12/Parameters!$W$12),0)) -> -0.14254998 | M12: =IF(Parameters!$P$13="logistic",Parameters!$Q$13*Parameters!$R$13*((1/(1+EXP(-($D12-Parameters!$T$13)/Parameters!$U$13)))-(1/(1+EXP(Parameters!$T$13/Parameters!$U$13))))/(1-(1/(1+EXP(Parameters!$T$13/Parameters!$U$13)))),Parameters!$Q$13*Parameters!$R$13*(1-EXP(-Parameters!$S$13*$D12))+IF(Parameters!$P$13="hump",Parameters!$V$13*($D12/Parameters!$W$13)*EXP(1-$D12/Parameters!$W$13),0)) -> -0.0036727117 | N12: =IF(Parameters!$P$14="logistic",Parameters!$Q$14*Parameters!$R$14*((1/(1+EXP(-($D12-Parameters!$T$14)/Parameters!$U$14)))-(1/(1+EXP(Parameters!$T$14/Parameters!$U$14))))/(1-(1/(1+EXP(Parameters!$T$14/Parameters!$U$14)))),Parameters!$Q$14*Parameters!$R$14*(1-EXP(-Parameters!$S$14*$D12))+IF(Parameters!$P$14="hump",Parameters!$V$14*($D12/Parameters!$W$14)*EXP(1-$D12/Parameters!$W$14),0)) -> 0.15550907 | O12: =IF(Parameters!$P$15="logistic",Parameters!$Q$15*Parameters!$R$15*((1/(1+EXP(-($D12-Parameters!$T$15)/Parameters!$U$15)))-(1/(1+EXP(Parameters!$T$15/Parameters!$U$15))))/(1-(1/(1+EXP(Parameters!$T$15/Parameters!$U$15)))),Parameters!$Q$15*Parameters!$R$15*(1-EXP(-Parameters!$S$15*$D12))+IF(Parameters!$P$15="hump",Parameters!$V$15*($D12/Parameters!$W$15)*EXP(1-$D12/Parameters!$W$15),0)) -> -0.038877267
