Workbook

Sheet README
A1: PLOT-WISE ESTIMATES OF BIOPHYSICAL AND BIOCHEMICAL PARAMETERS - 24/02/2026 (DI scored 26/02/2026)
A2: ESTIMATED VALUES, NOT LABORATORY MEASUREMENTS. Use them as expected plot values, for checking your lab data, as priors, and to test spectra-to-trait models. Report them as estimates; replace with your measured values where you have them.
A4: HOW EACH PLOT VALUE IS BUILT
A5: 1. Healthy baseline: the expected healthy value of the plot's treatment (sowing date x variety) on 24/02/2026 from the model workbook (stage, sampled leaf, variety, heat and VPD already included).
A6: 2. Severity: your leaf scores (0-9, Bisht et al. 2015) for the spectra of that plot -> pustule leaf area (grade mid-points 0, 2.5, 7.5, 18, 38, 75%) -> plot mean area A -> effective severity s_eff = kappa x A.
A7: 3. kappa = 0.47 was fitted so that the model's chlorophyll response matches the chlorophyll drop seen in your plot-average spectra (MTCI of each inoculated plot / MTCI of the healthy plot of the same treatment). Using DI directly (s = DI) would overstate the decline about 5-fold, because DI is a score index, not tissue area.
A8: 4. Prior: model response curves R(s_eff) x variety tolerance applied to the healthy baseline (Inputs sheet, 'prior' columns).
A9: 5. Spectral chlorophyll: plot-average ASD spectrum -> MTCI (insensitive to offset and gain) -> chlorophyll a+b per leaf area by PROSPECT-D -> divided by fresh mass per area -> mg g-1 FW.
A10: 6. Final (Estimates sheet, live formulas): total chlorophyll = weighted geometric mean of prior and spectral values; the ratio delta = final / prior chlorophyll then adjusts the other traits through the exponents in Settings (Pn, gs, MSI, protein follow the chlorophyll status; anthocyanin moves opposite). Chl a, Chl b and carotenoids keep the model's a/b and Car/Chl ratios.
A11: 7. Ranges: estimate x (1 -/+ 1.645 x CV) with the plant-to-plant and assay CVs of the model (about 90% interval).
A13: NOTES
A14: - The plot-average spectrum mixes the 3rd, 5th and lower leaves you scanned (L3/L5/LL); estimates refer to that plot-average leaf, on the stage-specific basis of the model (3rd leaf at vegetative, 5th leaf at flowering).
... A20: SHEETS: Settings | Estimates (final values) | Ranges (low-high) | Inputs (severity, priors, spectral chlorophyll) | Spectral_Features | Treatment_Summary | Plot_Mean_Spectra (350-2500 nm).

Sheet Estimates
A1: Plot | B1: Treatment | C1: Sowing | D1: Variety | E1: Replication | F1: Growth stage | G1: Plot DI (%) | H1: Severity class | I1: RWC (%) | J1: MSI (%) | K1: Pn (umol CO2 m-2 s-1) | L1: gs (mol H2O m-2 s-1) | M1: E (mmol H2O m-2 s-1) | N1: Ci (umol mol-1) | O1: LAI (m2 m-2) | P1: Chl a (ug mg-1 FW) | Q1: Chl b (ug mg-1 FW) | R1: Total chl (ug mg-1 FW) | S1: Chl a/b | T1: Carotenoids (mg g-1 FW) | U1: Car / total chl | V1: Anthocyanin (ug g-1 FW) | W1: Total protein (ug mg-1 FW) | X1: WUE Pn/E (umol mmol-1) | Y1: Chl final / prior (delta)
A2: 7 | B2: D1V1 | C2: D1 | D2: V1 | E2: Control | F2: Flowering | G2: 0 | H2: Healthy | I2: =Inputs!$S2 -> 85.041177 | J2: =Inputs!$T2*Y2^Settings!$C$7 -> 71.659645 | K2: =Inputs!$U2*Y2^Settings!$C$4 -> 19.831751 | L2: =Inputs!$V2*Y2^Settings!$C$5 -> 0.42696982 | M2: =Inputs!$W2*L2/Inputs!$V2 -> 5.137939 | N2: =Inputs!$X2*Y2^Settings!$C$6 -> 281.12481 | O2: =Inputs!$Y2 -> 3.0869849 | P2: =R2*Inputs!$Z2/(Inputs!$Z2+Inputs!$AA2) -> 1.3675481 | Q2: =R2*Inputs!$AA2/(Inputs!$Z2+Inputs!$AA2) -> 0.49231732 | R2: =EXP((1-Settings!$C$3)*LN((Inputs!$Z2+Inputs!$AA2))+Settings!$C$3*LN(Inputs!$R2)) -> 1.8598654 | S2: =P2/Q2 -> 2.7777778 | T2: =R2*Inputs!$AB2/(Inputs!$Z2+Inputs!$AA2) -> 0.32844044 | U2: =T2/R2 -> 0.17659366 | V2: =Inputs!$AC2*Y2^Settings!$C$9 -> 14.330861 | W2: =Inputs!$AD2*Y2^Settings!$C$8 -> 10.673808 | X2: =K2/M2 -> 3.859865 | Y2: =R2/(Inputs!$Z2+Inputs!$AA2) -> 1.0955645
A3: 5 | B3: D1V2 | C3: D1 | D3: V2 | E3: Control | F3: Flowering | G3: 0 | H3: Healthy | I3: =Inputs!$S3 -> 85.041177 | J3: =Inputs!$T3*Y3^Settings!$C$7 -> 71.468278 | K3: =Inputs!$U3*Y3^Settings!$C$4 -> 19.699615 | L3: =Inputs!$V3*Y3^Settings!$C$5 -> 0.42469243 | M3: =Inputs!$W3*L3/Inputs!$V3 -> 5.110534 | N3: =Inputs!$X3*Y3^Settings!$C$6 -> 281.68918 | O3: =Inputs!$Y3 -> 3.2494578 | P3: =R3*Inputs!$Z3/(Inputs!$Z3+Inputs!$AA3) -> 1.3493852 | Q3: =R3*Inputs!$AA3/(Inputs!$Z3+Inputs!$AA3) -> 0.48577868 | R3: =EXP((1-Settings!$C$3)*LN((Inputs!$Z3+Inputs!$AA3))+Settings!$C$3*LN(Inputs!$R3)) -> 1.8351639 | S3: =P3/Q3 -> 2.7777778 | T3: =R3*Inputs!$AB3/(Inputs!$Z3+Inputs!$AA3) -> 0.32407831 | U3: =T3/R3 -> 0.17659366 | V3: =Inputs!$AC3*Y3^Settings!$C$9 -> 14.426986 | W3: =Inputs!$AD3*Y3^Settings!$C$8 -> 11.039968 | X3: =K3/M3 -> 3.8547077 | Y3: =R3/(Inputs!$Z3+Inputs!$AA3) -> 1.0810139
A4: 3 | B4: D1V3 | C4: D1 | D4: V3 | E4: Control | F4: Flowering | G4: 0 | H4: Healthy | I4: =Inputs!$S4 -> 85.041177 | J4: =Inputs!$T4*Y4^Settings!$C$7 -> 70.508863 | K4: =Inputs!$U4*Y4^Settings!$C$4 -> 19.616474 | L4: =Inputs!$V4*Y4^Settings!$C$5 -> 0.41336653 | M4: =Inputs!$W4*L4/Inputs!$V4 -> 4.9742438 | N4: =Inputs!$X4*Y4^Settings!$C$6 -> 284.55903 | O4: =Inputs!$Y4 -> 3.2494578 | P4: =R4*Inputs!$Z4/(Inputs!$Z4+Inputs!$AA4) -> 1.2990479 | Q4: =R4*Inputs!$AA4/(Inputs!$Z4+Inputs!$AA4) -> 0.46765723 | R4: =EXP((1-Settings!$C$3)*LN((Inputs!$Z4+Inputs!$AA4))+Settings!$C$3*LN(Inputs!$R4)) -> 1.7667051 | S4: =P4/Q4 -> 2.7777778 | T4: =R4*Inputs!$AB4/(Inputs!$Z4+Inputs!$AA4) -> 0.31198892 | U4: =T4/R4 -> 0.17659366 | V4: =Inputs!$AC4*Y4^Settings!$C$9 -> 14.922777 | W4: =Inputs!$AD4*Y4^Settings!$C$8 -> 10.017045 | X4: =K4/M4 -> 3.9436092 | Y4: =R4/(Inputs!$Z4+Inputs!$AA4) -> 1.0103765
A5: 9 | B5: D2V1 | C5: D2 | D5: V1 | E5: Control | F5: Flowering | G5: 0 | H5: Healthy | I5: =Inputs!$S5 -> 85.041177 | J5: =Inputs!$T5*Y5^Settings!$C$7 -> 71.81726 | K5: =Inputs!$U5*Y5^Settings!$C$4 -> 19.94098 | L5: =Inputs!$V5*Y5^Settings!$C$5 -> 0.42885012 | M5: =Inputs!$W5*L5/Inputs!$V5 -> 5.1605656 | N5: =Inputs!$X5*Y5^Settings!$C$6 -> 280.66195 | O5: =Inputs!$Y5 -> 2.7101143 | P5: =R5*Inputs!$Z5/(Inputs!$Z5+Inputs!$AA5) -> 1.382654 | Q5: =R5*Inputs!$AA5/(Inputs!$Z5+Inputs!$AA5) -> 0.49775544 | R5: =EXP((1-Settings!$C$3)*LN((Inputs!$Z5+Inputs!$AA5))+Settings!$C$3*LN(Inputs!$R5)) -> 1.8804094 | S5: =P5/Q5 -> 2.7777778 | T5: =R5*Inputs!$AB5/(Inputs!$Z5+Inputs!$AA5) -> 0.33206838 | U5: =T5/R5 -> 0.17659366 | V5: =Inputs!$AC5*Y5^Settings!$C$9 -> 14.252362 | W5: =Inputs!$AD5*Y5^Settings!$C$8 -> 10.709043 | X5: =K5/M5 -> 3.8641075 | Y5: =R5/(Inputs!$Z5+Inputs!$AA5) -> 1.107666
A6: 2 | B6: D2V2 | C6: D2 | D6: V2 | E6: Control | F6: Flowering | G6: 0 | H6: Healthy | I6: =Inputs!$S6 -> 85.041177 | J6: =Inputs!$T6*Y6^Settings!$C$7 -> 69.872802 | K6: =Inputs!$U6*Y6^Settings!$C$4 -> 18.618506 | L6: =Inputs!$V6*Y6^Settings!$C$5 -> 0.4059422 | M6: =Inputs!$W6*L6/Inputs!$V6 -> 4.8849032 | N6: =Inputs!$X6*Y6^Settings!$C$6 -> 286.49961 | O6: =Inputs!$Y6 -> 2.8527519 | P6: =R6*Inputs!$Z6/(Inputs!$Z6+Inputs!$AA6) -> 1.2053417 | Q6: =R6*Inputs!$AA6/(Inputs!$Z6+Inputs!$AA6) -> 0.433923 | R6: =EXP((1-Settings!$C$3)*LN((Inputs!$Z6+Inputs!$AA6))+Settings!$C$3*LN(Inputs!$R6)) -> 1.6392647 | S6: =P6/Q6 -> 2.7777778 | T6: =R6*Inputs!$AB6/(Inputs!$Z6+Inputs!$AA6) -> 0.28948375 | U6: =T6/R6 -> 0.17659366 | V6: =Inputs!$AC6*Y6^Settings!$C$9 -> 15.264708 | W6: =Inputs!$AD6*Y6^Settings!$C$8 -> 10.67235 | X6: =K6/M6 -> 3.8114381 | Y6: =R6/(Inputs!$Z6+Inputs!$AA6) -> 0.9656183
A7: 8 | B7: D2V3 | C7: D2 | D7: V3 | E7: Control | F7: Flowering | G7: 0 | H7: Healthy | I7: =Inputs!$S7 -> 85.041177 | J7: =Inputs!$T7*Y7^Settings!$C$7 -> 71.605732 | K7: =Inputs!$U7*Y7^Settings!$C$4 -> 20.388305 | L7: =Inputs!$V7*Y7^Settings!$C$5 -> 0.42632761 | M7: =Inputs!$W7*L7/Inputs!$V7 -> 5.1302109 | N7: =Inputs!$X7*Y7^Settings!$C$6 -> 281.28354 | O7: =Inputs!$Y7 -> 2.8527519 | P7: =R7*Inputs!$Z7/(Inputs!$Z7+Inputs!$AA7) -> 1.4032839 | Q7: =R7*Inputs!$AA7/(Inputs!$Z7+Inputs!$AA7) -> 0.50518219 | R7: =EXP((1-Settings!$C$3)*LN((Inputs!$Z7+Inputs!$AA7))+Settings!$C$3*LN(Inputs!$R7)) -> 1.908466 | S7: =P7/Q7 -> 2.7777778 | T7: =R7*Inputs!$AB7/(Inputs!$Z7+Inputs!$AA7) -> 0.337023 | U7: =T7/R7 -> 0.17659366 | V7: =Inputs!$AC7*Y7^Settings!$C$9 -> 14.357851 | W7: =Inputs!$AD7*Y7^Settings!$C$8 -> 10.251697 | X7: =K7/M7 -> 3.9741651 | Y7: =R7/(Inputs!$Z7+Inputs!$AA7) -> 1.0914494
A8: 4 | B8: D3V1 | C8: D3 | D8: V1 | E8: Control | F8: Flowering | G8: 0 | H8: Healthy | I8: =Inputs!$S8 -> 85.041177 | J8: =Inputs!$T8*Y8^Settings!$C$7 -> 72.129358 | K8: =Inputs!$U8*Y8^Settings!$C$4 -> 20.158332 | L8: =Inputs!$V8*Y8^Settings!$C$5 -> 0.43258555 | M8: =Inputs!$W8*L8/Inputs!$V8 -> 5.2055158 | N8: =Inputs!$X8*Y8^Settings!$C$6 -> 279.75065 | O8: =Inputs!$Y8 -> 2.140268 | P8: =R8*Inputs!$Z8/(Inputs!$Z8+Inputs!$AA8) -> 1.4129594 | Q8: =R8*Inputs!$AA8/(Inputs!$Z8+Inputs!$AA8) -> 0.50866538 | R8: =EXP((1-Settings!$C$3)*LN((Inputs!$Z8+Inputs!$AA8))+Settings!$C$3*LN(Inputs!$R8)) -> 1.9216248 | S8: =P8/Q8 -> 2.7777778 | T8: =R8*Inputs!$AB8/(Inputs!$Z8+Inputs!$AA8) -> 0.33934675 | U8: =T8/R8 -> 0.17659366 | V8: =Inputs!$AC8*Y8^Settings!$C$9 -> 14.803624 | W8: =Inputs!$AD8*Y8^Settings!$C$8 -> 10.778926 | X8: =K8/M8 -> 3.8724946 | Y8: =R8/(Inputs!$Z8+Inputs!$AA8) -> 1.1319442
A9: 11 | B9: D3V2 | C9: D3 | D9: V2 | E9: Control | F9: Vegetative | G9: 0 | H9: Healthy | I9: =Inputs!$S9 -> 85.900179 | J9: =Inputs!$T9*Y9^Settings!$C$7 -> 73.496568 | K9: =Inputs!$U9*Y9^Settings!$C$4 -> 20.086639 | L9: =Inputs!$V9*Y9^Settings!$C$5 -> 0.43135432 | M9: =Inputs!$W9*L9/Inputs!$V9 -> 5.1906998 | N9: =Inputs!$X9*Y9^Settings!$C$6 -> 280.04983 | O9: =Inputs!$Y9 -> 2.2529137 | P9: =R9*Inputs!$Z9/(Inputs!$Z9+Inputs!$AA9) -> 1.3327805 | Q9: =R9*Inputs!$AA9/(Inputs!$Z9+Inputs!$AA9) -> 0.47980099 | R9: =EXP((1-Settings!$C$3)*LN((Inputs!$Z9+Inputs!$AA9))+Settings!$C$3*LN(Inputs!$R9)) -> 1.8125815 | S9: =P9/Q9 -> 2.7777778 | T9: =R9*Inputs!$AB9/(Inputs!$Z9+Inputs!$AA9) -> 0.3200904 | U9: =T9/R9 -> 0.17659366 | V9: =Inputs!$AC9*Y9^Settings!$C$9 -> 16.342108 | W9: =Inputs!$AD9*Y9^Settings!$C$8 -> 12.063165 | X9: =K9/M9 -> 3.8697362 | Y9: =R9/(Inputs!$Z9+Inputs!$AA9) -> 1.1239069
A10: 10 | B10: D3V3 | C10: D3 | D10: V3 | E10: Control | F10: Vegetative | G10: 0 | H10: Healthy | I10: =Inputs!$S10 -> 85.900179 | J10: =Inputs!$T10*Y10^Settings!$C$7 -> 73.115267 | K10: =Inputs!$U10*Y10^Settings!$C$4 -> 20.421941 | L10: =Inputs!$V10*Y10^Settings!$C$5 -> 0.42689019 | M10: =Inputs!$W10*L10/Inputs!$V10 -> 5.1369807 | N10: =Inputs!$X10*Y10^Settings!$C$6 -> 281.14447 | O10: =Inputs!$Y10 -> 2.2529137 | P10: =R10*Inputs!$Z10/(Inputs!$Z10+Inputs!$AA10) -> 1.337522 | Q10: =R10*Inputs!$AA10/(Inputs!$Z10+Inputs!$AA10) -> 0.4815079 | R10: =EXP((1-Settings!$C$3)*LN((Inputs!$Z10+Inputs!$AA10))+Settings!$C$3*LN(Inputs!$R10)) -> 1.8190299 | S10: =P10/Q10 -> 2.7777778 | T10: =R10*Inputs!$AB10/(Inputs!$Z10+Inputs!$AA10) -> 0.32122914 | U10: =T10/R10 -> 0.17659366 | V10: =Inputs!$AC10*Y10^Settings!$C$9 -> 16.556005 | W10: =Inputs!$AD10*Y10^Settings!$C$8 -> 11.082789 | X10: =K10/M10 -> 3.9754756 | Y10: =R10/(Inputs!$Z10+Inputs!$AA10) -> 1.0950537
A11: 12 | B11: D4V1 | C11: D4 | D11: V1 | E11: Control | F11: Vegetative | G11: 0 | H11: Healthy | I11: =Inputs!$S11 -> 85.900179 | J11: =Inputs!$T11*Y11^Settings!$C$7 -> 72.600944 | K11: =Inputs!$U11*Y11^Settings!$C$4 -> 19.480284 | L11: =Inputs!$V11*Y11^Settings!$C$5 -> 0.42090546 | M11: =Inputs!$W11*L11/Inputs!$V11 -> 5.0649636 | N11: =Inputs!$X11*Y11^Settings!$C$6 -> 282.63693 | O11: =Inputs!$Y11 -> 1.3380911 | P11: =R11*Inputs!$Z11/(Inputs!$Z11+Inputs!$AA11) -> 1.2535298 | Q11: =R11*Inputs!$AA11/(Inputs!$Z11+Inputs!$AA11) -> 0.45127074 | R11: =EXP((1-Settings!$C$3)*LN((Inputs!$Z11+Inputs!$AA11))+Settings!$C$3*LN(Inputs!$R11)) -> 1.7048006 | S11: =P11/Q11 -> 2.7777778 | T11: =R11*Inputs!$AB11/(Inputs!$Z11+Inputs!$AA11) -> 0.30105697 | U11: =T11/R11 -> 0.17659366 | V11: =Inputs!$AC11*Y11^Settings!$C$9 -> 18.455618 | W11: =Inputs!$AD11*Y11^Settings!$C$8 -> 11.404695 | X11: =K11/M11 -> 3.8460857 | Y11: =R11/(Inputs!$Z11+Inputs!$AA11) -> 1.0570764
A12: 1 | B12: D4V2 | C12: D4 | D12: V2 | E12: Control | F12: Vegetative | G12: 0 | H12: Healthy | I12: =Inputs!$S12 -> 85.900179 | J12: =Inputs!$T12*Y12^Settings!$C$7 -> 71.863095 | K12: =Inputs!$U12*Y12^Settings!$C$4 -> 18.989102 | L12: =Inputs!$V12*Y12^Settings!$C$5 -> 0.41239355 | M12: =Inputs!$W12*L12/Inputs!$V12 -> 4.9625356 | N12: =Inputs!$X12*Y12^Settings!$C$6 -> 284.81061 | O12: =Inputs!$Y12 -> 1.408517 | P12: =R12*Inputs!$Z12/(Inputs!$Z12+Inputs!$AA12) -> 1.1911129 | Q12: =R12*Inputs!$AA12/(Inputs!$Z12+Inputs!$AA12) -> 0.42880065 | R12: =EXP((1-Settings!$C$3)*LN((Inputs!$Z12+Inputs!$AA12))+Settings!$C$3*LN(Inputs!$R12)) -> 1.6199136 | S12: =P12/Q12 -> 2.7777778 | T12: =R12*Inputs!$AB12/(Inputs!$Z12+Inputs!$AA12) -> 0.28606647 | U12: =T12/R12 -> 0.17659366 | V12: =Inputs!$AC12*Y12^Settings!$C$9 -> 18.933001 | W12: =Inputs!$AD12*Y12^Settings!$C$8 -> 11.66325 | X12: =K12/M12 -> 3.8264918 | Y12: =R12/(Inputs!$Z12+Inputs!$AA12) -> 1.0044415
A13: 6 | B13: D4V3 | C13: D4 | D13: V3 | E13: Control | F13: Vegetative | G13: 0 | H13: Healthy | I13: =Inputs!$S13 -> 85.900179 | J13: =Inputs!$T13*Y13^Settings!$C$7 -> 72.640564 | K13: =Inputs!$U13*Y13^Settings!$C$4 -> 20.092078 | L13: =Inputs!$V13*Y13^Settings!$C$5 -> 0.42136499 | M13: =Inputs!$W13*L13/Inputs!$V13 -> 5.0704932 | N13: =Inputs!$X13*Y13^Settings!$C$6 -> 282.5213 | O13: =Inputs!$Y13 -> 1.408517 | P13: =R13*Inputs!$Z13/(Inputs!$Z13+Inputs!$AA13) -> 1.2946626 | Q13: =R13*Inputs!$AA13/(Inputs!$Z13+Inputs!$AA13) -> 0.46607853 | R13: =EXP((1-Settings!$C$3)*LN((Inputs!$Z13+Inputs!$AA13))+Settings!$C$3*LN(Inputs!$R13)) -> 1.7607411 | S13: =P13/Q13 -> 2.7777778 | T13: =R13*Inputs!$AB13/(Inputs!$Z13+Inputs!$AA13) -> 0.31093572 | U13: =T13/R13 -> 0.17659366 | V13: =Inputs!$AC13*Y13^Settings!$C$9 -> 18.430463 | W13: =Inputs!$AD13*Y13^Settings!$C$8 -> 10.975031 | X13: =K13/M13 -> 3.9625491 | Y13: =R13/(Inputs!$Z13+Inputs!$AA13) -> 1.0599639
... A49: 20 | B49: D4V3 | C49: D4 | D49: V3 | E49: R3 | F49: Vegetative | G49: 44.4 | H49: High | I49: =Inputs!$S49 -> 85.090799 | J49: =Inputs!$T49*Y49^Settings!$C$7 -> 70.837038 | K49: =Inputs!$U49*Y49^Settings!$C$4 -> 17.085098 | L49: =Inputs!$V49*Y49^Settings!$C$5 -> 0.38370819 | M49: =Inputs!$W49*L49/Inputs!$V49 -> 4.6946622 | N49: =Inputs!$X49*Y49^Settings!$C$6 -> 298.06594 | O49: =Inputs!$Y49 -> 1.3254564 | P49: =R49*Inputs!$Z49/(Inputs!$Z49+Inputs!$AA49) -> 1.1930221 | Q49: =R49*Inputs!$AA49/(Inputs!$Z49+Inputs!$AA49) -> 0.43981655 | R49: =EXP((1-Settings!$C$3)*LN((Inputs!$Z49+Inputs!$AA49))+Settings!$C$3*LN(Inputs!$R49)) -> 1.6328386 | S49: =P49/Q49 -> 2.7125448 | T49: =R49*Inputs!$AB49/(Inputs!$Z49+Inputs!$AA49) -> 0.32626045 | U49: =T49/R49 -> 0.19981182 | V49: =Inputs!$AC49*Y49^Settings!$C$9 -> 19.832224 | W49: =Inputs!$AD49*Y49^Settings!$C$8 -> 10.820291 | X49: =K49/M49 -> 3.6392604 | Y49: =R49/(Inputs!$Z49+Inputs!$AA49) -> 1.093273

Sheet Settings
A1: Combination settings (yellow = editable)
A2: Name | B2: Meaning | C2: Value
A3: w_spec | B3: Weight of spectral chlorophyll in total chlorophyll (0-1) | C3: 0.5
A4: e_Pn | B4: Exponent of chlorophyll ratio on Pn | C4: 0.5
A5: e_gs | B5: Exponent of chlorophyll ratio on gs (E follows gs) | C5: 0.4
A6: e_Ci | B6: Exponent of chlorophyll ratio on Ci | C6: -0.15
A7: e_MSI | B7: Exponent of chlorophyll ratio on MSI | C7: 0.2
A8: e_Prot | B8: Exponent of chlorophyll ratio on protein | C8: 0.3
A9: e_Anth | B9: Exponent of chlorophyll ratio on anthocyanin | C9: -0.5
A10: kappa | B10: s_eff = kappa x pustule leaf area (fitted from spectra; information only) | C10: 0.47
A12: Coefficients of variation for ranges (model values)
A13: Code | B13: Parameter | C13: CV
A14: RWC | B14: RWC | C14: 0.04
A15: MSI | B15: MSI | C15: 0.07
A16: Pn | B16: Pn | C16: 0.12
A17: gs | B17: gs | C17: 0.18
A18: E | B18: E | C18: 0.18
A19: Ci | B19: Ci | C19: 0.06
A20: LAI | B20: LAI | C20: 0.12
A21: ChlA | B21: ChlA | C21: 0.1
A22: ChlB | B22: ChlB | C22: 0.12
A23: Car | B23: Car | C23: 0.12
A24: Anth | B24: Anth | C24: 0.3
A25: Prot | B25: Prot | C25: 0.12
... A27: WUE | B27: WUE | C27: 0.15

Sheet Inputs
A1: Plot | B1: Treatment | C1: Sowing | D1: Variety | E1: Replication | F1: Growth stage | G1: Plot DI (%) | H1: Severity class | I1: Spectra (n) | J1: Leaves scanned | K1: Mean leaf grade | L1: Pustule leaf area A (%) | M1: s_eff | N1: MTCI | O1: Chl rel. to own healthy plot | P1: Cab spectral (ug cm-2) | Q1: Fresh mass per area (g cm-2) | R1: Total chl spectral (mg g-1 FW) | S1: RWC prior | T1: MSI prior | U1: Pn prior | V1: gs prior | W1: E prior | X1: Ci prior | Y1: LAI prior | Z1: ChlA prior | AA1: ChlB prior | AB1: Car prior | AC1: Anth prior | AD1: Prot prior | AE1: gs healthy | AF1: E healthy
A2: 7 | B2: D1V1 | C2: D1 | D2: V1 | E2: Control | F2: Flowering | G2: 0 | H2: Healthy | I2: 9 | J2: 3 L3 / 3 L5 / 3 LL | K2: 0 | L2: 0 | M2: 0 | N2: 1.5816986 | O2: 1 | P2: 52.224519 | Q2: 0.025630377 | R2: 2.0376025 | S2: 85.041177 | T2: 70.36344 | U2: 18.947071 | V2: 0.41166316 | W2: 4.9537464 | X2: 285 | Y2: 3.0869849 | Z2: 1.2482589 | AA2: 0.44937321 | AB2: 0.29979107 | AC2: 15 | AD2: 10.385514 | AE2: 0.41166316 | AF2: 4.9537464
A3: 5 | B3: D1V2 | C3: D1 | D3: V2 | E3: Control | F3: Flowering | G3: 0 | H3: Healthy | I3: 9 | J3: 3 L3 / 3 L5 / 3 LL | K3: 0 | L3: 0 | M3: 0 | N3: 1.5309995 | O3: 1 | P3: 50.846507 | Q3: 0.025630377 | R3: 1.9838377 | S3: 85.041177 | T3: 70.36344 | U3: 18.947071 | V3: 0.41166316 | W3: 4.9537464 | X3: 285 | Y3: 3.2494578 | Z3: 1.2482589 | AA3: 0.44937321 | AB3: 0.29979107 | AC3: 15 | AD3: 10.784957 | AE3: 0.41166316 | AF3: 4.9537464
A4: 3 | B4: D1V3 | C4: D1 | D4: V3 | E4: Control | F4: Flowering | G4: 0 | H4: Healthy | I4: 9 | J4: 3 L3 / 3 L5 / 3 LL | K4: 0 | L4: 0 | M4: 0 | N4: 1.3492965 | O4: 1 | P4: 45.75118 | Q4: 0.025630377 | R4: 1.7850374 | S4: 85.041177 | T4: 70.36344 | U4: 19.515484 | V4: 0.41166316 | W4: 4.9537464 | X4: 285 | Y4: 3.2494578 | Z4: 1.2857067 | AA4: 0.46285441 | AB4: 0.3087848 | AC4: 15 | AD4: 9.9860714 | AE4: 0.41166316 | AF4: 4.9537464
A5: 9 | B5: D2V1 | C5: D2 | D5: V1 | E5: Control | F5: Flowering | G5: 0 | H5: Healthy | I5: 9 | J5: 3 L3 / 3 L5 / 3 LL | K5: 0 | L5: 0 | M5: 0 | N5: 1.624902 | O5: 1 | P5: 53.38463 | Q5: 0.025630377 | R5: 2.0828656 | S5: 85.041177 | T5: 70.36344 | U5: 18.947071 | V5: 0.41166316 | W5: 4.9537464 | X5: 285 | Y5: 2.7101143 | Z5: 1.2482589 | AA5: 0.44937321 | AB5: 0.29979107 | AC5: 15 | AD5: 10.385514 | AE5: 0.41166316 | AF5: 4.9537464
A6: 2 | B6: D2V2 | C6: D2 | D6: V2 | E6: Control | F6: Flowering | G6: 0 | H6: Healthy | I6: 9 | J6: 3 L3 / 3 L5 / 3 LL | K6: 0 | L6: 0 | M6: 0 | N6: 1.1736825 | O6: 1 | P6: 40.570425 | Q6: 0.025630377 | R6: 1.582904 | S6: 85.041177 | T6: 70.36344 | U6: 18.947071 | V6: 0.41166316 | W6: 4.9537464 | X6: 285 | Y6: 2.8527519 | Z6: 1.2482589 | AA6: 0.44937321 | AB6: 0.29979107 | AC6: 15 | AD6: 10.784957 | AE6: 0.41166316 | AF6: 4.9537464
A7: 8 | B7: D2V3 | C7: D2 | D7: V3 | E7: Control | F7: Flowering | G7: 0 | H7: Healthy | I7: 9 | J7: 3 L3 / 3 L5 / 3 LL | K7: 0 | L7: 0 | M7: 0 | N7: 1.6250254 | O7: 1 | P7: 53.387926 | Q7: 0.025630377 | R7: 2.0829942 | S7: 85.041177 | T7: 70.36344 | U7: 19.515484 | V7: 0.41166316 | W7: 4.9537464 | X7: 285 | Y7: 2.8527519 | Z7: 1.2857067 | AA7: 0.46285441 | AB7: 0.3087848 | AC7: 15 | AD7: 9.9860714 | AE7: 0.41166316 | AF7: 4.9537464
A8: 4 | B8: D3V1 | C8: D3 | D8: V1 | E8: Control | F8: Flowering | G8: 0 | H8: Healthy | I8: 6 | J8: 3 L3 / 3 L5 / 0 LL | K8: 0 | L8: 0 | M8: 0 | N8: 1.7144974 | O8: 1 | P8: 55.750476 | Q8: 0.025630377 | R8: 2.1751719 | S8: 85.041177 | T8: 70.36344 | U8: 18.947071 | V8: 0.41166316 | W8: 4.9537464 | X8: 285 | Y8: 2.140268 | Z8: 1.2482589 | AA8: 0.44937321 | AB8: 0.29979107 | AC8: 15.75 | AD8: 10.385514 | AE8: 0.41166316 | AF8: 4.9537464
A9: 11 | B9: D3V2 | C9: D3 | D9: V2 | E9: Control | F9: Vegetative | G9: 0 | H9: Healthy | I9: 6 | J9: 3 L3 / 3 L5 / 0 LL | K9: 0 | L9: 0 | M9: 0 | N9: 1.4803245 | O9: 1 | P9: 47.63978 | Q9: 0.023385241 | R9: 2.037173 | S9: 85.900179 | T9: 71.799429 | U9: 18.947071 | V9: 0.41166316 | W9: 4.9537464 | X9: 285 | Y9: 2.2529137 | Z9: 1.185846 | AA9: 0.42690455 | AB9: 0.28480152 | AC9: 17.325 | AD9: 11.647754 | AE9: 0.41166316 | AF9: 4.9537464
A10: 10 | B10: D3V3 | C10: D3 | D10: V3 | E10: Control | F10: Vegetative | G10: 0 | H10: Healthy | I10: 6 | J10: 3 L3 / 3 L5 / 0 LL | K10: 0 | L10: 0 | M10: 0 | N10: 1.4404584 | O10: 1 | P10: 46.581888 | Q10: 0.023385241 | R10: 1.9919353 | S10: 85.900179 | T10: 71.799429 | U10: 19.515484 | V10: 0.41166316 | W10: 4.9537464 | X10: 285 | Y10: 2.2529137 | Z10: 1.2214214 | AA10: 0.43971169 | AB10: 0.29334556 | AC10: 17.325 | AD10: 10.784957 | AE10: 0.41166316 | AF10: 4.9537464
A11: 12 | B11: D4V1 | C11: D4 | D11: V1 | E11: Control | F11: Vegetative | G11: 0 | H11: Healthy | I11: 6 | J11: 3 L3 / 3 L5 / 0 LL | K11: 0 | L11: 0 | M11: 0 | N11: 1.2778945 | O11: 1 | P11: 42.142648 | Q11: 0.023385241 | R11: 1.8021045 | S11: 85.900179 | T11: 71.799429 | U11: 18.947071 | V11: 0.41166316 | W11: 4.9537464 | X11: 285 | Y11: 1.3380911 | Z11: 1.185846 | AA11: 0.42690455 | AB11: 0.28480152 | AC11: 18.975 | AD11: 11.216355 | AE11: 0.41166316 | AF11: 4.9537464
A12: 1 | B12: D4V2 | C12: D4 | D12: V2 | E12: Control | F12: Vegetative | G12: 0 | H12: Healthy | I12: 6 | J12: 3 L3 / 3 L5 / 0 LL | K12: 0 | L12: 0 | M12: 0 | N12: 1.1346966 | O12: 1 | P12: 38.050322 | Q12: 0.023385241 | R12: 1.6271084 | S12: 85.900179 | T12: 71.799429 | U12: 18.947071 | V12: 0.41166316 | W12: 4.9537464 | X12: 285 | Y12: 1.408517 | Z12: 1.185846 | AA12: 0.42690455 | AB12: 0.28480152 | AC12: 18.975 | AD12: 11.647754 | AE12: 0.41166316 | AF12: 4.9537464
A13: 6 | B13: D4V3 | C13: D4 | D13: V3 | E13: Control | F13: Vegetative | G13: 0 | H13: Healthy | I13: 6 | J13: 3 L3 / 3 L5 / 0 LL | K13: 0 | L13: 0 | M13: 0 | N13: 1.3320391 | O13: 1 | P13: 43.644391 | Q13: 0.023385241 | R13: 1.8663221 | S13: 85.900179 | T13: 71.799429 | U13: 19.515484 | V13: 0.41166316 | W13: 4.9537464 | X13: 285 | Y13: 1.408517 | Z13: 1.2214214 | AA13: 0.43971169 | AB13: 0.29334556 | AC13: 18.975 | AD13: 10.784957 | AE13: 0.41166316 | AF13: 4.9537464
... A49: 20 | B49: D4V3 | C49: D4 | D49: V3 | E49: R3 | F49: Vegetative | G49: 44.4 | H49: High | I49: 10 | J49: 5 L3 / 5 L5 / 0 LL | K49: 4 | L49: 14.25 | M49: 0.066975 | N49: 1.260541 | O49: 0.95234973 | P49: 41.371031 | Q49: 0.023175252 | R49: 1.7851384 | S49: 85.090799 | T49: 69.584845 | U49: 16.340042 | V49: 0.37026241 | W49: 4.5301533 | X49: 302.07977 | Y49: 1.3254564 | Z49: 1.0912389 | AA49: 0.40229343 | AB49: 0.29842542 | AC49: 20.736513 | AD49: 10.534656 | AE49: 0.41166316 | AF49: 4.9537464

Sheet Ranges
A1: Plot | B1: Treatment | C1: RWC (%) low | D1: RWC (%) high | E1: MSI (%) low | F1: MSI (%) high | G1: Pn (umol CO2 m-2 s-1) low | H1: Pn (umol CO2 m-2 s-1) high | I1: gs (mol H2O m-2 s-1) low | J1: gs (mol H2O m-2 s-1) high | K1: E (mmol H2O m-2 s-1) low | L1: E (mmol H2O m-2 s-1) high | M1: Ci (umol mol-1) low | N1: Ci (umol mol-1) high | O1: LAI (m2 m-2) low | P1: LAI (m2 m-2) high | Q1: Chl a (ug mg-1 FW) low | R1: Chl a (ug mg-1 FW) high | S1: Chl b (ug mg-1 FW) low | T1: Chl b (ug mg-1 FW) high | U1: Total chl (ug mg-1 FW) low | V1: Total chl (ug mg-1 FW) high | W1: Carotenoids (mg g-1 FW) low | X1: Carotenoids (mg g-1 FW) high | Y1: Anthocyanin (ug g-1 FW) low | Z1: Anthocyanin (ug g-1 FW) high | AA1: Total protein (ug mg-1 FW) low | AB1: Total protein (ug mg-1 FW) high | AC1: WUE Pn/E (umol mmol-1) low | AD1: WUE Pn/E (umol mmol-1) high
A2: 7 | B2: D1V1 | C2: =Estimates!I2*(1-1.645*Settings!$C$14) -> 79.445467 | D2: =Estimates!I2*(1+1.645*Settings!$C$14) -> 90.636886 | E2: =Estimates!J2*(1-1.645*Settings!$C$15) -> 63.408037 | F2: =Estimates!J2*(1+1.645*Settings!$C$15) -> 79.911253 | G2: =Estimates!K2*(1-1.645*Settings!$C$16) -> 15.916963 | H2: =Estimates!K2*(1+1.645*Settings!$C$16) -> 23.746539 | I2: =Estimates!L2*(1-1.645*Settings!$C$17) -> 0.30054406 | J2: =Estimates!L2*(1+1.645*Settings!$C$17) -> 0.55339559 | K2: =Estimates!M2*(1-1.645*Settings!$C$18) -> 3.6165953 | L2: =Estimates!M2*(1+1.645*Settings!$C$18) -> 6.6592828 | M2: =Estimates!N2*(1-1.645*Settings!$C$19) -> 253.37779 | N2: =Estimates!N2*(1+1.645*Settings!$C$19) -> 308.87182 | O2: =Estimates!O2*(1-1.645*Settings!$C$20) -> 2.4776141 | P2: =Estimates!O2*(1+1.645*Settings!$C$20) -> 3.6963557 | Q2: =Estimates!P2*(1-1.645*Settings!$C$21) -> 1.1425865 | R2: =Estimates!P2*(1+1.645*Settings!$C$21) -> 1.5925098 | S2: =Estimates!Q2*(1-1.645*Settings!$C$22) -> 0.39513388 | T2: =Estimates!Q2*(1+1.645*Settings!$C$22) -> 0.58950076 | U2: =Estimates!R2*(1-1.645*Settings!$C$26) -> 1.5539176 | V2: =Estimates!R2*(1+1.645*Settings!$C$26) -> 2.1658133 | W2: =Estimates!T2*(1-1.645*Settings!$C$23) -> 0.2636063 | X2: =Estimates!T2*(1+1.645*Settings!$C$23) -> 0.39327459 | Y2: =Estimates!V2*(1-1.645*Settings!$C$24) -> 7.2585812 | Z2: =Estimates!V2*(1+1.645*Settings!$C$24) -> 21.403141 | AA2: =Estimates!W2*(1-1.645*Settings!$C$25) -> 8.5667983 | AB2: =Estimates!W2*(1+1.645*Settings!$C$25) -> 12.780818 | AC2: =Estimates!X2*(1-1.645*Settings!$C$27) -> 2.9074433 | AD2: =Estimates!X2*(1+1.645*Settings!$C$27) -> 4.8122867
A3: 5 | B3: D1V2 | C3: =Estimates!I3*(1-1.645*Settings!$C$14) -> 79.445467 | D3: =Estimates!I3*(1+1.645*Settings!$C$14) -> 90.636886 | E3: =Estimates!J3*(1-1.645*Settings!$C$15) -> 63.238706 | F3: =Estimates!J3*(1+1.645*Settings!$C$15) -> 79.69785 | G3: =Estimates!K3*(1-1.645*Settings!$C$16) -> 15.810911 | H3: =Estimates!K3*(1+1.645*Settings!$C$16) -> 23.588318 | I3: =Estimates!L3*(1-1.645*Settings!$C$17) -> 0.298941 | J3: =Estimates!L3*(1+1.645*Settings!$C$17) -> 0.55044386 | K3: =Estimates!M3*(1-1.645*Settings!$C$18) -> 3.5973049 | L3: =Estimates!M3*(1+1.645*Settings!$C$18) -> 6.6237631 | M3: =Estimates!N3*(1-1.645*Settings!$C$19) -> 253.88646 | N3: =Estimates!N3*(1+1.645*Settings!$C$19) -> 309.4919 | O3: =Estimates!O3*(1-1.645*Settings!$C$20) -> 2.6080148 | P3: =Estimates!O3*(1+1.645*Settings!$C$20) -> 3.8909008 | Q3: =Estimates!P3*(1-1.645*Settings!$C$21) -> 1.1274114 | R3: =Estimates!P3*(1+1.645*Settings!$C$21) -> 1.5713591 | S3: =Estimates!Q3*(1-1.645*Settings!$C$22) -> 0.38988597 | T3: =Estimates!Q3*(1+1.645*Settings!$C$22) -> 0.5816714 | U3: =Estimates!R3*(1-1.645*Settings!$C$26) -> 1.5332795 | V3: =Estimates!R3*(1+1.645*Settings!$C$26) -> 2.1370484 | W3: =Estimates!T3*(1-1.645*Settings!$C$23) -> 0.26010525 | X3: =Estimates!T3*(1+1.645*Settings!$C$23) -> 0.38805137 | Y3: =Estimates!V3*(1-1.645*Settings!$C$24) -> 7.3072686 | Z3: =Estimates!V3*(1+1.645*Settings!$C$24) -> 21.546704 | AA3: =Estimates!W3*(1-1.645*Settings!$C$25) -> 8.8606781 | AB3: =Estimates!W3*(1+1.645*Settings!$C$25) -> 13.219257 | AC3: =Estimates!X3*(1-1.645*Settings!$C$27) -> 2.9035586 | AD3: =Estimates!X3*(1+1.645*Settings!$C$27) -> 4.8058568
A4: 3 | B4: D1V3 | C4: =Estimates!I4*(1-1.645*Settings!$C$14) -> 79.445467 | D4: =Estimates!I4*(1+1.645*Settings!$C$14) -> 90.636886 | E4: =Estimates!J4*(1-1.645*Settings!$C$15) -> 62.389768 | F4: =Estimates!J4*(1+1.645*Settings!$C$15) -> 78.627959 | G4: =Estimates!K4*(1-1.645*Settings!$C$16) -> 15.744182 | H4: =Estimates!K4*(1+1.645*Settings!$C$16) -> 23.488766 | I4: =Estimates!L4*(1-1.645*Settings!$C$17) -> 0.2909687 | J4: =Estimates!L4*(1+1.645*Settings!$C$17) -> 0.53576436 | K4: =Estimates!M4*(1-1.645*Settings!$C$18) -> 3.5013702 | L4: =Estimates!M4*(1+1.645*Settings!$C$18) -> 6.4471174 | M4: =Estimates!N4*(1-1.645*Settings!$C$19) -> 256.47305 | N4: =Estimates!N4*(1+1.645*Settings!$C$19) -> 312.64501 | O4: =Estimates!O4*(1-1.645*Settings!$C$20) -> 2.6080148 | P4: =Estimates!O4*(1+1.645*Settings!$C$20) -> 3.8909008 | Q4: =Estimates!P4*(1-1.645*Settings!$C$21) -> 1.0853545 | R4: =Estimates!P4*(1+1.645*Settings!$C$21) -> 1.5127412 | S4: =Estimates!Q4*(1-1.645*Settings!$C$22) -> 0.3753417 | T4: =Estimates!Q4*(1+1.645*Settings!$C$22) -> 0.55997277 | U4: =Estimates!R4*(1-1.645*Settings!$C$26) -> 1.4760821 | V4: =Estimates!R4*(1+1.645*Settings!$C$26) -> 2.0573281 | W4: =Estimates!T4*(1-1.645*Settings!$C$23) -> 0.25040231 | X4: =Estimates!T4*(1+1.645*Settings!$C$23) -> 0.37357553 | Y4: =Estimates!V4*(1-1.645*Settings!$C$24) -> 7.5583863 | Z4: =Estimates!V4*(1+1.645*Settings!$C$24) -> 22.287167 | AA4: =Estimates!W4*(1-1.645*Settings!$C$25) -> 8.0396807 | AB4: =Estimates!W4*(1+1.645*Settings!$C$25) -> 11.99441 | AC4: =Estimates!X4*(1-1.645*Settings!$C$27) -> 2.9705236 | AD4: =Estimates!X4*(1+1.645*Settings!$C$27) -> 4.9166948
A5: 9 | B5: D2V1 | C5: =Estimates!I5*(1-1.645*Settings!$C$14) -> 79.445467 | D5: =Estimates!I5*(1+1.645*Settings!$C$14) -> 90.636886 | E5: =Estimates!J5*(1-1.645*Settings!$C$15) -> 63.547502 | F5: =Estimates!J5*(1+1.645*Settings!$C$15) -> 80.087017 | G5: =Estimates!K5*(1-1.645*Settings!$C$16) -> 16.004631 | H5: =Estimates!K5*(1+1.645*Settings!$C$16) -> 23.87733 | I5: =Estimates!L5*(1-1.645*Settings!$C$17) -> 0.3018676 | J5: =Estimates!L5*(1+1.645*Settings!$C$17) -> 0.55583265 | K5: =Estimates!M5*(1-1.645*Settings!$C$18) -> 3.6325221 | L5: =Estimates!M5*(1+1.645*Settings!$C$18) -> 6.6886091 | M5: =Estimates!N5*(1-1.645*Settings!$C$19) -> 252.96061 | N5: =Estimates!N5*(1+1.645*Settings!$C$19) -> 308.36328 | O5: =Estimates!O5*(1-1.645*Settings!$C$20) -> 2.1751378 | P5: =Estimates!O5*(1+1.645*Settings!$C$20) -> 3.2450909 | Q5: =Estimates!P5*(1-1.645*Settings!$C$21) -> 1.1552074 | R5: =Estimates!P5*(1+1.645*Settings!$C$21) -> 1.6101006 | S5: =Estimates!Q5*(1-1.645*Settings!$C$22) -> 0.39949851 | T5: =Estimates!Q5*(1+1.645*Settings!$C$22) -> 0.59601236 | U5: =Estimates!R5*(1-1.645*Settings!$C$26) -> 1.5710821 | V5: =Estimates!R5*(1+1.645*Settings!$C$26) -> 2.1897368 | W5: =Estimates!T5*(1-1.645*Settings!$C$23) -> 0.26651808 | X5: =Estimates!T5*(1+1.645*Settings!$C$23) -> 0.39761868 | Y5: =Estimates!V5*(1-1.645*Settings!$C$24) -> 7.2188213 | Z5: =Estimates!V5*(1+1.645*Settings!$C$24) -> 21.285903 | AA5: =Estimates!W5*(1-1.645*Settings!$C$25) -> 8.5950778 | AB5: =Estimates!W5*(1+1.645*Settings!$C$25) -> 12.823008 | AC5: =Estimates!X5*(1-1.645*Settings!$C$27) -> 2.910639 | AD5: =Estimates!X5*(1+1.645*Settings!$C$27) -> 4.8175761
A6: 2 | B6: D2V2 | C6: =Estimates!I6*(1-1.645*Settings!$C$14) -> 79.445467 | D6: =Estimates!I6*(1+1.645*Settings!$C$14) -> 90.636886 | E6: =Estimates!J6*(1-1.645*Settings!$C$15) -> 61.826949 | F6: =Estimates!J6*(1+1.645*Settings!$C$15) -> 77.918655 | G6: =Estimates!K6*(1-1.645*Settings!$C$16) -> 14.943213 | H6: =Estimates!K6*(1+1.645*Settings!$C$16) -> 22.293799 | I6: =Estimates!L6*(1-1.645*Settings!$C$17) -> 0.28574272 | J6: =Estimates!L6*(1+1.645*Settings!$C$17) -> 0.52614169 | K6: =Estimates!M6*(1-1.645*Settings!$C$18) -> 3.4384834 | L6: =Estimates!M6*(1+1.645*Settings!$C$18) -> 6.3313231 | M6: =Estimates!N6*(1-1.645*Settings!$C$19) -> 258.2221 | N6: =Estimates!N6*(1+1.645*Settings!$C$19) -> 314.77712 | O6: =Estimates!O6*(1-1.645*Settings!$C$20) -> 2.2896187 | P6: =Estimates!O6*(1+1.645*Settings!$C$20) -> 3.4158852 | Q6: =Estimates!P6*(1-1.645*Settings!$C$21) -> 1.007063 | R6: =Estimates!P6*(1+1.645*Settings!$C$21) -> 1.4036204 | S6: =Estimates!Q6*(1-1.645*Settings!$C$22) -> 0.3482666 | T6: =Estimates!Q6*(1+1.645*Settings!$C$22) -> 0.5195794 | U6: =Estimates!R6*(1-1.645*Settings!$C$26) -> 1.3696056 | V6: =Estimates!R6*(1+1.645*Settings!$C$26) -> 1.9089237 | W6: =Estimates!T6*(1-1.645*Settings!$C$23) -> 0.23233965 | X6: =Estimates!T6*(1+1.645*Settings!$C$23) -> 0.34662784 | Y6: =Estimates!V6*(1-1.645*Settings!$C$24) -> 7.7315748 | Z6: =Estimates!V6*(1+1.645*Settings!$C$24) -> 22.797842 | AA6: =Estimates!W6*(1-1.645*Settings!$C$25) -> 8.5656283 | AB6: =Estimates!W6*(1+1.645*Settings!$C$25) -> 12.779072 | AC6: =Estimates!X6*(1-1.645*Settings!$C$27) -> 2.8709657 | AD6: =Estimates!X6*(1+1.645*Settings!$C$27) -> 4.7519104
A7: 8 | B7: D2V3 | C7: =Estimates!I7*(1-1.645*Settings!$C$14) -> 79.445467 | D7: =Estimates!I7*(1+1.645*Settings!$C$14) -> 90.636886 | E7: =Estimates!J7*(1-1.645*Settings!$C$15) -> 63.360332 | F7: =Estimates!J7*(1+1.645*Settings!$C$15) -> 79.851132 | G7: =Estimates!K7*(1-1.645*Settings!$C$16) -> 16.363654 | H7: =Estimates!K7*(1+1.645*Settings!$C$16) -> 24.412957 | I7: =Estimates!L7*(1-1.645*Settings!$C$17) -> 0.300092 | J7: =Estimates!L7*(1+1.645*Settings!$C$17) -> 0.55256321 | K7: =Estimates!M7*(1-1.645*Settings!$C$18) -> 3.6111555 | L7: =Estimates!M7*(1+1.645*Settings!$C$18) -> 6.6492664 | M7: =Estimates!N7*(1-1.645*Settings!$C$19) -> 253.52085 | N7: =Estimates!N7*(1+1.645*Settings!$C$19) -> 309.04622 | O7: =Estimates!O7*(1-1.645*Settings!$C$20) -> 2.2896187 | P7: =Estimates!O7*(1+1.645*Settings!$C$20) -> 3.4158852 | Q7: =Estimates!P7*(1-1.645*Settings!$C$21) -> 1.1724437 | R7: =Estimates!P7*(1+1.645*Settings!$C$21) -> 1.6341241 | S7: =Estimates!Q7*(1-1.645*Settings!$C$22) -> 0.40545922 | T7: =Estimates!Q7*(1+1.645*Settings!$C$22) -> 0.60490515 | U7: =Estimates!R7*(1-1.645*Settings!$C$26) -> 1.5945234 | V7: =Estimates!R7*(1+1.645*Settings!$C$26) -> 2.2224087 | W7: =Estimates!T7*(1-1.645*Settings!$C$23) -> 0.27049466 | X7: =Estimates!T7*(1+1.645*Settings!$C$23) -> 0.40355134 | Y7: =Estimates!V7*(1-1.645*Settings!$C$24) -> 7.2722516 | Z7: =Estimates!V7*(1+1.645*Settings!$C$24) -> 21.443451 | AA7: =Estimates!W7*(1-1.645*Settings!$C$25) -> 8.2280119 | AB7: =Estimates!W7*(1+1.645*Settings!$C$25) -> 12.275382 | AC7: =Estimates!X7*(1-1.645*Settings!$C$27) -> 2.9935399 | AD7: =Estimates!X7*(1+1.645*Settings!$C$27) -> 4.9547904
A8: 4 | B8: D3V1 | C8: =Estimates!I8*(1-1.645*Settings!$C$14) -> 79.445467 | D8: =Estimates!I8*(1+1.645*Settings!$C$14) -> 90.636886 | E8: =Estimates!J8*(1-1.645*Settings!$C$15) -> 63.823662 | F8: =Estimates!J8*(1+1.645*Settings!$C$15) -> 80.435053 | G8: =Estimates!K8*(1-1.645*Settings!$C$16) -> 16.179077 | H8: =Estimates!K8*(1+1.645*Settings!$C$16) -> 24.137587 | I8: =Estimates!L8*(1-1.645*Settings!$C$17) -> 0.30449697 | J8: =Estimates!L8*(1+1.645*Settings!$C$17) -> 0.56067413 | K8: =Estimates!M8*(1-1.645*Settings!$C$18) -> 3.6641626 | L8: =Estimates!M8*(1+1.645*Settings!$C$18) -> 6.7468691 | M8: =Estimates!N8*(1-1.645*Settings!$C$19) -> 252.13926 | N8: =Estimates!N8*(1+1.645*Settings!$C$19) -> 307.36204 | O8: =Estimates!O8*(1-1.645*Settings!$C$20) -> 1.7177791 | P8: =Estimates!O8*(1+1.645*Settings!$C$20) -> 2.5627569 | Q8: =Estimates!P8*(1-1.645*Settings!$C$21) -> 1.1805276 | R8: =Estimates!P8*(1+1.645*Settings!$C$21) -> 1.6453912 | S8: =Estimates!Q8*(1-1.645*Settings!$C$22) -> 0.40825484 | T8: =Estimates!Q8*(1+1.645*Settings!$C$22) -> 0.60907593 | U8: =Estimates!R8*(1-1.645*Settings!$C$26) -> 1.6055175 | V8: =Estimates!R8*(1+1.645*Settings!$C$26) -> 2.2377321 | W8: =Estimates!T8*(1-1.645*Settings!$C$23) -> 0.2723597 | X8: =Estimates!T8*(1+1.645*Settings!$C$23) -> 0.4063338 | Y8: =Estimates!V8*(1-1.645*Settings!$C$24) -> 7.4980357 | Z8: =Estimates!V8*(1+1.645*Settings!$C$24) -> 22.109213 | AA8: =Estimates!W8*(1-1.645*Settings!$C$25) -> 8.6511664 | AB8: =Estimates!W8*(1+1.645*Settings!$C$25) -> 12.906687 | AC8: =Estimates!X8*(1-1.645*Settings!$C$27) -> 2.9169566 | AD8: =Estimates!X8*(1+1.645*Settings!$C$27) -> 4.8280327
A9: 11 | B9: D3V2 | C9: =Estimates!I9*(1-1.645*Settings!$C$14) -> 80.247947 | D9: =Estimates!I9*(1+1.645*Settings!$C$14) -> 91.55241 | E9: =Estimates!J9*(1-1.645*Settings!$C$15) -> 65.033438 | F9: =Estimates!J9*(1+1.645*Settings!$C$15) -> 81.959698 | G9: =Estimates!K9*(1-1.645*Settings!$C$16) -> 16.121536 | H9: =Estimates!K9*(1+1.645*Settings!$C$16) -> 24.051741 | I9: =Estimates!L9*(1-1.645*Settings!$C$17) -> 0.3036303 | J9: =Estimates!L9*(1+1.645*Settings!$C$17) -> 0.55907833 | K9: =Estimates!M9*(1-1.645*Settings!$C$18) -> 3.6537336 | L9: =Estimates!M9*(1+1.645*Settings!$C$18) -> 6.727666 | M9: =Estimates!N9*(1-1.645*Settings!$C$19) -> 252.40891 | N9: =Estimates!N9*(1+1.645*Settings!$C$19) -> 307.69074 | O9: =Estimates!O9*(1-1.645*Settings!$C$20) -> 1.8081885 | P9: =Estimates!O9*(1+1.645*Settings!$C$20) -> 2.6976389 | Q9: =Estimates!P9*(1-1.645*Settings!$C$21) -> 1.1135381 | R9: =Estimates!P9*(1+1.645*Settings!$C$21) -> 1.5520229 | S9: =Estimates!Q9*(1-1.645*Settings!$C$22) -> 0.38508828 | T9: =Estimates!Q9*(1+1.645*Settings!$C$22) -> 0.57451371 | U9: =Estimates!R9*(1-1.645*Settings!$C$26) -> 1.5144119 | V9: =Estimates!R9*(1+1.645*Settings!$C$26) -> 2.1107512 | W9: =Estimates!T9*(1-1.645*Settings!$C$23) -> 0.25690456 | X9: =Estimates!T9*(1+1.645*Settings!$C$23) -> 0.38327625 | Y9: =Estimates!V9*(1-1.645*Settings!$C$24) -> 8.2772775 | Z9: =Estimates!V9*(1+1.645*Settings!$C$24) -> 24.406938 | AA9: =Estimates!W9*(1-1.645*Settings!$C$25) -> 9.6818966 | AB9: =Estimates!W9*(1+1.645*Settings!$C$25) -> 14.444434 | AC9: =Estimates!X9*(1-1.645*Settings!$C$27) -> 2.9148788 | AD9: =Estimates!X9*(1+1.645*Settings!$C$27) -> 4.8245936
A10: 10 | B10: D3V3 | C10: =Estimates!I10*(1-1.645*Settings!$C$14) -> 80.247947 | D10: =Estimates!I10*(1+1.645*Settings!$C$14) -> 91.55241 | E10: =Estimates!J10*(1-1.645*Settings!$C$15) -> 64.696044 | F10: =Estimates!J10*(1+1.645*Settings!$C$15) -> 81.53449 | G10: =Estimates!K10*(1-1.645*Settings!$C$16) -> 16.39065 | H10: =Estimates!K10*(1+1.645*Settings!$C$16) -> 24.453232 | I10: =Estimates!L10*(1-1.645*Settings!$C$17) -> 0.300488 | J10: =Estimates!L10*(1+1.645*Settings!$C$17) -> 0.55329237 | K10: =Estimates!M10*(1-1.645*Settings!$C$18) -> 3.6159207 | L10: =Estimates!M10*(1+1.645*Settings!$C$18) -> 6.6580407 | M10: =Estimates!N10*(1-1.645*Settings!$C$19) -> 253.39551 | N10: =Estimates!N10*(1+1.645*Settings!$C$19) -> 308.89343 | O10: =Estimates!O10*(1-1.645*Settings!$C$20) -> 1.8081885 | P10: =Estimates!O10*(1+1.645*Settings!$C$20) -> 2.6976389 | Q10: =Estimates!P10*(1-1.645*Settings!$C$21) -> 1.1174996 | R10: =Estimates!P10*(1+1.645*Settings!$C$21) -> 1.5575443 | S10: =Estimates!Q10*(1-1.645*Settings!$C$22) -> 0.38645824 | T10: =Estimates!Q10*(1+1.645*Settings!$C$22) -> 0.57655757 | U10: =Estimates!R10*(1-1.645*Settings!$C$26) -> 1.5197995 | V10: =Estimates!R10*(1+1.645*Settings!$C$26) -> 2.1182603 | W10: =Estimates!T10*(1-1.645*Settings!$C$23) -> 0.25781851 | X10: =Estimates!T10*(1+1.645*Settings!$C$23) -> 0.38463977 | Y10: =Estimates!V10*(1-1.645*Settings!$C$24) -> 8.3856163 | Z10: =Estimates!V10*(1+1.645*Settings!$C$24) -> 24.726393 | AA10: =Estimates!W10*(1-1.645*Settings!$C$25) -> 8.8950461 | AB10: =Estimates!W10*(1+1.645*Settings!$C$25) -> 13.270531 | AC10: =Estimates!X10*(1-1.645*Settings!$C$27) -> 2.994527 | AD10: =Estimates!X10*(1+1.645*Settings!$C$27) -> 4.9564241
A11: 12 | B11: D4V1 | C11: =Estimates!I11*(1-1.645*Settings!$C$14) -> 80.247947 | D11: =Estimates!I11*(1+1.645*Settings!$C$14) -> 91.55241 | E11: =Estimates!J11*(1-1.645*Settings!$C$15) -> 64.240945 | F11: =Estimates!J11*(1+1.645*Settings!$C$15) -> 80.960942 | G11: =Estimates!K11*(1-1.645*Settings!$C$16) -> 15.634876 | H11: =Estimates!K11*(1+1.645*Settings!$C$16) -> 23.325692 | I11: =Estimates!L11*(1-1.645*Settings!$C$17) -> 0.29627536 | J11: =Estimates!L11*(1+1.645*Settings!$C$17) -> 0.54553557 | K11: =Estimates!M11*(1-1.645*Settings!$C$18) -> 3.5652279 | L11: =Estimates!M11*(1+1.645*Settings!$C$18) -> 6.5646993 | M11: =Estimates!N11*(1-1.645*Settings!$C$19) -> 254.74066 | N11: =Estimates!N11*(1+1.645*Settings!$C$19) -> 310.53319 | O11: =Estimates!O11*(1-1.645*Settings!$C$20) -> 1.0739519 | P11: =Estimates!O11*(1+1.645*Settings!$C$20) -> 1.6022303 | Q11: =Estimates!P11*(1-1.645*Settings!$C$21) -> 1.0473242 | R11: =Estimates!P11*(1+1.645*Settings!$C$21) -> 1.4597355 | S11: =Estimates!Q11*(1-1.645*Settings!$C$22) -> 0.3621899 | T11: =Estimates!Q11*(1+1.645*Settings!$C$22) -> 0.54035159 | U11: =Estimates!R11*(1-1.645*Settings!$C$26) -> 1.4243609 | V11: =Estimates!R11*(1+1.645*Settings!$C$26) -> 1.9852403 | W11: =Estimates!T11*(1-1.645*Settings!$C$23) -> 0.24162833 | X11: =Estimates!T11*(1+1.645*Settings!$C$23) -> 0.36048562 | Y11: =Estimates!V11*(1-1.645*Settings!$C$24) -> 9.3477705 | Z11: =Estimates!V11*(1+1.645*Settings!$C$24) -> 27.563465 | AA11: =Estimates!W11*(1-1.645*Settings!$C$25) -> 9.1534083 | AB11: =Estimates!W11*(1+1.645*Settings!$C$25) -> 13.655982 | AC11: =Estimates!X11*(1-1.645*Settings!$C$27) -> 2.8970641 | AD11: =Estimates!X11*(1+1.645*Settings!$C$27) -> 4.7951074
A12: 1 | B12: D4V2 | C12: =Estimates!I12*(1-1.645*Settings!$C$14) -> 80.247947 | D12: =Estimates!I12*(1+1.645*Settings!$C$14) -> 91.55241 | E12: =Estimates!J12*(1-1.645*Settings!$C$15) -> 63.58806 | F12: =Estimates!J12*(1+1.645*Settings!$C$15) -> 80.13813 | G12: =Estimates!K12*(1-1.645*Settings!$C$16) -> 15.240653 | H12: =Estimates!K12*(1+1.645*Settings!$C$16) -> 22.73755 | I12: =Estimates!L12*(1-1.645*Settings!$C$17) -> 0.29028382 | J12: =Estimates!L12*(1+1.645*Settings!$C$17) -> 0.53450329 | K12: =Estimates!M12*(1-1.645*Settings!$C$18) -> 3.4931288 | L12: =Estimates!M12*(1+1.645*Settings!$C$18) -> 6.4319423 | M12: =Estimates!N12*(1-1.645*Settings!$C$19) -> 256.6998 | N12: =Estimates!N12*(1+1.645*Settings!$C$19) -> 312.92142 | O12: =Estimates!O12*(1-1.645*Settings!$C$20) -> 1.1304757 | P12: =Estimates!O12*(1+1.645*Settings!$C$20) -> 1.6865582 | Q12: =Estimates!P12*(1-1.645*Settings!$C$21) -> 0.99517485 | R12: =Estimates!P12*(1+1.645*Settings!$C$21) -> 1.387051 | S12: =Estimates!Q12*(1-1.645*Settings!$C$22) -> 0.3441554 | T12: =Estimates!Q12*(1+1.645*Settings!$C$22) -> 0.5134459 | U12: =Estimates!R12*(1-1.645*Settings!$C$26) -> 1.3534378 | V12: =Estimates!R12*(1+1.645*Settings!$C$26) -> 1.8863894 | W12: =Estimates!T12*(1-1.645*Settings!$C$23) -> 0.22959695 | X12: =Estimates!T12*(1+1.645*Settings!$C$23) -> 0.34253599 | Y12: =Estimates!V12*(1-1.645*Settings!$C$24) -> 9.589565 | Z12: =Estimates!V12*(1+1.645*Settings!$C$24) -> 28.276437 | AA12: =Estimates!W12*(1-1.645*Settings!$C$25) -> 9.3609242 | AB12: =Estimates!W12*(1+1.645*Settings!$C$25) -> 13.965575 | AC12: =Estimates!X12*(1-1.645*Settings!$C$27) -> 2.8823049 | AD12: =Estimates!X12*(1+1.645*Settings!$C$27) -> 4.7706786
A13: 6 | B13: D4V3 | C13: =Estimates!I13*(1-1.645*Settings!$C$14) -> 80.247947 | D13: =Estimates!I13*(1+1.645*Settings!$C$14) -> 91.55241 | E13: =Estimates!J13*(1-1.645*Settings!$C$15) -> 64.276003 | F13: =Estimates!J13*(1+1.645*Settings!$C$15) -> 81.005125 | G13: =Estimates!K13*(1-1.645*Settings!$C$16) -> 16.125902 | H13: =Estimates!K13*(1+1.645*Settings!$C$16) -> 24.058255 | I13: =Estimates!L13*(1-1.645*Settings!$C$17) -> 0.29659881 | J13: =Estimates!L13*(1+1.645*Settings!$C$17) -> 0.54613116 | K13: =Estimates!M13*(1-1.645*Settings!$C$18) -> 3.5691202 | L13: =Estimates!M13*(1+1.645*Settings!$C$18) -> 6.5718663 | M13: =Estimates!N13*(1-1.645*Settings!$C$19) -> 254.63645 | N13: =Estimates!N13*(1+1.645*Settings!$C$19) -> 310.40615 | O13: =Estimates!O13*(1-1.645*Settings!$C$20) -> 1.1304757 | P13: =Estimates!O13*(1+1.645*Settings!$C$20) -> 1.6865582 | Q13: =Estimates!P13*(1-1.645*Settings!$C$21) -> 1.0816906 | R13: =Estimates!P13*(1+1.645*Settings!$C$21) -> 1.5076346 | S13: =Estimates!Q13*(1-1.645*Settings!$C$22) -> 0.37407463 | T13: =Estimates!Q13*(1+1.645*Settings!$C$22) -> 0.55808244 | U13: =Estimates!R13*(1-1.645*Settings!$C$26) -> 1.4710992 | V13: =Estimates!R13*(1+1.645*Settings!$C$26) -> 2.050383 | W13: =Estimates!T13*(1-1.645*Settings!$C$23) -> 0.24955701 | X13: =Estimates!T13*(1+1.645*Settings!$C$23) -> 0.37231443 | Y13: =Estimates!V13*(1-1.645*Settings!$C$24) -> 9.3350294 | Z13: =Estimates!V13*(1+1.645*Settings!$C$24) -> 27.525896 | AA13: =Estimates!W13*(1-1.645*Settings!$C$25) -> 8.8085598 | AB13: =Estimates!W13*(1+1.645*Settings!$C$25) -> 13.141502 | AC13: =Estimates!X13*(1-1.645*Settings!$C$27) -> 2.9847901 | AD13: =Estimates!X13*(1+1.645*Settings!$C$27) -> 4.9403081
... A49: 20 | B49: D4V3 | C49: =Estimates!I49*(1-1.645*Settings!$C$14) -> 79.491824 | D49: =Estimates!I49*(1+1.645*Settings!$C$14) -> 90.689773 | E49: =Estimates!J49*(1-1.645*Settings!$C$15) -> 62.680153 | F49: =Estimates!J49*(1+1.645*Settings!$C$15) -> 78.993922 | G49: =Estimates!K49*(1-1.645*Settings!$C$16) -> 13.7125 | H49: =Estimates!K49*(1+1.645*Settings!$C$16) -> 20.457697 | I49: =Estimates!L49*(1-1.645*Settings!$C$17) -> 0.2700922 | J49: =Estimates!L49*(1+1.645*Settings!$C$17) -> 0.49732419 | K49: =Estimates!M49*(1-1.645*Settings!$C$18) -> 3.3045727 | L49: =Estimates!M49*(1+1.645*Settings!$C$18) -> 6.0847517 | M49: =Estimates!N49*(1-1.645*Settings!$C$19) -> 268.64683 | N49: =Estimates!N49*(1+1.645*Settings!$C$19) -> 327.48504 | O49: =Estimates!O49*(1-1.645*Settings!$C$20) -> 1.0638113 | P49: =Estimates!O49*(1+1.645*Settings!$C$20) -> 1.5871015 | Q49: =Estimates!P49*(1-1.645*Settings!$C$21) -> 0.99676994 | R49: =Estimates!P49*(1+1.645*Settings!$C$21) -> 1.3892742 | S49: =Estimates!Q49*(1-1.645*Settings!$C$22) -> 0.35299676 | T49: =Estimates!Q49*(1+1.645*Settings!$C$22) -> 0.52663633 | U49: =Estimates!R49*(1-1.645*Settings!$C$26) -> 1.3642367 | V49: =Estimates!R49*(1+1.645*Settings!$C$26) -> 1.9014406 | W49: =Estimates!T49*(1-1.645*Settings!$C$23) -> 0.26185664 | X49: =Estimates!T49*(1+1.645*Settings!$C$23) -> 0.39066426 | Y49: =Estimates!V49*(1-1.645*Settings!$C$24) -> 10.045022 | Z49: =Estimates!V49*(1+1.645*Settings!$C$24) -> 29.619427 | AA49: =Estimates!W49*(1-1.645*Settings!$C$25) -> 8.6843658 | AB49: =Estimates!W49*(1+1.645*Settings!$C$25) -> 12.956217 | AC49: =Estimates!X49*(1-1.645*Settings!$C$27) -> 2.7412729 | AD49: =Estimates!X49*(1+1.645*Settings!$C$27) -> 4.5372479

Sheet Spectral_Features
A1: Plot | B1: Treatment | C1: Sowing | D1: Variety | E1: Replication | F1: Growth stage | G1: Plot DI (%) | H1: Severity class | I1: MTCI (R754-R709)/(R709-R681) | J1: CI red-edge R780/R710-1 | K1: NDVI (R800,R670) | L1: Red-edge position, max 1st derivative (nm) | M1: ARI 1/R550-1/R700 | N1: NDWI (R860,R1240) | O1: 1450 nm water band depth
A2: 7 | B2: D1V1 | C2: D1 | D2: V1 | E2: Control | F2: Flowering | G2: 0 | H2: Healthy | I2: 1.5816986 | J2: 1.0127543 | K2: 0.7541922 | L2: 710 | M2: -1.2671254 | N2: 0.066593541 | O2: 0.77455019
A3: 5 | B3: D1V2 | C3: D1 | D3: V2 | E3: Control | F3: Flowering | G3: 0 | H3: Healthy | I3: 1.5309995 | J3: 0.9585578 | K3: 0.73547939 | L3: 709 | M3: -1.3430612 | N3: 0.063707927 | O3: 0.75694221
A4: 3 | B4: D1V3 | C4: D1 | D4: V3 | E4: Control | F4: Flowering | G4: 0 | H4: Healthy | I4: 1.3492965 | J4: 0.87350023 | K4: 0.74446043 | L4: 706 | M4: -1.179221 | N4: 0.076947077 | O4: 0.76558142
A5: 9 | B5: D2V1 | C5: D2 | D5: V1 | E5: Control | F5: Flowering | G5: 0 | H5: Healthy | I5: 1.624902 | J5: 1.0326527 | K5: 0.74786377 | L5: 710 | M5: -1.4855302 | N5: 0.060198532 | O5: 0.76613522
A6: 2 | B6: D2V2 | C6: D2 | D6: V2 | E6: Control | F6: Flowering | G6: 0 | H6: Healthy | I6: 1.1736825 | J6: 0.77625734 | K6: 0.74501742 | L6: 704 | M6: -1.2714359 | N6: 0.051795309 | O6: 0.73878093
A7: 8 | B7: D2V3 | C7: D2 | D7: V3 | E7: Control | F7: Flowering | G7: 0 | H7: Healthy | I7: 1.6250254 | J7: 1.0295466 | K7: 0.74690822 | L7: 710 | M7: -1.4461163 | N7: 0.061010078 | O7: 0.77108482
A8: 4 | B8: D3V1 | C8: D3 | D8: V1 | E8: Control | F8: Flowering | G8: 0 | H8: Healthy | I8: 1.7144974 | J8: 1.1050736 | K8: 0.7599008 | L8: 712 | M8: -1.7028581 | N8: 0.072139991 | O8: 0.77823006
A9: 11 | B9: D3V2 | C9: D3 | D9: V2 | E9: Control | F9: Vegetative | G9: 0 | H9: Healthy | I9: 1.4803245 | J9: 0.97438046 | K9: 0.76394033 | L9: 708 | M9: -1.5597469 | N9: 0.058512007 | O9: 0.77139312
A10: 10 | B10: D3V3 | C10: D3 | D10: V3 | E10: Control | F10: Vegetative | G10: 0 | H10: Healthy | I10: 1.4404584 | J10: 0.95543648 | K10: 0.75864433 | L10: 707 | M10: -1.5701349 | N10: 0.057347478 | O10: 0.77031802
A11: 12 | B11: D4V1 | C11: D4 | D11: V1 | E11: Control | F11: Vegetative | G11: 0 | H11: Healthy | I11: 1.2778945 | J11: 0.86600609 | K11: 0.76461998 | L11: 705 | M11: -1.4856087 | N11: 0.05380756 | O11: 0.75023705
A12: 1 | B12: D4V2 | C12: D4 | D12: V2 | E12: Control | F12: Vegetative | G12: 0 | H12: Healthy | I12: 1.1346966 | J12: 0.75693745 | K12: 0.74917258 | L12: 703 | M12: -1.2417174 | N12: 0.067763049 | O12: 0.76317454
A13: 6 | B13: D4V3 | C13: D4 | D13: V3 | E13: Control | F13: Vegetative | G13: 0 | H13: Healthy | I13: 1.3320391 | J13: 0.89419331 | K13: 0.77039852 | L13: 706 | M13: -1.5394043 | N13: 0.054956386 | O13: 0.76046098
... A49: 20 | B49: D4V3 | C49: D4 | D49: V3 | E49: R3 | F49: Vegetative | G49: 44.4 | H49: High | I49: 1.260541 | J49: 0.8253877 | K49: 0.7392766 | L49: 705 | M49: -1.1523595 | N49: 0.080454203 | O49: 0.78532835

Sheet Treatment_Summary
A1: Treatment means: healthy control plot vs mean of inoculated R1-R3 (formulas on Estimates)
A2: Treatment | B2: Growth stage | C2: Mean DI R1-R3 (%) | D2: RWC (%) healthy | E2: RWC (%) R1-R3 | F2: % change | G2: MSI (%) healthy | H2: MSI (%) R1-R3 | I2: % change | J2: Pn (umol CO2 m-2 s-1) healthy | K2: Pn (umol CO2 m-2 s-1) R1-R3 | L2: % change | M2: gs (mol H2O m-2 s-1) healthy | N2: gs (mol H2O m-2 s-1) R1-R3 | O2: % change | P2: E (mmol H2O m-2 s-1) healthy | Q2: E (mmol H2O m-2 s-1) R1-R3 | R2: % change | S2: Ci (umol mol-1) healthy | T2: Ci (umol mol-1) R1-R3 | U2: % change | V2: LAI (m2 m-2) healthy | W2: LAI (m2 m-2) R1-R3 | X2: % change | Y2: Total chl (ug mg-1 FW) healthy | Z2: Total chl (ug mg-1 FW) R1-R3 | AA2: % change | AB2: Carotenoids (mg g-1 FW) healthy | AC2: Carotenoids (mg g-1 FW) R1-R3 | AD2: % change | AE2: Anthocyanin (ug g-1 FW) healthy | AF2: Anthocyanin (ug g-1 FW) R1-R3 | AG2: % change | AH2: Total protein (ug mg-1 FW) healthy | AI2: Total protein (ug mg-1 FW) R1-R3 | AJ2: % change
A3: D1V1 | B3: Flowering | C3: =AVERAGEIFS(Estimates!$G$2:$G$49,Estimates!$B$2:$B$49,A3,Estimates!$E$2:$E$49,"<>Control") -> 56.533333 | D3: =Estimates!I2 -> 85.041177 | E3: =AVERAGEIFS(Estimates!$I$2:$I$49,Estimates!$B$2:$B$49,A3,Estimates!$E$2:$E$49,"<>Control") -> 82.816809 | F3: =E3/D3-1 -> -0.026156364 | G3: =Estimates!J2 -> 71.659645 | H3: =AVERAGEIFS(Estimates!$J$2:$J$49,Estimates!$B$2:$B$49,A3,Estimates!$E$2:$E$49,"<>Control") -> 65.274909 | I3: =H3/G3-1 -> -0.089098066 | J3: =Estimates!K2 -> 19.831751 | K3: =AVERAGEIFS(Estimates!$K$2:$K$49,Estimates!$B$2:$B$49,A3,Estimates!$E$2:$E$49,"<>Control") -> 13.868072 | L3: =K3/J3-1 -> -0.3007137 | M3: =Estimates!L2 -> 0.42696982 | N3: =AVERAGEIFS(Estimates!$L$2:$L$49,Estimates!$B$2:$B$49,A3,Estimates!$E$2:$E$49,"<>Control") -> 0.34441931 | O3: =N3/M3-1 -> -0.19334039 | P3: =Estimates!M2 -> 5.137939 | Q3: =AVERAGEIFS(Estimates!$M$2:$M$49,Estimates!$B$2:$B$49,A3,Estimates!$E$2:$E$49,"<>Control") -> 4.2662908 | R3: =Q3/P3-1 -> -0.1696494 | S3: =Estimates!N2 -> 281.12481 | T3: =AVERAGEIFS(Estimates!$N$2:$N$49,Estimates!$B$2:$B$49,A3,Estimates!$E$2:$E$49,"<>Control") -> 312.47584 | U3: =T3/S3-1 -> 0.11151999 | V3: =Estimates!O2 -> 3.0869849 | W3: =AVERAGEIFS(Estimates!$O$2:$O$49,Estimates!$B$2:$B$49,A3,Estimates!$E$2:$E$49,"<>Control") -> 2.7322585 | X3: =W3/V3-1 -> -0.11491031 | Y3: =Estimates!R2 -> 1.8598654 | Z3: =AVERAGEIFS(Estimates!$R$2:$R$49,Estimates!$B$2:$B$49,A3,Estimates!$E$2:$E$49,"<>Control") -> 1.5005029 | AA3: =Z3/Y3-1 -> -0.19321964 | AB3: =Estimates!T2 -> 0.32844044 | AC3: =AVERAGEIFS(Estimates!$T$2:$T$49,Estimates!$B$2:$B$49,A3,Estimates!$E$2:$E$49,"<>Control") -> 0.31936234 | AD3: =AC3/AB3-1 -> -0.027640026 | AE3: =Estimates!V2 -> 14.330861 | AF3: =AVERAGEIFS(Estimates!$V$2:$V$49,Estimates!$B$2:$B$49,A3,Estimates!$E$2:$E$49,"<>Control") -> 16.872384 | AG3: =AF3/AE3-1 -> 0.17734615 | AH3: =Estimates!W2 -> 10.673808 | AI3: =AVERAGEIFS(Estimates!$W$2:$W$49,Estimates!$B$2:$B$49,A3,Estimates!$E$2:$E$49,"<>Control") -> 10.199608 | AJ3: =AI3/AH3-1 -> -0.044426513
A4: D1V2 | B4: Flowering | C4: =AVERAGEIFS(Estimates!$G$2:$G$49,Estimates!$B$2:$B$49,A4,Estimates!$E$2:$E$49,"<>Control") -> 54.533333 | D4: =Estimates!I3 -> 85.041177 | E4: =AVERAGEIFS(Estimates!$I$2:$I$49,Estimates!$B$2:$B$49,A4,Estimates!$E$2:$E$49,"<>Control") -> 82.921423 | F4: =E4/D4-1 -> -0.0249262 | G4: =Estimates!J3 -> 71.468278 | H4: =AVERAGEIFS(Estimates!$J$2:$J$49,Estimates!$B$2:$B$49,A4,Estimates!$E$2:$E$49,"<>Control") -> 64.622457 | I4: =H4/G4-1 -> -0.095788252 | J4: =Estimates!K3 -> 19.699615 | K4: =AVERAGEIFS(Estimates!$K$2:$K$49,Estimates!$B$2:$B$49,A4,Estimates!$E$2:$E$49,"<>Control") -> 13.248641 | L4: =K4/J4-1 -> -0.32746701 | M4: =Estimates!L3 -> 0.42469243 | N4: =AVERAGEIFS(Estimates!$L$2:$L$49,Estimates!$B$2:$B$49,A4,Estimates!$E$2:$E$49,"<>Control") -> 0.33332408 | O4: =N4/M4-1 -> -0.21514005 | P4: =Estimates!M3 -> 5.110534 | Q4: =AVERAGEIFS(Estimates!$M$2:$M$49,Estimates!$B$2:$B$49,A4,Estimates!$E$2:$E$49,"<>Control") -> 4.1175014 | R4: =Q4/P4-1 -> -0.19431092 | S4: =Estimates!N3 -> 281.68918 | T4: =AVERAGEIFS(Estimates!$N$2:$N$49,Estimates!$B$2:$B$49,A4,Estimates!$E$2:$E$49,"<>Control") -> 316.33407 | U4: =T4/S4-1 -> 0.12298979 | V4: =Estimates!O3 -> 3.2494578 | W4: =AVERAGEIFS(Estimates!$O$2:$O$49,Estimates!$B$2:$B$49,A4,Estimates!$E$2:$E$49,"<>Control") -> 2.873459 | X4: =W4/V4-1 -> -0.11571126 | Y4: =Estimates!R3 -> 1.8351639 | Z4: =AVERAGEIFS(Estimates!$R$2:$R$49,Estimates!$B$2:$B$49,A4,Estimates!$E$2:$E$49,"<>Control") -> 1.3878833 | AA4: =Z4/Y4-1 -> -0.24372788 | AB4: =Estimates!T3 -> 0.32407831 | AC4: =AVERAGEIFS(Estimates!$T$2:$T$49,Estimates!$B$2:$B$49,A4,Estimates!$E$2:$E$49,"<>Control") -> 0.29871803 | AD4: =AC4/AB4-1 -> -0.078253567 | AE4: =Estimates!V3 -> 14.426986 | AF4: =AVERAGEIFS(Estimates!$V$2:$V$49,Estimates!$B$2:$B$49,A4,Estimates!$E$2:$E$49,"<>Control") -> 17.519577 | AG4: =AF4/AE4-1 -> 0.21436153 | AH4: =Estimates!W3 -> 11.039968 | AI4: =AVERAGEIFS(Estimates!$W$2:$W$49,Estimates!$B$2:$B$49,A4,Estimates!$E$2:$E$49,"<>Control") -> 10.354647 | AJ4: =AI4/AH4-1 -> -0.062076339
A5: D1V3 | B5: Flowering | C5: =AVERAGEIFS(Estimates!$G$2:$G$49,Estimates!$B$2:$B$49,A5,Estimates!$E$2:$E$49,"<>Control") -> 41.233333 | D5: =Estimates!I4 -> 85.041177 | E5: =AVERAGEIFS(Estimates!$I$2:$I$49,Estimates!$B$2:$B$49,A5,Estimates!$E$2:$E$49,"<>Control") -> 84.292633 | F5: =E5/D5-1 -> -0.0088021316 | G5: =Estimates!J4 -> 70.508863 | H5: =AVERAGEIFS(Estimates!$J$2:$J$49,Estimates!$B$2:$B$49,A5,Estimates!$E$2:$E$49,"<>Control") -> 68.530372 | I5: =H5/G5-1 -> -0.028060179 | J5: =Estimates!K4 -> 19.616474 | K5: =AVERAGEIFS(Estimates!$K$2:$K$49,Estimates!$B$2:$B$49,A5,Estimates!$E$2:$E$49,"<>Control") -> 16.656962 | L5: =K5/J5-1 -> -0.15086869 | M5: =Estimates!L4 -> 0.41336653 | N5: =AVERAGEIFS(Estimates!$L$2:$L$49,Estimates!$B$2:$B$49,A5,Estimates!$E$2:$E$49,"<>Control") -> 0.37503618 | O5: =N5/M5-1 -> -0.092727267 | P5: =Estimates!M4 -> 4.9742438 | Q5: =AVERAGEIFS(Estimates!$M$2:$M$49,Estimates!$B$2:$B$49,A5,Estimates!$E$2:$E$49,"<>Control") -> 4.5833558 | R5: =Q5/P5-1 -> -0.078582413 | S5: =Estimates!N4 -> 284.55903 | T5: =AVERAGEIFS(Estimates!$N$2:$N$49,Estimates!$B$2:$B$49,A5,Estimates!$E$2:$E$49,"<>Control") -> 300.31186 | U5: =T5/S5-1 -> 0.055358735 | V5: =Estimates!O4 -> 3.2494578 | W5: =AVERAGEIFS(Estimates!$O$2:$O$49,Estimates!$B$2:$B$49,A5,Estimates!$E$2:$E$49,"<>Control") -> 3.0703485 | X5: =W5/V5-1 -> -0.055119757 | Y5: =Estimates!R4 -> 1.7667051 | Z5: =AVERAGEIFS(Estimates!$R$2:$R$49,Estimates!$B$2:$B$49,A5,Estimates!$E$2:$E$49,"<>Control") -> 1.6062931 | AA5: =Z5/Y5-1 -> -0.090797274 | AB5: =Estimates!T4 -> 0.31198892 | AC5: =AVERAGEIFS(Estimates!$T$2:$T$49,Estimates!$B$2:$B$49,A5,Estimates!$E$2:$E$49,"<>Control") -> 0.31876744 | AD5: =AC5/AB5-1 -> 0.021726797 | AE5: =Estimates!V4 -> 14.922777 | AF5: =AVERAGEIFS(Estimates!$V$2:$V$49,Estimates!$B$2:$B$49,A5,Estimates!$E$2:$E$49,"<>Control") -> 16.182636 | AG5: =AF5/AE5-1 -> 0.084425242 | AH5: =Estimates!W4 -> 10.017045 | AI5: =AVERAGEIFS(Estimates!$W$2:$W$49,Estimates!$B$2:$B$49,A5,Estimates!$E$2:$E$49,"<>Control") -> 9.8116965 | AJ5: =AI5/AH5-1 -> -0.02049995
A6: D2V1 | B6: Flowering | C6: =AVERAGEIFS(Estimates!$G$2:$G$49,Estimates!$B$2:$B$49,A6,Estimates!$E$2:$E$49,"<>Control") -> 47.4 | D6: =Estimates!I5 -> 85.041177 | E6: =AVERAGEIFS(Estimates!$I$2:$I$49,Estimates!$B$2:$B$49,A6,Estimates!$E$2:$E$49,"<>Control") -> 83.639344 | F6: =E6/D6-1 -> -0.016484166 | G6: =Estimates!J5 -> 71.81726 | H6: =AVERAGEIFS(Estimates!$J$2:$J$49,Estimates!$B$2:$B$49,A6,Estimates!$E$2:$E$49,"<>Control") -> 67.864143 | I6: =H6/G6-1 -> -0.055044104 | J6: =Estimates!K5 -> 19.94098 | K6: =AVERAGEIFS(Estimates!$K$2:$K$49,Estimates!$B$2:$B$49,A6,Estimates!$E$2:$E$49,"<>Control") -> 15.341314 | L6: =K6/J6-1 -> -0.23066402 | M6: =Estimates!L5 -> 0.42885012 | N6: =AVERAGEIFS(Estimates!$L$2:$L$49,Estimates!$B$2:$B$49,A6,Estimates!$E$2:$E$49,"<>Control") -> 0.36657853 | O6: =N6/M6-1 -> -0.14520597 | P6: =Estimates!M5 -> 5.1605656 | Q6: =AVERAGEIFS(Estimates!$M$2:$M$49,Estimates!$B$2:$B$49,A6,Estimates!$E$2:$E$49,"<>Control") -> 4.5041732 | R6: =Q6/P6-1 -> -0.12719389 | S6: =Estimates!N5 -> 280.66195 | T6: =AVERAGEIFS(Estimates!$N$2:$N$49,Estimates!$B$2:$B$49,A6,Estimates!$E$2:$E$49,"<>Control") -> 304.56236 | U6: =T6/S6-1 -> 0.085157309 | V6: =Estimates!O5 -> 2.7101143 | W6: =AVERAGEIFS(Estimates!$O$2:$O$49,Estimates!$B$2:$B$49,A6,Estimates!$E$2:$E$49,"<>Control") -> 2.477325 | X6: =W6/V6-1 -> -0.085896508 | Y6: =Estimates!R5 -> 1.8804094 | Z6: =AVERAGEIFS(Estimates!$R$2:$R$49,Estimates!$B$2:$B$49,A6,Estimates!$E$2:$E$49,"<>Control") -> 1.608027 | AA6: =Z6/Y6-1 -> -0.14485272 | AB6: =Estimates!T5 -> 0.33206838 | AC6: =AVERAGEIFS(Estimates!$T$2:$T$49,Estimates!$B$2:$B$49,A6,Estimates!$E$2:$E$49,"<>Control") -> 0.33308446 | AD6: =AC6/AB6-1 -> 0.0030598504 | AE6: =Estimates!V5 -> 14.252362 | AF6: =AVERAGEIFS(Estimates!$V$2:$V$49,Estimates!$B$2:$B$49,A6,Estimates!$E$2:$E$49,"<>Control") -> 16.151061 | AG6: =AF6/AE6-1 -> 0.13321998 | AH6: =Estimates!W5 -> 10.709043 | AI6: =AVERAGEIFS(Estimates!$W$2:$W$49,Estimates!$B$2:$B$49,A6,Estimates!$E$2:$E$49,"<>Control") -> 10.353612 | AJ6: =AI6/AH6-1 -> -0.033189821
A7: D2V2 | B7: Flowering | C7: =AVERAGEIFS(Estimates!$G$2:$G$49,Estimates!$B$2:$B$49,A7,Estimates!$E$2:$E$49,"<>Control") -> 52.1 | D7: =Estimates!I6 -> 85.041177 | E7: =AVERAGEIFS(Estimates!$I$2:$I$49,Estimates!$B$2:$B$49,A7,Estimates!$E$2:$E$49,"<>Control") -> 83.006381 | F7: =E7/D7-1 -> -0.023927189 | G7: =Estimates!J6 -> 69.872802 | H7: =AVERAGEIFS(Estimates!$J$2:$J$49,Estimates!$B$2:$B$49,A7,Estimates!$E$2:$E$49,"<>Control") -> 66.251622 | I7: =H7/G7-1 -> -0.051825316 | J7: =Estimates!K6 -> 18.618506 | K7: =AVERAGEIFS(Estimates!$K$2:$K$49,Estimates!$B$2:$B$49,A7,Estimates!$E$2:$E$49,"<>Control") -> 13.828724 | L7: =K7/J7-1 -> -0.25725922 | M7: =Estimates!L6 -> 0.4059422 | N7: =AVERAGEIFS(Estimates!$L$2:$L$49,Estimates!$B$2:$B$49,A7,Estimates!$E$2:$E$49,"<>Control") -> 0.34602856 | O7: =N7/M7-1 -> -0.14759156 | P7: =Estimates!M6 -> 4.8849032 | Q7: =AVERAGEIFS(Estimates!$M$2:$M$49,Estimates!$B$2:$B$49,A7,Estimates!$E$2:$E$49,"<>Control") -> 4.2767347 | R7: =Q7/P7-1 -> -0.12449962 | S7: =Estimates!N6 -> 286.49961 | T7: =AVERAGEIFS(Estimates!$N$2:$N$49,Estimates!$B$2:$B$49,A7,Estimates!$E$2:$E$49,"<>Control") -> 312.33226 | U7: =T7/S7-1 -> 0.09016642 | V7: =Estimates!O6 -> 2.8527519 | W7: =AVERAGEIFS(Estimates!$O$2:$O$49,Estimates!$B$2:$B$49,A7,Estimates!$E$2:$E$49,"<>Control") -> 2.5171817 | X7: =W7/V7-1 -> -0.11763035 | Y7: =Estimates!R6 -> 1.6392647 | Z7: =AVERAGEIFS(Estimates!$R$2:$R$49,Estimates!$B$2:$B$49,A7,Estimates!$E$2:$E$49,"<>Control") -> 1.5327574 | AA7: =Z7/Y7-1 -> -0.06497258 | AB7: =Estimates!T6 -> 0.28948375 | AC7: =AVERAGEIFS(Estimates!$T$2:$T$49,Estimates!$B$2:$B$49,A7,Estimates!$E$2:$E$49,"<>Control") -> 0.33269593 | AD7: =AC7/AB7-1 -> 0.14927326 | AE7: =Estimates!V6 -> 15.264708 | AF7: =AVERAGEIFS(Estimates!$V$2:$V$49,Estimates!$B$2:$B$49,A7,Estimates!$E$2:$E$49,"<>Control") -> 16.711294 | AG7: =AF7/AE7-1 -> 0.094766633 | AH7: =Estimates!W6 -> 10.67235 | AI7: =AVERAGEIFS(Estimates!$W$2:$W$49,Estimates!$B$2:$B$49,A7,Estimates!$E$2:$E$49,"<>Control") -> 10.66735 | AJ7: =AI7/AH7-1 -> -0.00046853896
