Workbook

Sheet README
A1: TITLE | B1: Conservation agriculture meta-analysis - NEW data extraction workbook (structure of META_ANALYSIS_MASTER updated 53, no previous data)
A2: NEW SERIES | B2: Started 2026-10-05. All data rows of the old master were removed at the author's request; serials continue from the old master, starting at 164, so the two files can be merged. The history entries further down describe the OLD master (updated 53) and are kept only as the rulebook.
A3: PARTIAL CA COLUMNS | B3: Every parameter sheet has <prefix>pCA, pZT, pMT, pMTR (olive-green headers) after <prefix>DTR: puddled / conventional rice + ZT wheat with residue (pCA) / without residue (pZT), + MT wheat without (pMT) / with residue (pMTR). See Codes and RULES.
A4: LAT_LONG | B4: One row per study x site: coordinates as reported and in decimal degrees, source (paper / Google Maps), climate class.
A6: HOW TO USE | B6: Upload ONE research paper at a time. Data are extracted and appended to the relevant parameter sheets only. Sheets for parameters absent from a paper are left untouched.
A8: SHEET TYPES
A9: Study_Info | B9: One row per study x site. Master record of coordinates, climate, initial soil properties, management. Fill this FIRST for every new paper.
A10: Treatment_Mapping | B10: Log of every treatment in every paper and the code it was assigned. Any treatment that is unclear is logged here with status NEEDS CONFIRMATION and left out of the data sheets.
A11: Codes | B11: Treatment codes + all reclassification rules (climate, texture, duration, depth).
A12: Parameter sheets | B12: One sheet per measured parameter (BD, SOC, MWD, PR, YIELD, ...). Unit for each sheet is written in the orange note to the right of the header row AND in the UNIT column.
A14: COLUMN COLOUR KEY
A15: Dark blue | B15: Study identification
A16: Teal | B16: Soil depth (reclassified + as reported)
A17: Green | B17: Treatment mean values
A18: Amber | B18: Obs / Rep / SD
A19: Grey | B19: Site covariates (climate, initial soil)
A20: Purple | B20: Unit, treatment mapping, management, data source, notes
A22: RULES APPLIED
A23: Rep | B23: Always 3 unless the paper clearly states otherwise.
A24: Obs | B24: Number of paper-level data points collapsed into that row for that depth class: years x sub-treatments x original depths falling in the class. e.g. 3 years x 1 depth = 3; 3 years x 2 original depths in the same class x 2 qualifying treatments = 12.
A25: SD | B25: SD = SQRT(2*Obs/Rep) - the formula used in the original workbook. Written as a live formula so it updates if Obs changes. Overwritten with the real value when the paper reports SD (or SE, converted as SD = SE*sqrt(Rep)).
A26: Season | B26: Soil parameters are taken from the WHEAT season, not the rice season.
A27: Coordinates | B27: Decimal degrees. Taken from the paper; if absent, looked up from the stated location and flagged in Notes.
A28: Figures | B28: Values read off figures are digitised (WebPlotDigitizer style) and marked 'Figure' in Data source.
A29: Supplementary | B29: Supplementary files are searched for online and extracted; marked 'Supplementary' in Data source.
A30: Multi-year / multi-site | B30: Every year and every site is entered - separate rows, Site/Location and YEAR OF DATA distinguish them.
A31: Doubtful treatments | B31: Left blank in the data sheets and raised with you; logged in Treatment_Mapping.
A32: Porosity | B32: Where a paper reports total porosity it is entered as printed (studies 5 and 11). Everywhere else it is DERIVED as porosity (%) = (1 - BD / PD) x 100, using the TREATMENT bulk density from the BD sheet - as a live cross-sheet formula, so correcting a bulk density corrects the porosity - and PD = 2.65 Mg/m3, since no study with bulk-density data reports its own particle density. That default reproduces both measured porosities in this workbook to within 0.1 percentage points. Derived rows say DERIVED in Data source; replace 2.65 in the formulas to change the assumption.
A33: EXAMPLE ROW (BD sheet) | B33: Do not keep this in the data sheets - shown here only as a format guide.
A35: No. | B35: SERIAL NO | C35: Authors | D35: Year | E35: Journal | F35: Country | G35: Site/Location | H35: latitude | I35: longitude | J35: CLIMATE | K35: year of data collection/experiment | L35: DURATION | M35: SOIL | N35: DEPTH | O35: DEPTH (as reported in paper) | P35: BD_CA | Q35: BD_CT | R35: BD_ZT | S35: Obs | T35: Rep | U35: SD | V35: CLAY | W35: RAIN FALL | X35: ph (initial) | Y35: UNIT | Z35: Treatment mapping (paper's name -> code) | AA35: Data source
A36: 1 | B36: 1 | C36: Roy D. et al. | D36: 2021 | E36: Geoderma | F36: India | G36: Karnal, Haryana | H36: 29.42 | I36: 76.57 | J36: ST | K36: 10 | L36: 4-10 Y | M36: LOAMY | N36: 0-15 CM | O36: 0-5 + 5-15 cm pooled | P36: 1.39 | Q36: 1.5 | R36: 1.44 | S36: 2 | T36: 3 | U36: SD = SQRT(2*Obs/Rep) (live formula in the data sheets) | V36: 19.89 | W36: 670 | X36: 8 | Y36: Mg/m3 | Z36: ZT+R (ZTW with full residue) -> CA; CTW no residue -> CT; ZTW no residue -> ZT | AA36: Table 3
A38: SHEET SET | B38: Sheets are added only when you ask for them. Six were added on 2026-10-01 at your request: WSC, LFC-LFOC, LFON, PON, cPOM-C and fPOM-C - each carries its full form in the purple note to the right of its header row. For any OTHER parameter this workbook does not carry, values are kept in the Notes/Doubts column of the closest existing sheet. Those still parked in notes are listed below.
A39: SOC(active C pool) | B39: Soil organic carbon as the papers report it - in most papers simply "SOC" or "organic carbon", measured by Walkley-Black wet oxidation, i.e. the oxidisable / labile fraction rather than total carbon. ALL studies that report treatment-level SOC go on this sheet. Total carbon by dry combustion goes on TC(total c); inorganic carbon on SIC.
A40: ACTIVE C-MACRO / MICRO | B40: Active carbon pool associated with macroaggregates (>0.25 mm) and microaggregates (<0.25 mm), g/kg - these live on the macro c and micro c sheets, no separate sheets.
A41: Still parked in Notes | B41: DOC (dissolved organic carbon), KMnO4-oxidisable carbon, the Chan et al. very-labile / labile / less-labile / non-labile pools P1-P4, cumulative CO2-C, sorptivity, cumulative infiltration, stratification ratios, energy-budget terms, and the 0-90 cm carbon stocks of study 25. Say the word and any of these becomes a sheet.
A45: Derived-value rule | B45: Anything computed rather than printed carries its formula and inputs in the Notes column and names its Data source as DERIVED.
A46: ROOT sheets (added 2026-10-03) | B46: On author instruction, root parameters of rice and wheat are entered as DENSITIES plus diameter: RLD(CM-CM3), RVD(cm3-cm3), RMD(mg-cm3) and two new sheets RSD(cm2-cm3) (root surface area density) and ROOT DIA(mm) (average root diameter). Per-sample root values are converted with the sampled soil volume (formula and assumption in Notes). _W = wheat, _R = rice columns.
A47: New sheets (updated 8, 2026-10-03) | B47: Carbon/soil sheets added for Gupta et al. 2022 (study 75 companion) and Kahlon 2014 (study 74): POXC(KMnO4-C) mg/kg; the Chan et al. (2001) oxidisable C fractions VLC(Cfrac1), LC(Cfrac2), LLC(Cfrac3), NLC(Cfrac4) g/kg (VLC + LC + LLC + NLC = TOC); Fungal count and Cellulolytic count (CFU/g, multiplier in UNIT); Moisture storage (mm, soil-profile water storage). Same column layout as every parameter sheet.
A48: IR sheet (2026-10-03) | B48: IR_ columns = STEADY-STATE infiltration rate; IIR_ columns = INITIAL infiltration rate (both cm/hr). Final, basic and quasi-steady rates go in IR_; the first-reading rate goes in IIR_.
A49: FORMULAS sheet + NET RETURN sheet (2026-10-04) | B49: Every derivation used in the workbook is listed on the FORMULAS sheet (straw = biomass - grain, HI = grain / biomass, CL/LI/CPI/CMI, GHGI = GWP / grain, porosity, SD, unit conversions). NET RETURN sheet = net return per ha in the printed currency (W / R / SYS groups, as BC ratio). DERIVED rows reference their source cells with live formulas and say so in Data source.
...

Sheet RULES
A1: RULES - consolidated extraction, coding and analysis rules of this workbook (author-confirmed unless marked). Updated 2026-10-05
A3: No. | B3: Category | C3: Rule | D3: Details / worked examples | E3: Source / date | F3: Status
A4: WORKFLOW & DATA MANAGEMENT
A5: 1 | B5: Workflow & data management | C5: Existing entries are correct and are not recalculated or 'fixed'. | D5: New rules apply to new papers. Earlier rows are changed only when the author asks (e.g. an entry shown to be wrong against its source: study 59 in updated 17; rotary-rule recoding in updated 47). | E5: Author 2026-10-03 | F5: IN FORCE
A6: 2 | B6: Workflow & data management | C6: Every batch is saved as a new numbered version (META_ANALYSIS_MASTER updated NN.xlsx); the previous file is never overwritten. | D6: Each build is checked cell-by-cell against the previous version (only intended cells may change, 0 formula errors). | E6: Workbook convention | F6: IN FORCE
A7: 3 | B7: Workflow & data management | C7: Ask the author whenever in doubt. | D7: Unclear treatments are left out of the data sheets and raised with the author; doubts are written in Notes/Doubts. | E7: Author | F7: IN FORCE
A8: 4 | B8: Workflow & data management | C8: Fill Study_Info first; log EVERY treatment of every paper in Treatment_Mapping with its code (or EXCLUDED) and rationale; excluded data go to EXCLUDED_rows. | D8: Check Study_Info for duplicates (DOI, title, authors, year) before adding a paper. | E8: Workbook convention | F8: IN FORCE
A9: 5 | B9: Workflow & data management | C9: Same experiment reported in two papers = ONE serial; same site but a different experiment = separate serials. | D9: Different papers of one trial are filed as 'NN (companion)', 'NN (companion 2)' ... | E9: Codes - SAME-EXPERIMENT RULE | F9: IN FORCE
A10: 6 | B10: Workflow & data management | C10: A re-submitted paper that is already in the workbook is entered AGAIN as 'NN (companion)' (duplicate-flagged); the original study is not changed. | D10: Two identical files in the SAME batch: enter once, record the duplicate in EXCLUDED_rows. Same-trial papers reporting the same seasons: keep both, flag duplicate seasons. | E10: Author 2026-10-03 / 2026-10-05 | F10: IN FORCE
A11: 7 | B11: Workflow & data management | C11: Look for supplementary material online for every paper and report what was found (or 'none found' and where searched); extract its data (Data source = 'Supplementary ...'). | D11: Downloading a supplement needs the author's permission. CAPTCHA pages are never bypassed - the file is fetched from the publisher's direct link only after permission, or the author supplies it (Desktop\SUPP DATA). | E11: Author 2026-10-03 | F11: IN FORCE
A12: 8 | B12: Workflow & data management | C12: Extract everything: tables, text AND figures (digitised; approximate values flagged). | D12: End each batch with a list of anything not extracted. Figures: vector paths read exactly where possible, raster figures by calibrated colour digitising. | E12: Author 2026-10-03 | F12: IN FORCE
A13: 9 | B13: Workflow & data management | C13: The author wants MORE data: enter every parameter that has a sheet, even when it must be derived or has a non-standard definition/unit (flagged). | D13: When unsure whether something goes in notes or on a sheet, lean to a sheet. Parameters with NO sheet are not entered unless the author asks for a new sheet (e.g. PLFA not entered). | E13: Author 2026-10-03 / 2026-10-04 | F13: IN FORCE
A14: 10 | B14: Workflow & data management | C14: Every data sheet carries 'Treatment details (from paper)' and 'Method used (from paper)' right after Notes/Doubts. | D14: Treatment details = Study_Info treatments + every Treatment_Mapping line of the study (so treatments can be re-classified). Method = analytical method auto-detected from the paper's Methods with a quoted context (verify). Filled for every new row of every build. | E14: Author 2026-10-05 | F14: IN FORCE
A15: 11 | B15: Workflow & data management | C15: Data source tags: Text / Table n / Figure n (digitised) / Supplementary / Calculated / DERIVED / MODEL OUTPUT / Author-reported. | E15: Codes | F15: IN FORCE
A16: TREATMENT CODES
A17: 12 | B17: Treatment codes | C17: CA = zero tillage + residue; ZT = zero tillage, no residue; CT = conventional tillage, no residue; CTR = conventional + residue; MT = minimum/reduced tillage, no residue; MTR = minimum/reduced + residue; DT = deep tillage, no residue; DTR = deep tillage + residue. | D17: Typical descriptions of each code are on the Codes sheet. | E17: Codes | F17: IN FORCE
A18: 13 | B18: Treatment codes | C18: ROTARY / ROTAVATOR RULE: full-width rotary or rotavator tillage to >=10 cm, OR >=2 full-width passes = CT (CTR with residue), whatever the paper calls it. Rotary <=8 cm, a single-pass rotary till-drill, Super Seeder / Roto Seeder, or strip / zone rotary (only the seed rows tilled) = MT (MTR with residue). | D18: Rotavator = rotary tillage (same rule). 8-10 cm, or depth unstated and not clearly full-width primary tillage -> ask. Applied to old studies in updated 47: 25 T6/T7 -> CT/CTR (row b), 41 Rot+R100 -> MTR (row b), 64 + 64 (companion) RT -> CTR (row b), 69 AR -> CT (study excluded, no contrast), 74 RT -> CTR, 82 rotavator -> CT/CTR (row a, depth not stated - flag). | E18: Author 2026-10-05 | F18: IN FORCE
A19: 14 | B19: Treatment codes | C19: Deep tillage: ploughing / chiselling / sub-soiling >= 25 cm, or straw buried to 30 cm -> DT (no straw) / DTR (straw). | D19: Studies 9, 65, 108. | E19: Author 2026-10-03 | F19: IN FORCE
A20: 15 | B20: Treatment codes | C20: Bed systems: permanent beds + residue -> CA; permanent beds without residue -> ZT; freshly made beds each season -> MT; VMP beds re-formed + non-puddled transplanting -> MTR. | E20: Codes; author 2026-10-04 | F20: IN FORCE
A21: 16 | B21: Treatment codes | C21: Strip tillage, zone-disc tiller or strip drill + residue -> MTR, even when the paper calls it CA. | D21: Studies 124, 125, 127. | E21: Author 2026-10-03 / 2026-10-04 | F21: IN FORCE
A22: 17 | B22: Treatment codes | C22: Shallow rotary 3-5 cm stubble breaking + surface straw -> MTR; shallow rotary 6-7 cm + straw mulch -> MTR. | D22: Guo 2026 'NT' (129 companion); Kong 121 STS. | E22: Author 2026-10-04 / 2026-10-05 | F22: IN FORCE
A23: 18 | B23: Treatment codes | C23: Low residue (about 20 % stubble, farmer practice) counts as residue -> CTR / MTR. | D23: Rows pair like residue levels (as study 40). | E23: Author 2026-10-04 | F23: IN FORCE
A24: 19 | B24: Treatment codes | C24: Tillage ~25 cm with a 'conventional tiller' + straw -> CT / CTR; PTOS (power-tiller-operated seeder, full tillage) -> CTR. | E24: Author 2026-10-04 / 2026-10-05 | F24: IN FORCE
A25: 20 | B25: Treatment codes | C25: Several of the paper's treatments under ONE code -> one row per treatment (rows a, b, c ...), the other codes repeated in each row. | D25: Obs adds T = number of treatments under that code (see Statistics). | E25: Author 2026-10-03 | F25: IN FORCE
A26: 21 | B26: Treatment codes | C26: Inclusion threshold: a study is included if it yields ANY TWO usable codes; a CT reference is not required. | D26: A study left with one code after the rotation rule contributes nothing (e.g. study 69 after the rotary rule). | E26: Codes - INCLUSION THRESHOLD | F26: IN FORCE
A27: ROTATION MATCHING (RICE + WHEAT PHASES)
A28: 22 | B28: Rotation matching (rice + wheat phases) | C28: Rice tillage stated: the rice and wheat phases of a treatment must be the SAME type of tillage; a mismatched treatment is EXCLUDED, in either direction. | D28: Excluded: no-till rice + conventional wheat (RNT-WCT); puddled rice + ZT / bed wheat; alternate tillage. Logged in Treatment_Mapping as EXCLUDED. | E28: Codes - STANDING RULE 1 | F28: IN FORCE
A29: 23 | B29: Rotation matching (rice + wheat phases) | C29: Rice tillage NOT stated: classify on the wheat-phase tillage alone (do not assume a puddled rice phase). | D29: Studies 9, 11, 12, 41. | E29: Codes - STANDING RULE 2 | F29: IN FORCE
A30: 24 | B30: Rotation matching (rice + wheat phases) | C30: Author exceptions: puddled rice + conservation wheat INCLUDED and flagged 'PUDDLED RICE PHASE'. | D30: Kahlon 2014 (74), 34 (companion), Yangzhou group 126-128, 130, 132 - filter on the flag for sensitivity analysis. | E30: Author 2026-10-03 / 2026-10-04 | F30: IN FORCE
A31: 25 | B31: Rotation matching (rice + wheat phases) | C31: Tilled UNPUDDLED rice (dry tillage, transplanted or direct-seeded) + ZT wheat: without residue -> ZT, with residue -> CA (flagged). | D31: UPTR-ZTW, MTR/DSR-ZTW, CT-DDSR fb ZT -> ZT; study 29 family T6 -> CA. Puddled / wet-tilled rice + ZTW stays a mismatch. | E31: Author 2026-10-03 / 2026-10-04 | F31: IN FORCE
A32: 26 | B32: Rotation matching (rice + wheat phases) | C32: Zero-till DSR + one-pass rotary till-drill wheat -> MT; tilled DSR + reduced-till wheat -> MT (+ residue -> MTR). | D32: Studies 76, 79, 113. | E32: Author 2026-10-03 / 2026-10-04 | F32: IN FORCE
A33: 27 | B33: Rotation matching (rice + wheat phases) | C33: Unpuddled (aerobic) rice = reduced tillage -> MT. | D33: Study 69 AR. Superseded on 2026-10-05: AR land preparation was disc plough + rotavator = CT under the rotary rule, so study 69 is excluded (rows in EXCLUDED_rows). | E33: Author 2026-10-03 | F33: SUPERSEDED (rotary rule)
A34: 28 | B34: Rotation matching (rice + wheat phases) | C34: Puddled drum-seeded rice + CT wheat -> CT; SRI fb SWI -> CT; SRI-SWI with a different nutrient regime is excluded when a proper CT exists; CT dry-seeded unpuddled rice + CT wheat -> CT / CTR (flagged). | E34: Author 2026-10-03 / 2026-10-04 | F34: IN FORCE
A35: 29 | B35: Rotation matching (rice + wheat phases) | C35: When papers of one trial disagree on puddling, follow the main paper. | D35: Mishra Table 1 used over Saurabh for study 29 T3. | E35: Author 2026-10-04 | F35: IN FORCE
A36: CROPPING SYSTEM & DESIGN
A37: 30 | B37: Cropping system & design | C37: Third crop grown in EVERY treatment -> included; added in some treatments only -> those treatments excluded; with a mixed rotation history -> include flagged. | D37: When a third crop is present only in some treatments, use the treatment with the same rotation as the CT reference (Chaki CS1 vs CS2/CS3). | E37: Codes; author 2026-10-04 | F37: IN FORCE
A38: 31 | B38: Cropping system & design | C38: Excluded systems: rice-maize, wheat-maize, soybean-wheat, double rice, rice-only or rice-rice TRIALS. | D38: Exception: a rice-season-only paper from a genuine rice-wheat CA trial -> red rice rows (Rana 2023, Bazaya 2009). | E38: Author 2026-10-03 / 2026-10-05 | F38: IN FORCE
A39: 32 | B39: Cropping system & design | C39: Factorial / split-plot papers: use the interaction (cell) means; papers with only marginal / mixed-rotation means -> excluded, values in notes. | D39: Tripathi 2007 (72). | E39: Codes | F39: IN FORCE
A40: 33 | B40: Cropping system & design | C40: Non-tillage factors (N dose, irrigation, nutrient source, variety, density, rotation ...) crossed with tillage -> one row per factor level (cell means), level named in Notes and 'Fertilizer dose & other management'. | D40: Only if no cell means are printed, the main-effect mean is used and flagged. From serial 76 onward (not retroactive). Main-effect means pooled over residue -> entered flagged. | E40: Author 2026-10-03 / 2026-10-04 | F40: IN FORCE
A41: 34 | B41: Cropping system & design | C41: Amendments and confounded treatments are excluded: biochar, compost added, INM / nutrient-management trials with identical tillage, unfertilised control or undefined farmer practice when a fertilised tier exists, rotation treatments. | D41: Artificial warming: ambient (W0) rows only, warmed rows in notes. Rhizosphere devices / simulated tillage soil excluded. | E41: Author 2026-10-03 / 2026-10-05 | F41: IN FORCE
...

Sheet Codes
A1: TREATMENT CODES
A2: Code | B2: Meaning | C2: Typical descriptions in papers
A3: CA | B3: Zero tillage + residue retention | C3: ZT+R, ZTW with residue, permanent beds with residue, NT + mulch, CA-based scenario
A4: CT | B4: Conventional tillage, NO residue | C4: CT, farmers practice, puddled transplanted rice - conventional till wheat, residue removed/burnt
A5: ZT | B5: Zero tillage only, no residue | C5: ZT, NT, direct drilled without residue
A6: DT | B6: Deep tillage only, no residue | C6: deep ploughing, sub-soiling, chiselling without residue
A7: MTR | B7: Minimum / reduced tillage WITH residue | C7: RT+R, reduced till (power tiller 2 passes, 0.08-0.10 m) + residue, rotary till drill + residue, reduced puddling + residue, unpuddled harrowing+rotavator + residue
A8: MT | B8: Minimum / reduced tillage only, no residue | C8: RT, reduced till, rotary till drill, reduced puddling, 2 passes power tiller, unpuddled rice without residue
A9: CTR | B9: Conventional tillage WITH residue | C9: CT+R, conventional till with residue incorporated
A10: DTR | B10: Deep tillage WITH residue | C10: deep tillage + residue incorporation
A11: pCA | B11: PARTIAL CA: puddled / conventional-till rice + ZERO-TILL wheat WITH residue retained | C11: PTR-ZTW+R, TPR fb ZTW (Happy Seeder / Turbo Happy Seeder into rice residue), puddled rice + ZT wheat with mulch
A12: pZT | B12: PARTIAL ZT: puddled / conventional-till rice + ZERO-TILL wheat, residue REMOVED / burnt | C12: PTR-ZTW, TPR fb ZTW (no residue), puddled rice + ZT drill wheat
A13: pMT | B13: PARTIAL MT: puddled / conventional-till rice + MINIMUM / REDUCED-till wheat, NO residue | C13: PTR + rotary till-drill / Super Seeder / strip-till wheat (rotary <= 8 cm or single pass), no residue
... A18: NOTE | B18: Unclear treatments | C18: Left out of the data sheets and raised with you.
A20: RECLASSIFICATION
A21: Climate | B21: latitude > 30 deg -> TEMP (temperate) | C21: Pittelkow et al. 2015; Mondal et al. 2018
A22: Climate | B22: latitude <= 30 deg -> ST (sub-tropical)
A23: Texture | B23: Sandy clay loam, silty clay loam, clay loam, silt, silt loam, loam, sandy loam -> LOAMY | C23: Shirazi et al. 2001
A24: Texture | B24: Loamy sand, sand -> SANDY
A25: Texture | B25: Sandy clay, silty clay, clay -> CLAYEY
A26: Texture | B26: Class not stated -> derive from sand/silt/clay using the USDA texture triangle, then reclassify
A27: Duration | B27: 0-3 Y / 4-10 Y / >10 Y | C27: Years since the trial was established at the time of sampling
A28: Depth (general) | B28: 0-15, 15-30, 30-45, 45-60, >60 CM | C28: Reported depth reassigned by MAXIMUM OVERLAP, applied SEQUENTIALLY so consecutive reported layers fall in consecutive classes. Worked rules agreed with author: (a) paper reports 0-20 / 20-40 cm -> 0-20 = 0-15 CM, 20-40 = 15-30 CM. (b) paper reports 0-10 / 10-20 / 20-40 cm -> 0-10 = 0-15 CM, 10-20 = 15-30 CM, 20-40 = 30-45 CM. Original depth always kept in 'DEPTH (as reported in paper)'. If a paper genuinely reports >1 layer inside one class, all are entered and Obs increases.
A29: Depth (PR) | B29: 0-10, 10-20, 20-30, 30-40, 40-50, 50-60 CM | C29: Penetration resistance only
A30: Depth (C stock / sequestration) | B30: 0-10, 0-20, 0-30, 0-40, 0-50, 0-60 CM | C30: Cumulative depths
A32: DATA SOURCE TAGS | B32: Text / Table n / Figure n (digitised) / Supplementary / Calculated / Author-reported
A34: DECISIONS (author-confirmed)
A35: EXCLUDED | B35: No-till rice + conventional-till wheat (RNT-WCT, AT1 type) | C35: Excluded from the meta-analysis entirely. Log in Treatment_Mapping with ASSIGNED CODE = EXCLUDED, Status = EXCLUDED.
A36: SD | B36: SD = SQRT(2*Obs/Rep) | C36: Formula carried over from the original workbook; replaced by the real SD when a paper reports SD or SE (SD = SE*SQRT(Rep)).
A37: Rep | B37: Always 3 | C37: Unless the paper explicitly states a different number of replications.
A38: Season | B38: Wheat season only | C38: Soil parameters measured in the rice season are not entered.
A40: ROTATION-MATCHING RULE
A41: Rule | B41: Within a SINGLE treatment, the rice phase and the wheat phase must be the SAME type of tillage. If one phase is conventional and the other is conservation (or vice versa), that treatment is EXCLUDED. | C41: INCLUDE: puddled transplanted rice + conventional tillage wheat = CT. ZT/unpuddled/DSR rice + ZT wheat, residue in both = CA. ZT rice + ZT wheat, no residue = ZT. EXCLUDE: no-till rice + conventional-till wheat (RNT-WCT). EXCLUDE: conventionally puddled transplanted rice + zero-till wheat. EXCLUDE: conventional-till DSR + reduced-till wheat (CTDSR-RTW).
A42: Consequence | B42: Any treatment with contrasting tillage between the two phases is dropped, in either direction. | C42: Log it in Treatment_Mapping with ASSIGNED CODE = EXCLUDED. If this leaves a study with no CA-vs-CT (or other-vs-CT) pair, the whole study contributes nothing and its rows are moved to EXCLUDED_rows.
A43: Factorial / split-plot papers | B43: Use the INTERACTION (cell) means so the rice and wheat phase are matched, not the marginal means of one factor. | C43: A marginal mean for a wheat treatment is averaged across every rice treatment, so its rice phase is a mixture. If the paper reports only marginal means and no cell means, note it in Notes/Doubts and flag the row.
A45: RULE AMENDMENT - WITHDRAWN
A46: WITHDRAWN | B46: A short-lived amendment exempted wheat-phase-only experiments from the rotation-matching rule. It has been WITHDRAWN at the author's instruction. | C46: The rule applies in full again: the previous crop's tillage counts, and only treatments with the SAME type of treatment in the rice and the wheat phase are included (e.g. puddled transplanted rice + conventional tillage wheat = CT). Reversed for Singh & Singh 2021 (ZT removed again) and Kumar et al. 2012 (all rows moved to EXCLUDED_rows).
A47: IN FORCE | B47: Any treatment whose rice and wheat phases differ in tillage type is excluded, whether or not the contrast was part of the experimental design. | C47: Excludes: no-till rice + conventional-till wheat (RNT-WCT); conventionally puddled rice + zero-till or bed-planted wheat; conventional-till DSR + reduced-till wheat.
A48: CONSISTENT | B48: Sharma et al. 2022 (study 1) stays excluded - its ZTWR0 and ZTWR100 follow a conventionally puddled rice phase. | C48: Its 22 rows remain in EXCLUDED_rows. Consistent with Singh & Singh 2021 ZT, Kumar et al. 2012, Bachchan et al. 2018 and Paliwal et al. TPR-ZTW-ZTS.
A50: RULE REFINEMENT (author instruction)
...

Sheet FORMULAS
A1: Parameter | B1: Formula (definition) | C1: Excel implementation in this workbook | D1: Unit | E1: Where applied | F1: Reference / note
A2: SD | B2: SD = SQRT(2 x Obs / Rep) | C2: Excel: =IF(AND(N(Obs)>0,N(Rep)>0),SQRT(2*Obs/Rep),"") | D2: - | E2: every data sheet (SD column) | F2: Original workbook rule; replaced by real SD only when a paper prints SD/SE
A3: Obs | B3: Obs = Y + T + D (years + paper treatments under one code + original depths collapsed into the row) | C3: entered value | D3: count | E3: every data sheet | F3: Codes / README rule
A4: STRAW YIELD | B4: Straw yield = biological (above-ground) yield - grain yield | C4: Excel: =ROUND(biomass - grain_cell, 2) in W STRAW_ / RSTRAW_ columns | D4: t/ha | E4: YIELD: studies 47 (row 50), 53 (row 62), 104, 106, 120 (all rows where only biomass is printed) | F4: Author instruction 2026-10-04
A5: HARVEST INDEX | B5: HI = grain / biological yield = grain / (grain + straw) | C5: Excel: =ROUND('YIELD'!grain/('YIELD'!grain+'YIELD'!straw),3) or =ROUND(grain/biomass,3); printed % -> /100 | D5: ratio 0-1 | E5: HARVEST INDEX sheet (printed values where the paper gives HI; DERIVED rows reference the YIELD cells) | F5: Added 2026-10-04
A6: BIOLOGICAL YIELD | B6: Biological yield = grain + straw | C6: (inverse of the straw rule; used only in notes) | D6: t/ha | E6: notes
A7: UNIT CONVERSIONS | B7: kg/ha / 1000 = t/ha; q/ha / 10 = t/ha; 10^4 spikes/ha = spikes/m2; grains per 5 spikes / 5 = grains per spike; printed x1000 Rs -> x 1000 | C7: Excel: =value/1000 , =value/10 , =ROUND(x/5,2) , =ROUND(x*1000,0) | D7: - | E7: YIELD, GRAINS PER PANICLE, NET RETURN
A8: TOTAL POROSITY | B8: Porosity (%) = (1 - BD / PD) x 100; PD = treatment PD, else initial PD of the paper, else 2.65 Mg/m3 | C8: Excel: =ROUND((1-BD!cell/PD)*100,2) (live link to the BD sheet; PD cell or value named in Notes) | D8: % | E8: POROSITY sheet (all treatment columns incl. pCA / pZT / pMT / pMTR) | F8: Author rule 2026-10-05
A9: SOC FROM SOM / OM | B9: SOC = SOM (or OM) / 1.724 | C9: Excel: =ROUND(SOM/1.724,3) | D9: g/kg | E9: SOC, soc (initial) where only OM is printed | F9: Van Bemmelen factor
A10: SOC STOCK | B10: SOC stock (Mg/ha) = SOC (g/kg) x BD (Mg/m3) x depth (cm) x 0.1 | C10: live formula from SOC and BD cells | D10: Mg C/ha | E10: stock-SOC
A11: C LIABILITY (CL) | B11: CL = labile C / non-labile C = POXC / (SOC x 1000 - POXC) | C11: Excel: =ROUND(POXC/(SOC*1000-POXC),3) | D11: ratio | E11: C liability (75 companion, 92, 102) | F11: Blair et al. 1995
A12: LABILITY INDEX (LI) | B12: LI = CL_treatment / CL_reference (reference = CT) | C12: LI_CT = 1; LI_x = CL_x / CL_CT | D12: - | E12: LI sheet | F12: Blair et al. 1995
A13: C POOL INDEX (CPI) | B13: CPI = SOC_treatment / SOC_reference (reference = CT) | C13: CPI_CT = 1; CPI_x = SOC_x / SOC_CT | D13: - | E13: CPI sheet | F13: Blair et al. 1995
A14: C MANAGEMENT INDEX (CMI) | B14: CMI = CPI x LI x 100 | C14: CMI_CT = 100; =ROUND(CPI*LI*100,2) | D14: - | E14: CMI sheet | F14: Blair et al. 1995
A15: GWP | B15: GWP = CH4 x 28 + N2O x 265 (kg CO2-eq/ha); CH4 = CH4-C x 16/12; N2O = N2O-N x 44/28 | C15: Excel: =ROUND(CH4*28+N2O*265,0) | D15: kg CO2-eq/ha | E15: GWP sheet | F15: IPCC AR5 100-yr factors
A16: GHG INTENSITY (GHGI) | B16: GHGI = GWP / grain yield | C16: Excel: =ROUND('GWP'!x/('YIELD'!y*1000),3) | D16: kg CO2-eq/kg grain | E16: GHG intensity (printed rows 76, 103; DERIVED rows 17, 26, 29, 45, 46, 89, 90c) | F16: Added 2026-10-04
A17: NET RETURN | B17: Net return = gross return - total cost of cultivation | C17: entered as printed (or =x*1000 / =rice+wheat sums) | D17: currency/ha as printed | E17: NET RETURN sheet | F17: Sheet added 2026-10-04; gross-margin rows flagged
A18: B:C RATIO | B18: B:C (sheet definition) = net return / cost; when a paper prints gross/cost: B:C - 1 | C18: Excel: =ROUND(net/cost,3) or =ROUND(printed-1,2) | D18: ratio | E18: BC ratio sheet | F18: Workbook definition
A19: SYSTEM YIELD / REY | B19: System yield = rice + wheat grain; REY = sum(yield_i x price_i / price_rice) | C19: Excel: =rice+wheat | D19: t/ha | E19: YIELD SYS columns, SYS STRAW
A20: POXC DERIVATIONS | B20: POXC (mg/kg) = ASOM / 1.724 x 1000 (study 92); = LOC/SOC ratio x SOC x 1000 (study 102) | C20: Excel: =ROUND(x/1.724*1000,1) ; =ROUND(ratio*SOC*1000,0) | D20: mg/kg | E20: POXC(KMnO4-C)
A21: WATER CONTENT BASIS | B21: theta_w (% w/w) = theta_v (% v/v) / BD; theta_v = theta_w x BD | C21: Excel: =ROUND(value/BD!cell,2) or =ROUND(value/1.35,2) (default BD) | D21: % w/w / % v/v | E21: GWC, AWC (weight / volume basis), FC, PWP | F21: Author rule 2026-10-04: default BD 1.35 Mg/m3
A22: AWC FROM FC AND PWP | B22: AWC = FC - PWP (same basis) | C22: derived in notes / rows | D22: % | E22: AWC sheets (study 28)
A23: AWC AS WATER DEPTH | B23: AWC (% v/v) = water depth (cm) / layer thickness (cm) x 100 | C23: Excel: =ROUND(cm/15*100,2) | D23: % v/v | E23: AWC (study 3)
A24: AWC FROM FC AND PWP (live) | B24: AWC (w/w) = FC (w/w) - PWP (w/w); AWC (v/v) = AWC (w/w) x BD | C24: Excel: =ROUND('FC (weight basis)'!cell-'PWP (weight basis)'!cell,2) ; =ROUND('AWC (weight basis)'!cell*BD!cell,2) | D24: % w/w / % v/v | E24: AWC sheets (study 9) | F24: Added 2026-10-05
A25: GWC FROM PLOTTED VWC | B25: GWC (% w/w) = VWC (m3/m3) x 100 / BD of the same layer (paper's own BD when the study has no BD-sheet rows) | C25: Excel: =ROUND(vwc*100/bd,2) | D25: % w/w | E25: GWC (study 12) | F25: Added 2026-10-05
A26: PMN FROM NET N MINERALISATION RATE | B26: PMN (mg/kg) = net N mineralisation rate (mg/kg/d) x incubation days (14) | C26: Excel: =ROUND(rate*14,2) | D26: mg/kg | E26: no3,nh4,PMN (study 136) | F26: Added 2026-10-05
A27: ENZYME UNIT umol/g/d -> nmol/h/g | B27: nmol/h/g = umol/g/d x 1000 / 24 | C27: Excel: =ROUND(x*1000/24,1) | D27: nmol/h/g | E27: NAG, LAP (study 136) | F27: Added 2026-10-05

Sheet Study_Info
A1: No. | B1: SERIAL NO | C1: Authors | D1: Year | E1: Journal | F1: Full reference | G1: DOI / link | H1: Country | I1: Site/Location | J1: latitude | K1: longitude | L1: latitude (as reported) | M1: longitude (as reported) | N1: Coordinates source | O1: CLIMATE | P1: Experiment established (year) | Q1: year of data collection/experiment | R1: Years of data reported | S1: DURATION | T1: SOIL | U1: Texture as reported | V1: sand | W1: silt | X1: CLAY | Y1: ph (initial) | Z1: soc (initial) | AA1: Bdi | AB1: MIN TEMP | AC1: MAX TEMP | AD1: AVG T | AE1: April max temp | AF1: RAIN FALL | AG1: Crop rotation | AH1: Wheat variety | AI1: Rice variety | AJ1: N dose (kg/ha) | AK1: P dose (kg/ha) | AL1: K dose (kg/ha) | AM1: Residue type & rate (t/ha) | AN1: Irrigation / water management | AO1: Treatments in paper | AP1: Parameters extracted | AQ1: Supplementary data? | AR1: Notes/Doubts
A2: 164 | B2: 164 | C2: Yadav R.L., Dwivedi B.S., Prasad K., Tomar O.K., Shurpali N.J. & Pandey P.S. | D2: 2000 | E2: Field Crops Research | F2: Yadav RL et al. (2000) Yield trends, and changes in soil organic-C and available NPK in a long-term rice-wheat system under integrated use of manures and fertilisers. Field Crops Res 68:219-246 | G2: https://doi.org/10.1016/S0378-4290(00)00126-X | H2: India (7 sites) | I2: Ludhiana, Pantnagar, Kanpur, Faizabad, Sabour, Kalyani, Jabalpur (one row per site in data sheets) | N2: Paper (each site); see LAT_LONG | O2: ST (Ludhiana TEMP) | P2: 1983-1986 (by site) | Q2: 1983-84 to 1998-99 | R2: 12-15 seasons per site (year-wise yields); soil after final wheat | S2: >10 Y | AG2: Rice-wheat (transplanted rice) | AJ2: 120 (100F); 60 + CR (50F+CR rice) | AK2: 26 | AL2: 33 | AM2: Wheat straw to rice: 8.8-15.8 t/ha/yr (by site) in 50F+CR | AN2: Irrigated; rice 5 cm flooding; wheat 5 irrigations | AO2: TREATMENTS IN PAPER (network long-term experiment, RBD 4 reps, plots 6 x 5 m, since 1983): Control (no fertiliser/manure); 50F (50% NPK rice, 100% wheat); 100F (100% NPK both crops) ; 50F+FYM, 50F+CR, 50F+GM = 50% NPK + 50% of recommended N through FYM, wheat crop residue (CR) or Sesbania green manure TO RICE ONLY, wheat 100% NPK. Recommended 120-26-33 kg N-P-K/ha each crop. Rice transplanted (puddled) 20 x 10 cm, wheat sown in 23 cm rows; above-ground biomass of both crops removed (sickle at ground level) except the CR returned in 50F+CR. 100F -> CT ; 50F+CR -> CTR (FLAG fertiliser offset, rule 62); Control, 50F, 50F+FYM, 50F+GM EXCLUDED. | AP2: YIELD (year-wise rice & wheat, 7 sites); SOC; available N (4 sites), P, K (final year) | AQ2: None found - web search 2026-10-05 (publisher pages not reachable from this environment) | AR2: INCLUDED FLAGGED (rule 62): 100F (CT) vs 50F+CR (CTR) - fertiliser cut offset by straw. Yields digitised year-wise from Fig. 2 and validated against Table 3 means. FLAG - FERTILISER OFFSET (rule 62): 50F+CR gets only 50% NPK to rice (wheat straw supplies the other 50% of N; P cut, K over-supplied) and 100% NPK to wheat; wheat straw is incorporated 1 month before rice transplanting (residue enters before the RICE phase only). Wheat tillage not described -> conventional (puddled transplanted rice + tilled wheat). Supplementary: none found (web search 2026-10-05; publisher site not reachable). Source file 112.pdf.
A3: 165 | B3: 165 | C3: Davari M.R., Sharma S.N. & Mirzakhani M. | D3: 2012 | E3: Biological Agriculture & Horticulture | F3: Davari MR, Sharma SN, Mirzakhani M (2012) Effect of cropping systems and crop residue incorporation on production and properties of soil in an organic agroecosystem. Biol Agric Hortic 28(3):206-222 | G3: https://doi.org/10.1080/01448765.2012.735005 | H3: India (Delhi) | I3: IARI research farm, New Delhi (organic rice-based cropping systems trial) | J3: 28.633 | K3: 77.183 | L3: 28 deg 38'N | M3: 77 deg 11'E | N3: Paper | O3: ST | P3: 2006 | Q3: 2006-07, 2007-08 | R3: 2 | S3: 0-3 Y | T3: LOAMY | U3: Sandy clay loam | V3: 52.06 | W3: 22.54 | X3: 25.4 | Y3: 8.16 | Z3: 5.2 | AA3: 1.5 | AG3: Rice-wheat and rice-wheat-mungbean (organic) | AH3: HD 2643 | AI3: Pusa Basmati 1 | AJ3: 60 (FYM-N, organic) | AM3: All residues incorporated in RI: 14.2-19.7 Mg DM/ha/yr | AN3: Rice flooded/puddled; mungbean 2 irrigations | AO3: TREATMENTS IN PAPER: strip-plot, 3 reps, 2006-07 and 2007-08, ORGANIC management. Rows = cropping system: RW (rice-wheat, summer fallow) and RWM (rice-wheat-mungbean, summer mungbean with Rhizobium + PSB); columns = residue: RR (entire above-ground biomass removed) and RI (all residue of each crop incorporated before the next crop: rice residue for wheat, wheat residue for rice in RW / for mungbean in RWM, mungbean residue for rice). Rice: field flooded and PUDDLED with tractor-drawn offset disc harrow, Pusa Basmati 1 transplanted 20 x 10 cm. Wheat: after rice harvest, residue (RI) + FYM incorporated with tractor-drawn heavy disc, then disked and planked twice; HD 2643 sown 3rd week Nov. RR -> CT, RI -> CTR (in both systems). | AP3: Rice, wheat, rice-equivalent yield (year-wise); SOC, Kjeldahl N, Olsen P, NH4OAc K (year-wise); BD, porosity, HC; bacteria, fungi, actinomycetes, MBC, DHA, CO2 evolution | AQ3: None found - web search 2026-10-05 (publisher pages not reachable from this environment) | AR3: INCLUDED: RR (CT) vs RI (CTR) in RW and in RWM (mungbean in both treatments of the RWM row, flagged). Protein yield and energy output (Figs 1-2) have no sheet. Rotation-matched: puddled transplanted rice + disc-tilled wheat = conventional in both phases; residue incorporated by disc -> CTR. FLAG: RI plots also received a cellulolytic culture spray (confounded with residue). Supplementary: none found (web search 2026-10-05; publisher site not reachable). Source file 113_rqal.pdf.
A4: 166 | B4: 166 | C4: Das B., Chakraborty D., Singh V.K., Aggarwal P., Singh R., Dwivedi B.S. & Mishra R.P. | D4: 2014 | E4: Soil & Tillage Research | F4: Das B et al. (2014) Effect of integrated nutrient management practice on soil aggregate properties, its stability and aggregate-associated carbon content in an intensive rice-wheat system. Soil Tillage Res 136:9-18 | G4: https://doi.org/10.1016/j.still.2013.09.009 | H4: India (Uttar Pradesh) | I4: PDFSR (now ICAR-IIFSR) long-term INM experiment, Modipuram, Meerut | J4: 29.067 | K4: 77.767 | L4: 29 deg 4'N | M4: 77 deg 46'E | N4: Paper | O4: ST | P4: 1993 | Q4: 2011 | R4: Soil 2011; yields as 3-yr means 1993-96 and 2008-11 | S4: >10 Y | T4: LOAMY | U4: Sandy loam | V4: 55 | W4: 18 | X4: 27 | Y4: 7.98 | Z4: 4.1 | AA4: 1.55 | AB4: 5 | AC4: 45.5 | AF4: 863 | AG4: Rice-wheat | AH4: HD 2338 | AI4: Saket 4 | AJ4: 120 (T2); 90 + CR (T8) | AK4: 26 | AL4: 33 | AM4: T8: rice and wheat straw supplying 25% of N (61.5 + 47.7 Mg C/ha over 18 yr) | AN4: Rice continuous 5 cm submergence; wheat 5 irrigations | AO4: TREATMENTS IN PAPER (Table 1, RBD 3 reps, since 1993, PDFSR Modipuram): T1 unfertilised; T2 recommended NPK (+Zn to rice) through fertilisers; T3 NPK + Zn + S (rice); T4 75% NPK + 25% N via FYM (rice); T5 75% NPK + 25% N via sulphitation press mud (rice); T6 75% NPK + green gram residue incorporated before rice; T7 = T6 (rice) + 75% NPK + 25% N via FYM (wheat); T8 75% NPK + 25% N via WHEAT STRAW to rice and 75% NPK + 25% N via RICE STRAW to wheat (CR). Rice puddled and transplanted (Saket 4, 20 x 10 cm, continuous 5 cm submergence); wheat HD 2338 drilled after dry tillage ('wet tillage followed by dry tillage'); recommended 120-26-33 kg N-P-K/ha to each crop. T2 -> CT ; T8 -> CTR (FLAG fertiliser offset, rule 62); T1, T3-T7 EXCLUDED (unfertilised / amendments / third crop in some treatments only). | AP4: TOC; macro/micro aggregates, WSA (derived), MWD (slaked + capillary), macro-C, micro-C, cPOM-C; aggregate FC/PWP/AWC; yields (3-yr means) | AQ4: None found - web search 2026-10-05 (publisher pages not reachable from this environment) | AR4: INCLUDED FLAGGED (rule 62): T2 (CT) vs T8 (CTR). FLAG - FERTILISER OFFSET (rule 62): in T8 crop residue replaces 25% of fertiliser N and 25% of P and K are also cut; drop for a fertiliser-matched sensitivity check. Wheat tillage not described in detail ('wet tillage followed by dry tillage', residue incorporated) -> conventional. Supplementary: none found (web search 2026-10-05; publisher site not reachable). Source file 113.pdf.
A5: 167 | B5: 167 | C5: Naz A., Rebi A., Naz R., Akbar M.U., Aslam A., Kalsom A., Niaz A., Ahmad M.I., Nawaz S., Kausar R., Ali B., Saleem M.H. & Zhou J. | D5: 2023 | E5: Land | F5: Naz A et al. (2023) Impact of green manuring on health of low fertility calcareous soils. Land 12:546 | G5: https://doi.org/10.3390/land12030546 | H5: Pakistan (Punjab) | I5: Khushab / Faisalabad, Punjab (calcareous soil field trial) | P5: 2015 | Q5: 2015-2018 | AG5: Rice-berseem (green manure) | AO5: Control; NPK (100% RDF); GM100, GM75, GM50 = berseem green manure (last cutting rotavated in) + 100/75/50% RDF; rice puddled-transplanted in all | AP5: NONE (excluded) | AQ5: None found - web search 2026-10-05 (publisher pages not reachable from this environment) | AR5: EXCLUDED: rice-berseem green-manure x fertiliser-dose trial - no wheat phase in the treatments, identical (puddled/rotavator) tillage and no crop-residue contrast; green manure is an amendment here, not part of a CA treatment (rule 34; rule 71 lets GM support CA, but there is no CA). Source file 111_real.pdf.
A6: 168 | B6: 168 | C6: Dhaliwal J.K., Singh M.J., Sharma S., Gupta N. & Kukal S.S. | D6: 2020 | E6: Soil Research | F6: Dhaliwal JK, Singh MJ, Sharma S, Gupta N, Kukal SS (2020) Medium-term impact of tillage and residue retention on soil physical and biological properties in dry-seeded rice-wheat system in north-west India. Soil Research 58:468-477 | G6: https://doi.org/10.1071/SR19238 | H6: India (Punjab) | I6: PAU research farm, Ludhiana (DSR-wheat tillage x mulch trial of Gupta et al. 2016) | J6: 30.933 | K6: 75.867 | L6: 30 deg 56'N | M6: 75 deg 52'E | N6: Paper | O6: TEMP | P6: 2011 | Q6: 2016 | R6: 1 | S6: 4-10 Y | T6: LOAMY | U6: Sandy loam (Typic Ustochrept) | Y6: 7.4 | AF6: 734 | AG6: Dry-seeded rice-wheat | AH6: PBW 621 | AI6: PR 115 | AM6: Rice residue 7 t/ha surface mulch in wheat (+M) | AN6: Irrigated (PAU recommendations) | AO6: TREATMENTS IN PAPER (Table 1; three-factor trial est. 2011 - only the 'absolute' CT and ZT rice and wheat combinations were studied): 1 CTW-CTDSR (-M) = conventionally tilled wheat (1 discing + 1 tyne harrowing + planking) and conventionally tilled dry-seeded rice, all rice residue removed -> CT ; 2 CTW+M-CTDSR = as 1 with ALL rice residue (7 t/ha) retained as surface mulch in wheat -> CTR ; 3 ZTW-ZTDSR = zero-till wheat (Turbo Happy Seeder) and zero-till DSR (inverted-T tyne ZT drill), residue removed -> ZT ; 4 ZTW+M-ZTDSR = as 3 with rice residue mulch -> CA. Wheat straw removed in every treatment (cut 3-5 cm above ground). RBD 3 reps; plots 9.3 x 6.5 m. | AP6: SOC, SOC stock, macro/micro WSA, WSA (derived), MWD, BD, porosity (derived), IR (initial + steady), FC/PWP/AWC, MBC, BSR, DHA, urease, ALP, ACP | AQ6: None found - web search 2026-10-05 (publisher pages not reachable from this environment) | AR6: INCLUDED: CT, CTR, ZT, CA. ALL ROWS RED (rice-season fallback - sampling after 2016 rice harvest only). Enzymes = tillage main effects (flagged). RICE-SEASON DATA (RED ROW): the paper samples ONLY after the 2016 rice harvest, so values are entered under the rice-season fallback rule (rule 36). Rotation-matched: CT rice + CT wheat = CT; ZT rice + ZT wheat = ZT/CA (rice residue is the mulch factor). Supplementary: none found (web search 2026-10-05; publisher site not reachable from this environment). Source file 112_real.pdf.
A7: 169 | B7: 169 | C7: Singh V.K., Dwivedi B.S., Shukla A.K., Chauhan Y.S. & Yadav R.L. | D7: 2005 | E7: Field Crops Research | F7: Singh VK et al. (2005) Diversification of rice with pigeonpea in a rice-wheat cropping system on a Typic Ustochrept: effect on soil fertility, yield and nutrient use efficiency. Field Crops Res 92:85-105 | G7: https://doi.org/10.1016/j.fcr.2004.09.002 | H7: India (Uttar Pradesh) | I7: PDCSR Modipuram, Meerut + farmers' survey (Upper Gangetic Plain) | AG7: Rice-wheat vs pigeonpea-wheat | AO7: Cropping system (rice-wheat vs pigeonpea-wheat) x N (0/120) x P (0/26) to wheat | AP7: NONE (excluded) | AQ7: None found - web search 2026-10-05 (publisher pages not reachable from this environment) | AR7: EXCLUDED: crop-diversification x fertiliser trial (rice replaced by pigeonpea); no tillage or crop-residue contrast within rice-wheat (rule 34). Source file 114.pdf.
A8: 23 (companion 3) | B8: 23 (companion 3) | C8: Jat H.S., Datta A., Choudhary M., Yadav A.K., Choudhary V., Sharma P.C., Gathala M.K., Jat M.L. & McDonald A. | D8: 2019 | E8: Soil & Tillage Research | F8: Jat HS et al. (2019) Effects of tillage, crop establishment and diversification on soil organic carbon, aggregation, aggregate associated carbon and productivity in cereal systems of semi-arid Northwest India. Soil Tillage Res 190:128-138 | G8: https://doi.org/10.1016/j.still.2019.03.005 | H8: India (Haryana) | I8: ICAR-CSSRI research farm, Karnal (CSISA scenario trial, est. 2009) | J8: 29.7 | K8: 76.96 | L8: 29 deg 70'N (as printed) | M8: 76 deg 96'E (as printed) | N8: Paper (non-standard minutes, read as decimals) | O8: ST | P8: 2009 | Q8: 2013, 2015 (soil); 2009-10 to 2014-15 (yield) | R8: 2 soil samplings; 6 yield years | S8: 4-10 Y | T8: LOAMY | U8: Loam, reclaimed alkali (Typic Natrustalf) | AB8: 2 | AC8: 42.5 | AF8: 700 | AG8: Rice-wheat (Sc1); rice-wheat-mungbean (Sc2, Sc3) | AM8: Sc2 78.5, Sc3 74.5 t/ha over 6 yr | AO8: TREATMENTS IN PAPER (CSISA scenario trial, ICAR-CSSRI Karnal, est. 2009, RBD 3 reps, 100 x 20 m plots): Sc1 conventional rice-wheat (puddled manually transplanted rice, broadcast CT wheat, residues removed; farmers' practice) -> CT ; Sc2 partial CA rice-wheat-mungbean (puddled transplanted rice; ZT drill-seeded wheat and mungbean; anchored rice stubble 4.1-12.7 t/ha retained at wheat sowing, mungbean residue incorporated during puddling) -> pCA ; Sc3 full CA rice-wheat-mungbean (ZT DSR, ZT wheat, ZT mungbean, residues retained on the surface) -> CA ; Sc4 full CA maize-wheat-mungbean -> EXCLUDED (maize). Residue added 2009-15: Sc2 78.5, Sc3 74.5 t/ha. | AP8: WB-C, TOC, macro/micro WSA, WSA, MWD, GMD, macro-C, micro-C, POC (2013, 2015, 2 depths); REY 6 years | AQ8: None found - web search 2026-10-05 (publisher pages not reachable from this environment) | AR8: INCLUDED: Sc1 CT, Sc2 pCA, Sc3 CA. Soil rows RED (after rice harvest). GREEN MANURE / 3rd CROP: ZT mungbean in Sc2 and Sc3, not in Sc1 (rule 71). pCA (Sc2) was EXCLUDED in old-master study 23 (rotation mismatch) and is now coded pCA (rule 68). COMPANION of old-master study 23 (same CSSRI trial). Supplementary: none found. Source file 115_rep.pdf.
A9: 23 (companion 4) | B9: 23 (companion 4) | C9: Jat H.S., Datta A., Choudhary M., Sharma P.C., Yadav A.K., Choudhary V., Gathala M.K., Jat M.L. & McDonald A. | D9: 2019 | E9: Catena (accepted manuscript; version of record S0341816219301936) | F9: Jat HS et al. (2019) Climate Smart Agriculture practices improve soil organic carbon pools, biological properties and crop productivity in cereal-based systems of North-West India. Catena | G9: https://www.sciencedirect.com/science/article/pii/S0341816219301936 | H9: India (Haryana) | I9: ICAR-CSSRI research farm, Karnal (CSISA scenario trial, est. 2009) | J9: 29.7 | K9: 76.95 | N9: Paper | O9: ST | P9: 2009 | Q9: 2013 | R9: 1 | S9: 4-10 Y | T9: LOAMY | U9: Loam (Typic Natrustalf), OC 0.45% | Z9: 4.5 | AB9: 11.62 | AC9: 31.68 | AF9: 670 | AG9: Rice-wheat (Sc1); rice-wheat-mungbean (Sc2, Sc3) | AM9: Sc2 47.9, Sc3 56.1 t/ha over 4 yr | AO9: TREATMENTS IN PAPER (CSISA scenario trial, ICAR-CSSRI Karnal, est. 2009, RBD 3 reps, 100 x 20 m plots): Sc1 conventional rice-wheat (puddled manually transplanted rice, broadcast CT wheat, residues removed; farmers' practice) -> CT ; Sc2 partial CA rice-wheat-mungbean (puddled transplanted rice; ZT drill-seeded wheat and mungbean; anchored rice stubble 4.1-12.7 t/ha retained at wheat sowing, mungbean residue incorporated during puddling) -> pCA ; Sc3 full CA rice-wheat-mungbean (ZT DSR, ZT wheat, ZT mungbean, residues retained on the surface) -> CA ; Sc4 full CA maize-wheat-mungbean -> EXCLUDED (maize). Residue added 2009-13: Sc2 47.9, Sc3 56.1 t/ha. | AP9: SOC stock; VL/L/LL/NL C (derived g/kg); DHA, ALP, MBC, MBN, BSR, fungi, bacteria, actinomycetes (2 depths) | AQ9: None found - web search 2026-10-05 (publisher pages not reachable from this environment) | AR9: INCLUDED: Sc1 CT, Sc2 pCA, Sc3 CA. All rows RED. RICE-SEASON DATA (RED ROW). SAME SAMPLING (Oct 2013) as 23 (companion 3); parameters split between the two papers (no duplicates): concentrations of WB-C/TOC from companion 3, stocks, C pools and biology from this paper. GREEN MANURE / 3rd CROP: mungbean in Sc2 and Sc3 (rule 71). Supplementary: none found. Source file 116_rep.pdf.
A10: 165 (companion) | B10: 165 (companion) | C10: Meena A.L., Pandey R.N., Kumar D., Dotaniya M.L., Sharma V.K., Singh G., Meena B.P., Kumar A. & Bhanu C. | D10: 2020 | E10: Communications in Soil Science and Plant Analysis | F10: Meena AL et al. (2020) Impact of 12-year-long rice based organic farming on soil quality in terms of soil physical properties, available micronutrients and rice yield in a typic Ustochrept soil of India. Commun Soil Sci Plant Anal | G10: https://doi.org/10.1080/00103624.2020.1822386 | H10: India (Delhi) | I10: IARI research farm, New Delhi (long-term organic rice-based project, since 2003) | J10: 28.4 | K10: 77.1 | L10: 28.4 N | M10: 77.1 E | N10: Paper | O10: ST | P10: 2003 | Q10: 2015-16 (soil); 2009-2015 (rice yield mean) | S10: >10 Y | T10: LOAMY | U10: Sandy clay loam | V10: 52.1 | W10: 22.5 | X10: 25.4 | Y10: 8.45 | Z10: 5.1 | AA10: 1.5 | AB10: 18 | AC10: 35.2 | AF10: 750 | AG10: Organic basmati rice-wheat and rice-wheat-mungbean | AH10: HD 2967 | AI10: Pusa Basmati 1121 | AJ10: 60 (FYM or VC N) | AM10: 3 t/ha preceding-crop residue to each crop (CR treatments) | AO10: TREATMENTS IN PAPER (IARI long-term organic project 'Nutrient management in rice-wheat cropping system under organic conditions', since kharif 2003, organic from 2006; strip plot, 3 reps): main strips RWCS (basmati rice-wheat) and RWMCS (rice-wheat-mungbean); rows: Control (no organics), FYM, VC (each = 60 kg N/ha), FYM + CR, VC + CR (crop residue of the preceding crop 3 t/ha to each crop), FYM + CR + BF, VC + CR + BF (BF = BGA + PSB + cellulolytic culture in rice; Azotobacter + PSB + cellulolytic in wheat; Rhizobium + PSB in mungbean). FYM -> CT, FYM + CR -> CTR (row a), FYM + CR + BF -> CTR (row b, BF flag); VC -> CT, VC + CR -> CTR (row a), VC + CR + BF -> CTR (row b); Control EXCLUDED (no organics). | AP10: BD, porosity (derived), WHC, MWD, GMD, Ks, pH, EC, SOC, C stock, available N, P, DTPA Cu/Zn/Mn/Fe, rice grain and straw yield | AQ10: None found - web search 2026-10-05 (publisher pages not reachable from this environment) | AR10: INCLUDED: FYM/VC (CT) vs +CR (CTR), rows a/b (+BF). Soil rows RED (after rice harvest). SAME IARI ORGANIC PROJECT as serial 165 (Davari et al. 2012: identical initial soil, rotations and strip-plot layout) -> filed as 165 (companion); the CR rate (3 t/ha) and treatment set differ from Davari's 2006-08 RR/RI comparison - check. Tillage not described in this paper; from the same project (Davari 2012): puddled transplanted rice, disc-ploughed wheat -> conventional (flag). Supplementary: none found. Source file 116_real.pdf.
A11: 131 (companion) | B11: 131 (companion) | C11: Zhang Y.-P., Li X., He H.-J., Zhou H., Geng D.-Y. & Zhang Y.-Z. | D11: 2023 | E11: Sustainability | F11: Zhang Y-P et al. (2023) Effects of rotational tillage on soil physicochemical properties and crop yield in a rice-wheat double cropping area. Sustainability 15:474 | G11: https://doi.org/10.3390/su15010474 | H11: China (Shandong) | I11: Taoluo Town, Donggang District, Rizhao, Shandong | J11: 35.27 | K11: 119.38 | N11: Approximate - Taoluo town centre (paper gives none; Donggang district 35.425 N, 119.462 E) | O11: TEMP | P11: 2017 | Q11: 2018-2020 | R11: BD 2018-2020; other soil after 3 yr | S11: 0-3 Y | U11: Paddy soil (texture not stated) | Y11: 6.8 | Z11: 5.75 | AA11: 1.423 | AD11: 12.6 | AF11: 916 | AG11: Rice-wheat (double cropping) | AH11: Yannong 21 | AI11: Linhan 1 | AJ11: Wheat 225; rice slow-release 25-10-10 600 kg + compound | AM11: Full straw return (crushed) in all | AO11: TREATMENTS IN PAPER (one 960 m2 strip per pattern, 2017-2019 rice seasons, Taoluo, Rizhao): RT = rotational tillage before rice (no-till 2017 and 2018, plough 2019; no-till dry direct-seeded rice) -> EXCLUDED (alternate tillage); CN = continuous no-till dry direct-seeded rice (wide-belt stubble seeder) 2017-2019 -> CA ; PR = plough + rotary tillage, irrigation, puddling and transplanting (30 x 12 cm) every year -> pCA. In ALL treatments wheat (Yannong 21, 187.5 kg/ha, 14 Oct) is sown WITHOUT tillage with the same seeder, and the crushed straw (<=10 cm) of the previous crop is fully returned. Before the trial: ploughing + rotary 15-18 cm, transplanting, straw removed. | AP11: BD (2018-20, 3 layers), porosity (derived), water-stable macro-aggregates, MWD (wet, dry), SOC, total N, alkali-N, P, K, SOC stock and sequestration (derived), rice/wheat yield and components | AQ11: None found - web search 2026-10-05 (publisher pages not reachable from this environment) | AR11: INCLUDED: CN = CA, PR = pCA (RT excluded). RE-ENTRY of old-master study 131 (excluded there 2026-10-04 as a rotation mismatch); re-evaluated under the PARTIAL-CA rule (rule 68): PR = puddled transplanted rice + no-till wheat with straw -> pCA, CN -> CA. FLAG: UNREPLICATED (one strip per pattern, multi-point sampling) - Rep kept 3 by rule. Coordinates approximate (Taoluo town centre; paper gives none). Texture not stated (paddy soil). Supplementary: none found. Source file 114_reqal.pdf.

Sheet PARAMETERS_BY_STUDY
A1: PARAMETERS OF EACH STUDY - auto-generated from the data sheets (2026-10-05); regenerated at every build
A3: No. | B3: Serial | C3: Authors | D3: Year | E3: Journal | F3: Status | G3: Data rows | H3: No. of parameters (sheets) | I3: Parameters in this workbook (sheet: rows) | J3: Parameters extracted (Study_Info, paper-level description)
A4: 1 | B4: 164 | C4: Yadav R.L., Dwivedi B.S., Prasad K., Tomar O.K., Shurpali N.J. & Pandey P.S. | D4: 2000 | E4: Field Crops Research | F4: INCLUDED | G4: 120 | H4: 5 | I4: SOC(active C pool): 7; N: 4; P: 7; K: 7; YIELD: 95 | J4: YIELD (year-wise rice & wheat, 7 sites); SOC; available N (4 sites), P, K (final year)
A5: 2 | B5: 165 | C5: Davari M.R., Sharma S.N. & Mirzakhani M. | D5: 2012 | E5: Biological Agriculture & Horticulture | F5: INCLUDED | G5: 38 | H5: 14 | I5: BD: 2; POROSITY: 2; HC: 2; SOC(active C pool): 4; RESP: 2; P: 4; K: 4; total N: 4; MBC: 2; DHA: 2; Actinomycetes: 2; Soil microbial count: 2; Fungal count: 2; YIELD: 4 | J5: Rice, wheat, rice-equivalent yield (year-wise); SOC, Kjeldahl N, Olsen P, NH4OAc K (year-wise); BD, porosity, HC; bacteria, fungi, actinomycetes, MBC, DHA, CO2 evolution
A6: 3 | B6: 166 | C6: Das B., Chakraborty D., Singh V.K., Aggarwal P., Singh R., Dwivedi B.S. & Mishra R.P. | D6: 2014 | E6: Soil & Tillage Research | F6: INCLUDED | G6: 53 | H6: 13 | I6: MWD 1: 6; WSA: 3; MACRO: 3; MICRO: 3; macro c: 3; micro c: 3; AWC (weight basis): 6; AWC (volume basis): 6; FC (weight basis): 6; PWP (weight basis): 6; TOC: 3; cPOM-C: 3; YIELD: 2 | J6: TOC; macro/micro aggregates, WSA (derived), MWD (slaked + capillary), macro-C, micro-C, cPOM-C; aggregate FC/PWP/AWC; yields (3-yr means)
A7: 4 | B7: 167 | C7: Naz A., Rebi A., Naz R., Akbar M.U., Aslam A., Kalsom A., Niaz A., Ahmad M.I., Nawaz S., Kausar R., Ali B., Saleem M.H. & Zhou J. | D7: 2023 | E7: Land | F7: EXCLUDED | G7: 0 | H7: 0 | I7: - | J7: NONE (excluded)
A8: 5 | B8: 168 | C8: Dhaliwal J.K., Singh M.J., Sharma S., Gupta N. & Kukal S.S. | D8: 2020 | E8: Soil Research | F8: INCLUDED | G8: 27 | H8: 19 | I8: BD: 2; POROSITY: 2; MWD 1: 2; WSA: 2; MACRO: 2; MICRO: 2; IR: 1; AWC (weight basis): 1; AWC (volume basis): 1; FC (weight basis): 1; PWP (weight basis): 1; SOC(active C pool): 2; stock-SOC: 2; RESP: 1; MBC: 1; DHA: 1; ACP: 1; ALKP: 1; UREASE: 1 | J8: SOC, SOC stock, macro/micro WSA, WSA (derived), MWD, BD, porosity (derived), IR (initial + steady), FC/PWP/AWC, MBC, BSR, DHA, urease, ALP, ACP
A9: 6 | B9: 169 | C9: Singh V.K., Dwivedi B.S., Shukla A.K., Chauhan Y.S. & Yadav R.L. | D9: 2005 | E9: Field Crops Research | F9: EXCLUDED | G9: 0 | H9: 0 | I9: - | J9: NONE (excluded)
A10: 7 | B10: 23 (companion 3) | C10: Jat H.S., Datta A., Choudhary M., Yadav A.K., Choudhary V., Sharma P.C., Gathala M.K., Jat M.L. & McDonald A. | D10: 2019 | E10: Soil & Tillage Research | F10: INCLUDED | G10: 46 | H10: 11 | I10: MWD 1: 4; GMD 1: 4; WSA: 4; MACRO: 4; MICRO: 4; macro c: 4; micro c: 4; SOC(active C pool): 4; TOC: 4; PSOC: 4; YIELD: 6 | J10: WB-C, TOC, macro/micro WSA, WSA, MWD, GMD, macro-C, micro-C, POC (2013, 2015, 2 depths); REY 6 years
A11: 8 | B11: 23 (companion 4) | C11: Jat H.S., Datta A., Choudhary M., Sharma P.C., Yadav A.K., Choudhary V., Gathala M.K., Jat M.L. & McDonald A. | D11: 2019 | E11: Catena (accepted manuscript; version of record S0341816219301936) | F11: INCLUDED | G11: 25 | H11: 13 | I11: VLC(Cfrac1): 2; LC(Cfrac2): 2; LLC(Cfrac3): 2; NLC(Cfrac4): 2; stock-SOC: 2; RESP: 1; MBC: 2; MBN: 2; DHA: 2; ALKP: 2; Actinomycetes: 2; Soil microbial count: 2; Fungal count: 2 | J11: SOC stock; VL/L/LL/NL C (derived g/kg); DHA, ALP, MBC, MBN, BSR, fungi, bacteria, actinomycetes (2 depths)
A12: 9 | B12: 165 (companion) | C12: Meena A.L., Pandey R.N., Kumar D., Dotaniya M.L., Sharma V.K., Singh G., Meena B.P., Kumar A. & Bhanu C. | D12: 2020 | E12: Communications in Soil Science and Plant Analysis | F12: INCLUDED | G12: 136 | H12: 17 | I12: BD: 8; POROSITY: 8; MWD 1: 8; GMD 1: 8; HC: 8; WHC: 8; SOC(active C pool): 8; stock-SOC: 8; PH: 8; EC: 8; N: 8; P: 8; Fe(ppm): 8; Mn: 8; Cu(ppm): 8; Zn(ppm): 8; YIELD: 8 | J12: BD, porosity (derived), WHC, MWD, GMD, Ks, pH, EC, SOC, C stock, available N, P, DTPA Cu/Zn/Mn/Fe, rice grain and straw yield
A13: 10 | B13: 131 (companion) | C13: Zhang Y.-P., Li X., He H.-J., Zhou H., Geng D.-Y. & Zhang Y.-Z. | D13: 2023 | E13: Sustainability | F13: INCLUDED | G13: 50 | H13: 16 | I13: BD: 9; POROSITY: 9; MWD 1: 3; MWDA: 3; MACRO: 3; SOC(active C pool): 3; stock-SOC: 3; c sequestration rate: 1; N: 3; P: 3; K: 3; total N: 3; YIELD: 1; PANICLE-SPIKE DENSITY: 1; GRAINS PER PANICLE: 1; 1000-GRAIN WEIGHT: 1 | J13: BD (2018-20, 3 layers), porosity (derived), water-stable macro-aggregates, MWD (wet, dry), SOC, total N, alkali-N, P, K, SOC stock and sequestration (derived), rice/wheat yield and components

Sheet STUDIES_BY_PARAMETER
A1: STUDIES OF EACH PARAMETER SHEET - auto-generated (2026-10-05); 'NO DATA' = none of the entered studies reports this parameter
A3: No. | B3: Parameter sheet | C3: Unit | D3: Data rows | E3: No. of studies | F3: Studies (serial: rows)
A4: 1 | B4: BD | C4: Mg/m3 | D4: 21 | E4: 4 | F4: 168: 2; 165: 2; 131 (companion): 9; 165 (companion): 8
A5: 2 | B5: PD | C5: Mg/m3 | D5: 0 | E5: 0 | F5: NO DATA
A6: 3 | B6: POROSITY | C6: % v/v | D6: 21 | E6: 4 | F6: 168: 2; 165: 2; 131 (companion): 9; 165 (companion): 8
A7: 4 | B7: macro pore | C7: % v/v | D7: 0 | E7: 0 | F7: NO DATA
A8: 5 | B8: meso pore | C8: % v/v | D8: 0 | E8: 0 | F8: NO DATA
A9: 6 | B9: micro pore | C9: % v/v | D9: 0 | E9: 0 | F9: NO DATA
