Workbook

Sheet README
A1: STAGE-WISE PLOT INDEX - WHITE RUST ASD LEAF SPECTRA, IARI 2025-26
A2: Every plot-date (48 plots x 4 dates = 192) with its growth stage, treatment and the range of ASD files it holds.
A3: Source: asd__data_complete_labelled_110226 / 240226 / 030326 / 130326.xlsx and treatment_detail.xlsx (user files).
A4: Stage, variety and healthy/diseased labels in the ASD files were checked against the layout and stage table: all 192 agree.
A5: 13/03: plots 13, 34, 38, 41, 42 held each of their 15 spectra twice; spectrum counts here exclude the copies.
A7: TO FILL IN (yellow, blue text): 'Plot DI (%)' on each stage sheet. 'DI class' then follows the conventional PDI bands: 0 Healthy, 0.1-5 Very low, 5.1-10 Low, 10.1-25 Moderate, 25.1-50 High, >50 Very high (Shrivastava et al. 2023).
A8: Sheets: All_plot_dates; one sheet per stage (the training set of each stage model); Summary (counts by formula).

Sheet All_plot_dates
A1: Growth stage | B1: Assessment date | C1: DAI | D1: DAS | E1: Plot | F1: Treatment | G1: Sowing | H1: Variety | I1: Replication | J1: Healthy/Diseased | K1: Unique spectra | L1: First spectrum file | M1: Last spectrum file | N1: Note
A2: Vegetative | B2: 11/02/2026 | C2: 6 | D2: 33 | E2: 1 | F2: D4V2 | G2: D4 | H2: V2 | I2: Control | J2: Healthy | K2: 3 | L2: Mustard00001.asd.sco | M2: Mustard00003.asd.sco
A3: Vegetative | B3: 11/02/2026 | C3: 6 | D3: 55 | E3: 2 | F3: D2V2 | G3: D2 | H3: V2 | I3: Control | J3: Healthy | K3: 6 | L3: Mustard00004.asd.sco | M3: Mustard00009.asd.sco
A4: Vegetative | B4: 11/02/2026 | C4: 6 | D4: 64 | E4: 3 | F4: D1V3 | G4: D1 | H4: V3 | I4: Control | J4: Healthy | K4: 9 | L4: Mustard00010.asd.sco | M4: Mustard00018.asd.sco
A5: Vegetative | B5: 11/02/2026 | C5: 6 | D5: 46 | E5: 4 | F5: D3V1 | G5: D3 | H5: V1 | I5: Control | J5: Healthy | K5: 6 | L5: Mustard00019.asd.sco | M5: Mustard00024.asd.sco
A6: Vegetative | B6: 11/02/2026 | C6: 6 | D6: 64 | E6: 5 | F6: D1V2 | G6: D1 | H6: V2 | I6: Control | J6: Healthy | K6: 9 | L6: Mustard00025.asd.sco | M6: Mustard00033.asd.sco
A7: Vegetative | B7: 11/02/2026 | C7: 6 | D7: 33 | E7: 6 | F7: D4V3 | G7: D4 | H7: V3 | I7: Control | J7: Healthy | K7: 3 | L7: Mustard00034.asd.sco | M7: Mustard00036.asd.sco
A8: Vegetative | B8: 11/02/2026 | C8: 6 | D8: 55 | E8: 8 | F8: D2V3 | G8: D2 | H8: V3 | I8: Control | J8: Healthy | K8: 6 | L8: Mustard00046.asd.sco | M8: Mustard00051.asd.sco
A9: Vegetative | B9: 11/02/2026 | C9: 6 | D9: 55 | E9: 9 | F9: D2V1 | G9: D2 | H9: V1 | I9: Control | J9: Healthy | K9: 6 | L9: Mustard00052.asd.sco | M9: Mustard00057.asd.sco
A10: Vegetative | B10: 11/02/2026 | C10: 6 | D10: 46 | E10: 10 | F10: D3V3 | G10: D3 | H10: V3 | I10: Control | J10: Healthy | K10: 6 | L10: Mustard00058.asd.sco | M10: Mustard00063.asd.sco
A11: Vegetative | B11: 11/02/2026 | C11: 6 | D11: 46 | E11: 11 | F11: D3V2 | G11: D3 | H11: V2 | I11: Control | J11: Healthy | K11: 6 | L11: Mustard00064.asd.sco | M11: Mustard00069.asd.sco
A12: Vegetative | B12: 11/02/2026 | C12: 6 | D12: 33 | E12: 12 | F12: D4V1 | G12: D4 | H12: V1 | I12: Control | J12: Healthy | K12: 3 | L12: Mustard00070.asd.sco | M12: Mustard00072.asd.sco
A13: Vegetative | B13: 11/02/2026 | C13: 6 | D13: 64 | E13: 13 | F13: D1V2 | G13: D1 | H13: V2 | I13: R3 | J13: Diseased | K13: 15 | L13: Mustard00073.asd.sco | M13: Mustard00087.asd.sco
... A166: Pod formation | B166: 13/03/2026 | C166: 36 | D166: 76 | E166: 11 | F166: D3V2 | G166: D3 | H166: V2 | I166: Control | J166: Healthy | K166: 9 | L166: Mustard00091.asd.sco | M166: Mustard00099.asd.sco
A167: Pod formation | B167: 13/03/2026 | C167: 36 | D167: 94 | E167: 13 | F167: D1V2 | G167: D1 | H167: V2 | I167: R3 | J167: Diseased | K167: 15 | L167: Mustard00001.asd.sco | M167: Mustard00015.asd.sco | N167: 15 spectra were duplicated in the file; copies removed
A168: Pod formation | B168: 13/03/2026 | C168: 36 | D168: 76 | E168: 15 | F168: D3V1 | G168: D3 | H168: V1 | I168: R3 | J168: Diseased | K168: 15 | L168: Mustard00124.asd.sco | M168: Mustard00138.asd.sco
A169: Pod formation | B169: 13/03/2026 | C169: 36 | D169: 85 | E169: 16 | F169: D2V3 | G169: D2 | H169: V3 | I169: R3 | J169: Diseased | K169: 15 | L169: Mustard00139.asd.sco | M169: Mustard00153.asd.sco
A170: Pod formation | B170: 13/03/2026 | C170: 36 | D170: 76 | E170: 17 | F170: D3V2 | G170: D3 | H170: V2 | I170: R3 | J170: Diseased | K170: 15 | L170: Mustard00154.asd.sco | M170: Mustard00168.asd.sco
A171: Pod formation | B171: 13/03/2026 | C171: 36 | D171: 85 | E171: 19 | F171: D2V2 | G171: D2 | H171: V2 | I171: R3 | J171: Diseased | K171: 15 | L171: Mustard00184.asd.sco | M171: Mustard00198.asd.sco
A172: Pod formation | B172: 13/03/2026 | C172: 36 | D172: 76 | E172: 21 | F172: D3V3 | G172: D3 | H172: V3 | I172: R3 | J172: Diseased | K172: 15 | L172: Mustard00214.asd.sco | M172: Mustard00228.asd.sco
A173: Pod formation | B173: 13/03/2026 | C173: 36 | D173: 85 | E173: 22 | F173: D2V1 | G173: D2 | H173: V1 | I173: R3 | J173: Diseased | K173: 15 | L173: Mustard00229.asd.sco | M173: Mustard00243.asd.sco
A174: Pod formation | B174: 13/03/2026 | C174: 36 | D174: 94 | E174: 23 | F174: D1V3 | G174: D1 | H174: V3 | I174: R3 | J174: Diseased | K174: 15 | L174: Mustard00244.asd.sco | M174: Mustard00258.asd.sco
A175: Pod formation | B175: 13/03/2026 | C175: 36 | D175: 94 | E175: 24 | F175: D1V1 | G175: D1 | H175: V1 | I175: R3 | J175: Diseased | K175: 15 | L175: Mustard00259.asd.sco | M175: Mustard00273.asd.sco
A176: Pod formation | B176: 13/03/2026 | C176: 36 | D176: 94 | E176: 25 | F176: D1V3 | G176: D1 | H176: V3 | I176: R2 | J176: Diseased | K176: 15 | L176: Mustard00274.asd.sco | M176: Mustard00288.asd.sco
A177: Pod formation | B177: 13/03/2026 | C177: 36 | D177: 85 | E177: 27 | F177: D2V3 | G177: D2 | H177: V3 | I177: R2 | J177: Diseased | K177: 15 | L177: Mustard00304.asd.sco | M177: Mustard00318.asd.sco
A178: Pod formation | B178: 13/03/2026 | C178: 36 | D178: 76 | E178: 29 | F178: D3V3 | G178: D3 | H178: V3 | I178: R2 | J178: Diseased | K178: 15 | L178: Mustard00334.asd.sco | M178: Mustard00348.asd.sco
A179: Pod formation | B179: 13/03/2026 | C179: 36 | D179: 94 | E179: 30 | F179: D1V2 | G179: D1 | H179: V2 | I179: R2 | J179: Diseased | K179: 15 | L179: Mustard00349.asd.sco | M179: Mustard00363.asd.sco
... A181: Pod formation | B181: 13/03/2026 | C181: 36 | D181: 76 | E181: 32 | F181: D3V2 | G181: D3 | H181: V2 | I181: R2 | J181: Diseased | K181: 15 | L181: Mustard00379.asd.sco | M181: Mustard00393.asd.sco
A182: Pod formation | B182: 13/03/2026 | C182: 36 | D182: 94 | E182: 34 | F182: D1V1 | G182: D1 | H182: V1 | I182: R2 | J182: Diseased | K182: 15 | L182: Mustard00016.asd.sco | M182: Mustard00030.asd.sco | N182: 15 spectra were duplicated in the file; copies removed
A183: Pod formation | B183: 13/03/2026 | C183: 36 | D183: 85 | E183: 35 | F183: D2V2 | G183: D2 | H183: V2 | I183: R2 | J183: Diseased | K183: 15 | L183: Mustard00409.asd.sco | M183: Mustard00423.asd.sco
A184: Pod formation | B184: 13/03/2026 | C184: 36 | D184: 76 | E184: 36 | F184: D3V1 | G184: D3 | H184: V1 | I184: R2 | J184: Diseased | K184: 15 | L184: Mustard00424.asd.sco | M184: Mustard00438.asd.sco
A185: Pod formation | B185: 13/03/2026 | C185: 36 | D185: 76 | E185: 37 | F185: D3V1 | G185: D3 | H185: V1 | I185: R1 | J185: Diseased | K185: 15 | L185: Mustard00439.asd.sco | M185: Mustard00453.asd.sco
A186: Pod formation | B186: 13/03/2026 | C186: 36 | D186: 94 | E186: 38 | F186: D1V3 | G186: D1 | H186: V3 | I186: R1 | J186: Diseased | K186: 15 | L186: Mustard00031.asd.sco | M186: Mustard00045.asd.sco | N186: 15 spectra were duplicated in the file; copies removed
A187: Pod formation | B187: 13/03/2026 | C187: 36 | D187: 85 | E187: 39 | F187: D2V2 | G187: D2 | H187: V2 | I187: R1 | J187: Diseased | K187: 15 | L187: Mustard00454.asd.sco | M187: Mustard00468.asd.sco
A188: Pod formation | B188: 13/03/2026 | C188: 36 | D188: 85 | E188: 40 | F188: D2V3 | G188: D2 | H188: V3 | I188: R1 | J188: Diseased | K188: 15 | L188: Mustard00469.asd.sco | M188: Mustard00483.asd.sco
A189: Pod formation | B189: 13/03/2026 | C189: 36 | D189: 94 | E189: 41 | F189: D1V1 | G189: D1 | H189: V1 | I189: R1 | J189: Diseased | K189: 15 | L189: Mustard00046.asd.sco | M189: Mustard00060.asd.sco | N189: 15 spectra were duplicated in the file; copies removed
A190: Pod formation | B190: 13/03/2026 | C190: 36 | D190: 94 | E190: 42 | F190: D1V2 | G190: D1 | H190: V2 | I190: R1 | J190: Diseased | K190: 15 | L190: Mustard00061.asd.sco | M190: Mustard00075.asd.sco | N190: 15 spectra were duplicated in the file; copies removed
A191: Pod formation | B191: 13/03/2026 | C191: 36 | D191: 85 | E191: 43 | F191: D2V1 | G191: D2 | H191: V1 | I191: R1 | J191: Diseased | K191: 15 | L191: Mustard00484.asd.sco | M191: Mustard00498.asd.sco
A192: Pod formation | B192: 13/03/2026 | C192: 36 | D192: 76 | E192: 44 | F192: D3V2 | G192: D3 | H192: V2 | I192: R1 | J192: Diseased | K192: 15 | L192: Mustard00499.asd.sco | M192: Mustard00513.asd.sco
A193: Pod formation | B193: 13/03/2026 | C193: 36 | D193: 76 | E193: 48 | F193: D3V3 | G193: D3 | H193: V3 | I193: R1 | J193: Diseased | K193: 15 | L193: Mustard00559.asd.sco | M193: Mustard00573.asd.sco

Sheet Vegetative
A1: Growth stage | B1: Assessment date | C1: DAI | D1: DAS | E1: Plot | F1: Treatment | G1: Sowing | H1: Variety | I1: Replication | J1: Healthy/Diseased | K1: Unique spectra | L1: First spectrum file | M1: Last spectrum file | N1: Note | O1: Plot DI (%) - enter | P1: DI class (auto)
A2: Vegetative | B2: 11/02/2026 | C2: 6 | D2: 33 | E2: 1 | F2: D4V2 | G2: D4 | H2: V2 | I2: Control | J2: Healthy | K2: 3 | L2: Mustard00001.asd.sco | M2: Mustard00003.asd.sco | O2: 0 | P2: =IF(O2="","",IF(O2=0,"Healthy",IF(O2<=5,"Very low",IF(O2<=10,"Low",IF(O2<=25,"Moderate",IF(O2<=50,"High","Very high")))))) -> Healthy
A3: Vegetative | B3: 11/02/2026 | C3: 6 | D3: 55 | E3: 2 | F3: D2V2 | G3: D2 | H3: V2 | I3: Control | J3: Healthy | K3: 6 | L3: Mustard00004.asd.sco | M3: Mustard00009.asd.sco | O3: 0 | P3: =IF(O3="","",IF(O3=0,"Healthy",IF(O3<=5,"Very low",IF(O3<=10,"Low",IF(O3<=25,"Moderate",IF(O3<=50,"High","Very high")))))) -> Healthy
A4: Vegetative | B4: 11/02/2026 | C4: 6 | D4: 64 | E4: 3 | F4: D1V3 | G4: D1 | H4: V3 | I4: Control | J4: Healthy | K4: 9 | L4: Mustard00010.asd.sco | M4: Mustard00018.asd.sco | O4: 0 | P4: =IF(O4="","",IF(O4=0,"Healthy",IF(O4<=5,"Very low",IF(O4<=10,"Low",IF(O4<=25,"Moderate",IF(O4<=50,"High","Very high")))))) -> Healthy
A5: Vegetative | B5: 11/02/2026 | C5: 6 | D5: 46 | E5: 4 | F5: D3V1 | G5: D3 | H5: V1 | I5: Control | J5: Healthy | K5: 6 | L5: Mustard00019.asd.sco | M5: Mustard00024.asd.sco | O5: 0 | P5: =IF(O5="","",IF(O5=0,"Healthy",IF(O5<=5,"Very low",IF(O5<=10,"Low",IF(O5<=25,"Moderate",IF(O5<=50,"High","Very high")))))) -> Healthy
A6: Vegetative | B6: 11/02/2026 | C6: 6 | D6: 64 | E6: 5 | F6: D1V2 | G6: D1 | H6: V2 | I6: Control | J6: Healthy | K6: 9 | L6: Mustard00025.asd.sco | M6: Mustard00033.asd.sco | O6: 0 | P6: =IF(O6="","",IF(O6=0,"Healthy",IF(O6<=5,"Very low",IF(O6<=10,"Low",IF(O6<=25,"Moderate",IF(O6<=50,"High","Very high")))))) -> Healthy
A7: Vegetative | B7: 11/02/2026 | C7: 6 | D7: 33 | E7: 6 | F7: D4V3 | G7: D4 | H7: V3 | I7: Control | J7: Healthy | K7: 3 | L7: Mustard00034.asd.sco | M7: Mustard00036.asd.sco | O7: 0 | P7: =IF(O7="","",IF(O7=0,"Healthy",IF(O7<=5,"Very low",IF(O7<=10,"Low",IF(O7<=25,"Moderate",IF(O7<=50,"High","Very high")))))) -> Healthy
A8: Vegetative | B8: 11/02/2026 | C8: 6 | D8: 55 | E8: 8 | F8: D2V3 | G8: D2 | H8: V3 | I8: Control | J8: Healthy | K8: 6 | L8: Mustard00046.asd.sco | M8: Mustard00051.asd.sco | O8: 0 | P8: =IF(O8="","",IF(O8=0,"Healthy",IF(O8<=5,"Very low",IF(O8<=10,"Low",IF(O8<=25,"Moderate",IF(O8<=50,"High","Very high")))))) -> Healthy
A9: Vegetative | B9: 11/02/2026 | C9: 6 | D9: 55 | E9: 9 | F9: D2V1 | G9: D2 | H9: V1 | I9: Control | J9: Healthy | K9: 6 | L9: Mustard00052.asd.sco | M9: Mustard00057.asd.sco | O9: 0 | P9: =IF(O9="","",IF(O9=0,"Healthy",IF(O9<=5,"Very low",IF(O9<=10,"Low",IF(O9<=25,"Moderate",IF(O9<=50,"High","Very high")))))) -> Healthy
A10: Vegetative | B10: 11/02/2026 | C10: 6 | D10: 46 | E10: 10 | F10: D3V3 | G10: D3 | H10: V3 | I10: Control | J10: Healthy | K10: 6 | L10: Mustard00058.asd.sco | M10: Mustard00063.asd.sco | O10: 0 | P10: =IF(O10="","",IF(O10=0,"Healthy",IF(O10<=5,"Very low",IF(O10<=10,"Low",IF(O10<=25,"Moderate",IF(O10<=50,"High","Very high")))))) -> Healthy
A11: Vegetative | B11: 11/02/2026 | C11: 6 | D11: 46 | E11: 11 | F11: D3V2 | G11: D3 | H11: V2 | I11: Control | J11: Healthy | K11: 6 | L11: Mustard00064.asd.sco | M11: Mustard00069.asd.sco | O11: 0 | P11: =IF(O11="","",IF(O11=0,"Healthy",IF(O11<=5,"Very low",IF(O11<=10,"Low",IF(O11<=25,"Moderate",IF(O11<=50,"High","Very high")))))) -> Healthy
A12: Vegetative | B12: 11/02/2026 | C12: 6 | D12: 33 | E12: 12 | F12: D4V1 | G12: D4 | H12: V1 | I12: Control | J12: Healthy | K12: 3 | L12: Mustard00070.asd.sco | M12: Mustard00072.asd.sco | O12: 0 | P12: =IF(O12="","",IF(O12=0,"Healthy",IF(O12<=5,"Very low",IF(O12<=10,"Low",IF(O12<=25,"Moderate",IF(O12<=50,"High","Very high")))))) -> Healthy
A13: Vegetative | B13: 11/02/2026 | C13: 6 | D13: 64 | E13: 13 | F13: D1V2 | G13: D1 | H13: V2 | I13: R3 | J13: Diseased | K13: 15 | L13: Mustard00073.asd.sco | M13: Mustard00087.asd.sco | P13: =IF(O13="","",IF(O13=0,"Healthy",IF(O13<=5,"Very low",IF(O13<=10,"Low",IF(O13<=25,"Moderate",IF(O13<=50,"High","Very high"))))))
A14: Vegetative | B14: 11/02/2026 | C14: 6 | D14: 33 | E14: 14 | F14: D4V1 | G14: D4 | H14: V1 | I14: R3 | J14: Diseased | K14: 5 | L14: Mustard00088.asd.sco | M14: Mustard00092.asd.sco | P14: =IF(O14="","",IF(O14=0,"Healthy",IF(O14<=5,"Very low",IF(O14<=10,"Low",IF(O14<=25,"Moderate",IF(O14<=50,"High","Very high"))))))
A15: Vegetative | B15: 11/02/2026 | C15: 6 | D15: 46 | E15: 15 | F15: D3V1 | G15: D3 | H15: V1 | I15: R3 | J15: Diseased | K15: 10 | L15: Mustard00093.asd.sco | M15: Mustard00102.asd.sco | P15: =IF(O15="","",IF(O15=0,"Healthy",IF(O15<=5,"Very low",IF(O15<=10,"Low",IF(O15<=25,"Moderate",IF(O15<=50,"High","Very high"))))))
A16: Vegetative | B16: 11/02/2026 | C16: 6 | D16: 55 | E16: 16 | F16: D2V3 | G16: D2 | H16: V3 | I16: R3 | J16: Diseased | K16: 10 | L16: Mustard00103.asd.sco | M16: Mustard00112.asd.sco | P16: =IF(O16="","",IF(O16=0,"Healthy",IF(O16<=5,"Very low",IF(O16<=10,"Low",IF(O16<=25,"Moderate",IF(O16<=50,"High","Very high"))))))
A17: Vegetative | B17: 11/02/2026 | C17: 6 | D17: 46 | E17: 17 | F17: D3V2 | G17: D3 | H17: V2 | I17: R3 | J17: Diseased | K17: 10 | L17: Mustard00113.asd.sco | M17: Mustard00122.asd.sco | P17: =IF(O17="","",IF(O17=0,"Healthy",IF(O17<=5,"Very low",IF(O17<=10,"Low",IF(O17<=25,"Moderate",IF(O17<=50,"High","Very high"))))))
A18: Vegetative | B18: 11/02/2026 | C18: 6 | D18: 33 | E18: 18 | F18: D4V2 | G18: D4 | H18: V2 | I18: R3 | J18: Diseased | K18: 5 | L18: Mustard00123.asd.sco | M18: Mustard00127.asd.sco | P18: =IF(O18="","",IF(O18=0,"Healthy",IF(O18<=5,"Very low",IF(O18<=10,"Low",IF(O18<=25,"Moderate",IF(O18<=50,"High","Very high"))))))
A19: Vegetative | B19: 11/02/2026 | C19: 6 | D19: 55 | E19: 19 | F19: D2V2 | G19: D2 | H19: V2 | I19: R3 | J19: Diseased | K19: 10 | L19: Mustard00128.asd.sco | M19: Mustard00137.asd.sco | P19: =IF(O19="","",IF(O19=0,"Healthy",IF(O19<=5,"Very low",IF(O19<=10,"Low",IF(O19<=25,"Moderate",IF(O19<=50,"High","Very high"))))))
A20: Vegetative | B20: 11/02/2026 | C20: 6 | D20: 33 | E20: 20 | F20: D4V3 | G20: D4 | H20: V3 | I20: R3 | J20: Diseased | K20: 5 | L20: Mustard00138.asd.sco | M20: Mustard00142.asd.sco | P20: =IF(O20="","",IF(O20=0,"Healthy",IF(O20<=5,"Very low",IF(O20<=10,"Low",IF(O20<=25,"Moderate",IF(O20<=50,"High","Very high"))))))
A21: Vegetative | B21: 11/02/2026 | C21: 6 | D21: 46 | E21: 21 | F21: D3V3 | G21: D3 | H21: V3 | I21: R3 | J21: Diseased | K21: 10 | L21: Mustard00143.asd.sco | M21: Mustard00152.asd.sco | P21: =IF(O21="","",IF(O21=0,"Healthy",IF(O21<=5,"Very low",IF(O21<=10,"Low",IF(O21<=25,"Moderate",IF(O21<=50,"High","Very high"))))))
A22: Vegetative | B22: 11/02/2026 | C22: 6 | D22: 55 | E22: 22 | F22: D2V1 | G22: D2 | H22: V1 | I22: R3 | J22: Diseased | K22: 10 | L22: Mustard00153.asd.sco | M22: Mustard00162.asd.sco | P22: =IF(O22="","",IF(O22=0,"Healthy",IF(O22<=5,"Very low",IF(O22<=10,"Low",IF(O22<=25,"Moderate",IF(O22<=50,"High","Very high"))))))
A23: Vegetative | B23: 11/02/2026 | C23: 6 | D23: 64 | E23: 23 | F23: D1V3 | G23: D1 | H23: V3 | I23: R3 | J23: Diseased | K23: 15 | L23: Mustard00163.asd.sco | M23: Mustard00177.asd.sco | P23: =IF(O23="","",IF(O23=0,"Healthy",IF(O23<=5,"Very low",IF(O23<=10,"Low",IF(O23<=25,"Moderate",IF(O23<=50,"High","Very high"))))))
A24: Vegetative | B24: 11/02/2026 | C24: 6 | D24: 64 | E24: 25 | F24: D1V3 | G24: D1 | H24: V3 | I24: R2 | J24: Diseased | K24: 15 | L24: Mustard00193.asd.sco | M24: Mustard00207.asd.sco | P24: =IF(O24="","",IF(O24=0,"Healthy",IF(O24<=5,"Very low",IF(O24<=10,"Low",IF(O24<=25,"Moderate",IF(O24<=50,"High","Very high"))))))
... A45: Vegetative | B45: 11/02/2026 | C45: 6 | D45: 46 | E45: 48 | F45: D3V3 | G45: D3 | H45: V3 | I45: R1 | J45: Diseased | K45: 10 | L45: Mustard00419.asd.sco | M45: Mustard00428.asd.sco | P45: =IF(O45="","",IF(O45=0,"Healthy",IF(O45<=5,"Very low",IF(O45<=10,"Low",IF(O45<=25,"Moderate",IF(O45<=50,"High","Very high"))))))
A46: Vegetative | B46: 24/02/2026 | C46: 19 | D46: 46 | E46: 1 | F46: D4V2 | G46: D4 | H46: V2 | I46: Control | J46: Healthy | K46: 6 | L46: Mustard00001.asd.sco | M46: Mustard00006.asd.sco | O46: 0 | P46: =IF(O46="","",IF(O46=0,"Healthy",IF(O46<=5,"Very low",IF(O46<=10,"Low",IF(O46<=25,"Moderate",IF(O46<=50,"High","Very high")))))) -> Healthy
A47: Vegetative | B47: 24/02/2026 | C47: 19 | D47: 46 | E47: 6 | F47: D4V3 | G47: D4 | H47: V3 | I47: Control | J47: Healthy | K47: 6 | L47: Mustard00040.asd.sco | M47: Mustard00045.asd.sco | O47: 0 | P47: =IF(O47="","",IF(O47=0,"Healthy",IF(O47<=5,"Very low",IF(O47<=10,"Low",IF(O47<=25,"Moderate",IF(O47<=50,"High","Very high")))))) -> Healthy
A48: Vegetative | B48: 24/02/2026 | C48: 19 | D48: 59 | E48: 10 | F48: D3V3 | G48: D3 | H48: V3 | I48: Control | J48: Healthy | K48: 6 | L48: Mustard00073.asd.sco | M48: Mustard00078.asd.sco | O48: 0 | P48: =IF(O48="","",IF(O48=0,"Healthy",IF(O48<=5,"Very low",IF(O48<=10,"Low",IF(O48<=25,"Moderate",IF(O48<=50,"High","Very high")))))) -> Healthy
A49: Vegetative | B49: 24/02/2026 | C49: 19 | D49: 59 | E49: 11 | F49: D3V2 | G49: D3 | H49: V2 | I49: Control | J49: Healthy | K49: 6 | L49: Mustard00079.asd.sco | M49: Mustard00084.asd.sco | O49: 0 | P49: =IF(O49="","",IF(O49=0,"Healthy",IF(O49<=5,"Very low",IF(O49<=10,"Low",IF(O49<=25,"Moderate",IF(O49<=50,"High","Very high")))))) -> Healthy
A50: Vegetative | B50: 24/02/2026 | C50: 19 | D50: 46 | E50: 12 | F50: D4V1 | G50: D4 | H50: V1 | I50: Control | J50: Healthy | K50: 6 | L50: Mustard00085.asd.sco | M50: Mustard00090.asd.sco | O50: 0 | P50: =IF(O50="","",IF(O50=0,"Healthy",IF(O50<=5,"Very low",IF(O50<=10,"Low",IF(O50<=25,"Moderate",IF(O50<=50,"High","Very high")))))) -> Healthy
A51: Vegetative | B51: 24/02/2026 | C51: 19 | D51: 46 | E51: 14 | F51: D4V1 | G51: D4 | H51: V1 | I51: R3 | J51: Diseased | K51: 10 | L51: Mustard00106.asd.sco | M51: Mustard00115.asd.sco | P51: =IF(O51="","",IF(O51=0,"Healthy",IF(O51<=5,"Very low",IF(O51<=10,"Low",IF(O51<=25,"Moderate",IF(O51<=50,"High","Very high"))))))
A52: Vegetative | B52: 24/02/2026 | C52: 19 | D52: 59 | E52: 17 | F52: D3V2 | G52: D3 | H52: V2 | I52: R3 | J52: Diseased | K52: 10 | L52: Mustard00141.asd.sco | M52: Mustard00150.asd.sco | P52: =IF(O52="","",IF(O52=0,"Healthy",IF(O52<=5,"Very low",IF(O52<=10,"Low",IF(O52<=25,"Moderate",IF(O52<=50,"High","Very high"))))))
A53: Vegetative | B53: 24/02/2026 | C53: 19 | D53: 46 | E53: 18 | F53: D4V2 | G53: D4 | H53: V2 | I53: R3 | J53: Diseased | K53: 10 | L53: Mustard00151.asd.sco | M53: Mustard00160.asd.sco | P53: =IF(O53="","",IF(O53=0,"Healthy",IF(O53<=5,"Very low",IF(O53<=10,"Low",IF(O53<=25,"Moderate",IF(O53<=50,"High","Very high"))))))
A54: Vegetative | B54: 24/02/2026 | C54: 19 | D54: 46 | E54: 20 | F54: D4V3 | G54: D4 | H54: V3 | I54: R3 | J54: Diseased | K54: 10 | L54: Mustard00176.asd.sco | M54: Mustard00185.asd.sco | P54: =IF(O54="","",IF(O54=0,"Healthy",IF(O54<=5,"Very low",IF(O54<=10,"Low",IF(O54<=25,"Moderate",IF(O54<=50,"High","Very high"))))))
A55: Vegetative | B55: 24/02/2026 | C55: 19 | D55: 59 | E55: 21 | F55: D3V3 | G55: D3 | H55: V3 | I55: R3 | J55: Diseased | K55: 10 | L55: Mustard00186.asd.sco | M55: Mustard00195.asd.sco | P55: =IF(O55="","",IF(O55=0,"Healthy",IF(O55<=5,"Very low",IF(O55<=10,"Low",IF(O55<=25,"Moderate",IF(O55<=50,"High","Very high"))))))
A56: Vegetative | B56: 24/02/2026 | C56: 19 | D56: 46 | E56: 26 | F56: D4V2 | G56: D4 | H56: V2 | I56: R2 | J56: Diseased | K56: 15 | L56: Mustard00256.asd.sco | M56: Mustard00270.asd.sco | P56: =IF(O56="","",IF(O56=0,"Healthy",IF(O56<=5,"Very low",IF(O56<=10,"Low",IF(O56<=25,"Moderate",IF(O56<=50,"High","Very high"))))))
A57: Vegetative | B57: 24/02/2026 | C57: 19 | D57: 46 | E57: 28 | F57: D4V1 | G57: D4 | H57: V1 | I57: R2 | J57: Diseased | K57: 10 | L57: Mustard00286.asd.sco | M57: Mustard00295.asd.sco | P57: =IF(O57="","",IF(O57=0,"Healthy",IF(O57<=5,"Very low",IF(O57<=10,"Low",IF(O57<=25,"Moderate",IF(O57<=50,"High","Very high"))))))
A58: Vegetative | B58: 24/02/2026 | C58: 19 | D58: 59 | E58: 29 | F58: D3V3 | G58: D3 | H58: V3 | I58: R2 | J58: Diseased | K58: 10 | L58: Mustard00296.asd.sco | M58: Mustard00305.asd.sco | P58: =IF(O58="","",IF(O58=0,"Healthy",IF(O58<=5,"Very low",IF(O58<=10,"Low",IF(O58<=25,"Moderate",IF(O58<=50,"High","Very high"))))))
A59: Vegetative | B59: 24/02/2026 | C59: 19 | D59: 59 | E59: 32 | F59: D3V2 | G59: D3 | H59: V2 | I59: R2 | J59: Diseased | K59: 10 | L59: Mustard00331.asd.sco | M59: Mustard00340.asd.sco | P59: =IF(O59="","",IF(O59=0,"Healthy",IF(O59<=5,"Very low",IF(O59<=10,"Low",IF(O59<=25,"Moderate",IF(O59<=50,"High","Very high"))))))
A60: Vegetative | B60: 24/02/2026 | C60: 19 | D60: 46 | E60: 33 | F60: D4V3 | G60: D4 | H60: V3 | I60: R2 | J60: Diseased | K60: 10 | L60: Mustard00341.asd.sco | M60: Mustard00350.asd.sco | P60: =IF(O60="","",IF(O60=0,"Healthy",IF(O60<=5,"Very low",IF(O60<=10,"Low",IF(O60<=25,"Moderate",IF(O60<=50,"High","Very high"))))))
...

Sheet Flowering
A1: Growth stage | B1: Assessment date | C1: DAI | D1: DAS | E1: Plot | F1: Treatment | G1: Sowing | H1: Variety | I1: Replication | J1: Healthy/Diseased | K1: Unique spectra | L1: First spectrum file | M1: Last spectrum file | N1: Note | O1: Plot DI (%) - enter | P1: DI class (auto)
A2: Flowering | B2: 11/02/2026 | C2: 6 | D2: 64 | E2: 7 | F2: D1V1 | G2: D1 | H2: V1 | I2: Control | J2: Healthy | K2: 9 | L2: Mustard00037.asd.sco | M2: Mustard00045.asd.sco | O2: 0 | P2: =IF(O2="","",IF(O2=0,"Healthy",IF(O2<=5,"Very low",IF(O2<=10,"Low",IF(O2<=25,"Moderate",IF(O2<=50,"High","Very high")))))) -> Healthy
A3: Flowering | B3: 11/02/2026 | C3: 6 | D3: 64 | E3: 24 | F3: D1V1 | G3: D1 | H3: V1 | I3: R3 | J3: Diseased | K3: 15 | L3: Mustard00178.asd.sco | M3: Mustard00192.asd.sco | P3: =IF(O3="","",IF(O3=0,"Healthy",IF(O3<=5,"Very low",IF(O3<=10,"Low",IF(O3<=25,"Moderate",IF(O3<=50,"High","Very high"))))))
A4: Flowering | B4: 11/02/2026 | C4: 6 | D4: 64 | E4: 34 | F4: D1V1 | G4: D1 | H4: V1 | I4: R2 | J4: Diseased | K4: 15 | L4: Mustard00274.asd.sco | M4: Mustard00288.asd.sco | P4: =IF(O4="","",IF(O4=0,"Healthy",IF(O4<=5,"Very low",IF(O4<=10,"Low",IF(O4<=25,"Moderate",IF(O4<=50,"High","Very high"))))))
A5: Flowering | B5: 11/02/2026 | C5: 6 | D5: 64 | E5: 41 | F5: D1V1 | G5: D1 | H5: V1 | I5: R1 | J5: Diseased | K5: 15 | L5: Mustard00354.asd.sco | M5: Mustard00368.asd.sco | P5: =IF(O5="","",IF(O5=0,"Healthy",IF(O5<=5,"Very low",IF(O5<=10,"Low",IF(O5<=25,"Moderate",IF(O5<=50,"High","Very high"))))))
A6: Flowering | B6: 24/02/2026 | C6: 19 | D6: 68 | E6: 2 | F6: D2V2 | G6: D2 | H6: V2 | I6: Control | J6: Healthy | K6: 9 | L6: Mustard00007.asd.sco | M6: Mustard00015.asd.sco | O6: 0 | P6: =IF(O6="","",IF(O6=0,"Healthy",IF(O6<=5,"Very low",IF(O6<=10,"Low",IF(O6<=25,"Moderate",IF(O6<=50,"High","Very high")))))) -> Healthy
A7: Flowering | B7: 24/02/2026 | C7: 19 | D7: 77 | E7: 3 | F7: D1V3 | G7: D1 | H7: V3 | I7: Control | J7: Healthy | K7: 9 | L7: Mustard00016.asd.sco | M7: Mustard00024.asd.sco | O7: 0 | P7: =IF(O7="","",IF(O7=0,"Healthy",IF(O7<=5,"Very low",IF(O7<=10,"Low",IF(O7<=25,"Moderate",IF(O7<=50,"High","Very high")))))) -> Healthy
A8: Flowering | B8: 24/02/2026 | C8: 19 | D8: 59 | E8: 4 | F8: D3V1 | G8: D3 | H8: V1 | I8: Control | J8: Healthy | K8: 6 | L8: Mustard00025.asd.sco | M8: Mustard00030.asd.sco | O8: 0 | P8: =IF(O8="","",IF(O8=0,"Healthy",IF(O8<=5,"Very low",IF(O8<=10,"Low",IF(O8<=25,"Moderate",IF(O8<=50,"High","Very high")))))) -> Healthy
A9: Flowering | B9: 24/02/2026 | C9: 19 | D9: 77 | E9: 5 | F9: D1V2 | G9: D1 | H9: V2 | I9: Control | J9: Healthy | K9: 9 | L9: Mustard00031.asd.sco | M9: Mustard00039.asd.sco | O9: 0 | P9: =IF(O9="","",IF(O9=0,"Healthy",IF(O9<=5,"Very low",IF(O9<=10,"Low",IF(O9<=25,"Moderate",IF(O9<=50,"High","Very high")))))) -> Healthy
A10: Flowering | B10: 24/02/2026 | C10: 19 | D10: 77 | E10: 7 | F10: D1V1 | G10: D1 | H10: V1 | I10: Control | J10: Healthy | K10: 9 | L10: Mustard00046.asd.sco | M10: Mustard00054.asd.sco | O10: 0 | P10: =IF(O10="","",IF(O10=0,"Healthy",IF(O10<=5,"Very low",IF(O10<=10,"Low",IF(O10<=25,"Moderate",IF(O10<=50,"High","Very high")))))) -> Healthy
A11: Flowering | B11: 24/02/2026 | C11: 19 | D11: 68 | E11: 8 | F11: D2V3 | G11: D2 | H11: V3 | I11: Control | J11: Healthy | K11: 9 | L11: Mustard00055.asd.sco | M11: Mustard00063.asd.sco | O11: 0 | P11: =IF(O11="","",IF(O11=0,"Healthy",IF(O11<=5,"Very low",IF(O11<=10,"Low",IF(O11<=25,"Moderate",IF(O11<=50,"High","Very high")))))) -> Healthy
A12: Flowering | B12: 24/02/2026 | C12: 19 | D12: 68 | E12: 9 | F12: D2V1 | G12: D2 | H12: V1 | I12: Control | J12: Healthy | K12: 9 | L12: Mustard00064.asd.sco | M12: Mustard00072.asd.sco | O12: 0 | P12: =IF(O12="","",IF(O12=0,"Healthy",IF(O12<=5,"Very low",IF(O12<=10,"Low",IF(O12<=25,"Moderate",IF(O12<=50,"High","Very high")))))) -> Healthy
A13: Flowering | B13: 24/02/2026 | C13: 19 | D13: 77 | E13: 13 | F13: D1V2 | G13: D1 | H13: V2 | I13: R3 | J13: Diseased | K13: 15 | L13: Mustard00091.asd.sco | M13: Mustard00105.asd.sco | P13: =IF(O13="","",IF(O13=0,"Healthy",IF(O13<=5,"Very low",IF(O13<=10,"Low",IF(O13<=25,"Moderate",IF(O13<=50,"High","Very high"))))))
A14: Flowering | B14: 24/02/2026 | C14: 19 | D14: 59 | E14: 15 | F14: D3V1 | G14: D3 | H14: V1 | I14: R3 | J14: Diseased | K14: 10 | L14: Mustard00116.asd.sco | M14: Mustard00125.asd.sco | P14: =IF(O14="","",IF(O14=0,"Healthy",IF(O14<=5,"Very low",IF(O14<=10,"Low",IF(O14<=25,"Moderate",IF(O14<=50,"High","Very high"))))))
A15: Flowering | B15: 24/02/2026 | C15: 19 | D15: 68 | E15: 16 | F15: D2V3 | G15: D2 | H15: V3 | I15: R3 | J15: Diseased | K15: 15 | L15: Mustard00126.asd.sco | M15: Mustard00140.asd.sco | P15: =IF(O15="","",IF(O15=0,"Healthy",IF(O15<=5,"Very low",IF(O15<=10,"Low",IF(O15<=25,"Moderate",IF(O15<=50,"High","Very high"))))))
A16: Flowering | B16: 24/02/2026 | C16: 19 | D16: 68 | E16: 19 | F16: D2V2 | G16: D2 | H16: V2 | I16: R3 | J16: Diseased | K16: 15 | L16: Mustard00161.asd.sco | M16: Mustard00175.asd.sco | P16: =IF(O16="","",IF(O16=0,"Healthy",IF(O16<=5,"Very low",IF(O16<=10,"Low",IF(O16<=25,"Moderate",IF(O16<=50,"High","Very high"))))))
A17: Flowering | B17: 24/02/2026 | C17: 19 | D17: 68 | E17: 22 | F17: D2V1 | G17: D2 | H17: V1 | I17: R3 | J17: Diseased | K17: 15 | L17: Mustard00196.asd.sco | M17: Mustard00210.asd.sco | P17: =IF(O17="","",IF(O17=0,"Healthy",IF(O17<=5,"Very low",IF(O17<=10,"Low",IF(O17<=25,"Moderate",IF(O17<=50,"High","Very high"))))))
A18: Flowering | B18: 24/02/2026 | C18: 19 | D18: 77 | E18: 23 | F18: D1V3 | G18: D1 | H18: V3 | I18: R3 | J18: Diseased | K18: 15 | L18: Mustard00211.asd.sco | M18: Mustard00225.asd.sco | P18: =IF(O18="","",IF(O18=0,"Healthy",IF(O18<=5,"Very low",IF(O18<=10,"Low",IF(O18<=25,"Moderate",IF(O18<=50,"High","Very high"))))))
A19: Flowering | B19: 24/02/2026 | C19: 19 | D19: 77 | E19: 24 | F19: D1V1 | G19: D1 | H19: V1 | I19: R3 | J19: Diseased | K19: 15 | L19: Mustard00226.asd.sco | M19: Mustard00240.asd.sco | P19: =IF(O19="","",IF(O19=0,"Healthy",IF(O19<=5,"Very low",IF(O19<=10,"Low",IF(O19<=25,"Moderate",IF(O19<=50,"High","Very high"))))))
A20: Flowering | B20: 24/02/2026 | C20: 19 | D20: 77 | E20: 25 | F20: D1V3 | G20: D1 | H20: V3 | I20: R2 | J20: Diseased | K20: 15 | L20: Mustard00241.asd.sco | M20: Mustard00255.asd.sco | P20: =IF(O20="","",IF(O20=0,"Healthy",IF(O20<=5,"Very low",IF(O20<=10,"Low",IF(O20<=25,"Moderate",IF(O20<=50,"High","Very high"))))))
A21: Flowering | B21: 24/02/2026 | C21: 19 | D21: 68 | E21: 27 | F21: D2V3 | G21: D2 | H21: V3 | I21: R2 | J21: Diseased | K21: 15 | L21: Mustard00271.asd.sco | M21: Mustard00285.asd.sco | P21: =IF(O21="","",IF(O21=0,"Healthy",IF(O21<=5,"Very low",IF(O21<=10,"Low",IF(O21<=25,"Moderate",IF(O21<=50,"High","Very high"))))))
A22: Flowering | B22: 24/02/2026 | C22: 19 | D22: 77 | E22: 30 | F22: D1V2 | G22: D1 | H22: V2 | I22: R2 | J22: Diseased | K22: 15 | L22: Mustard00306.asd.sco | M22: Mustard00320.asd.sco | P22: =IF(O22="","",IF(O22=0,"Healthy",IF(O22<=5,"Very low",IF(O22<=10,"Low",IF(O22<=25,"Moderate",IF(O22<=50,"High","Very high"))))))
A23: Flowering | B23: 24/02/2026 | C23: 19 | D23: 68 | E23: 31 | F23: D2V1 | G23: D2 | H23: V1 | I23: R2 | J23: Diseased | K23: 10 | L23: Mustard00321.asd.sco | M23: Mustard00330.asd.sco | P23: =IF(O23="","",IF(O23=0,"Healthy",IF(O23<=5,"Very low",IF(O23<=10,"Low",IF(O23<=25,"Moderate",IF(O23<=50,"High","Very high"))))))
A24: Flowering | B24: 24/02/2026 | C24: 19 | D24: 77 | E24: 34 | F24: D1V1 | G24: D1 | H24: V1 | I24: R2 | J24: Diseased | K24: 15 | L24: Mustard00351.asd.sco | M24: Mustard00365.asd.sco | P24: =IF(O24="","",IF(O24=0,"Healthy",IF(O24<=5,"Very low",IF(O24<=10,"Low",IF(O24<=25,"Moderate",IF(O24<=50,"High","Very high"))))))
... A33: Flowering | B33: 24/02/2026 | C33: 19 | D33: 68 | E33: 43 | F33: D2V1 | G33: D2 | H33: V1 | I33: R1 | J33: Diseased | K33: 10 | L33: Mustard00476.asd.sco | M33: Mustard00485.asd.sco | P33: =IF(O33="","",IF(O33=0,"Healthy",IF(O33<=5,"Very low",IF(O33<=10,"Low",IF(O33<=25,"Moderate",IF(O33<=50,"High","Very high"))))))
A34: Flowering | B34: 03/03/2026 | C34: 26 | D34: 53 | E34: 1 | F34: D4V2 | G34: D4 | H34: V2 | I34: Control | J34: Healthy | K34: 9 | L34: Mustard00001.asd.sco | M34: Mustard00009.asd.sco | O34: 0 | P34: =IF(O34="","",IF(O34=0,"Healthy",IF(O34<=5,"Very low",IF(O34<=10,"Low",IF(O34<=25,"Moderate",IF(O34<=50,"High","Very high")))))) -> Healthy
A35: Flowering | B35: 03/03/2026 | C35: 26 | D35: 75 | E35: 2 | F35: D2V2 | G35: D2 | H35: V2 | I35: Control | J35: Healthy | K35: 9 | L35: Mustard00010.asd.sco | M35: Mustard00018.asd.sco | O35: 0 | P35: =IF(O35="","",IF(O35=0,"Healthy",IF(O35<=5,"Very low",IF(O35<=10,"Low",IF(O35<=25,"Moderate",IF(O35<=50,"High","Very high")))))) -> Healthy
A36: Flowering | B36: 03/03/2026 | C36: 26 | D36: 84 | E36: 3 | F36: D1V3 | G36: D1 | H36: V3 | I36: Control | J36: Healthy | K36: 9 | L36: Mustard00019.asd.sco | M36: Mustard00027.asd.sco | O36: 0 | P36: =IF(O36="","",IF(O36=0,"Healthy",IF(O36<=5,"Very low",IF(O36<=10,"Low",IF(O36<=25,"Moderate",IF(O36<=50,"High","Very high")))))) -> Healthy
A37: Flowering | B37: 03/03/2026 | C37: 26 | D37: 66 | E37: 4 | F37: D3V1 | G37: D3 | H37: V1 | I37: Control | J37: Healthy | K37: 9 | L37: Mustard00028.asd.sco | M37: Mustard00036.asd.sco | O37: 0 | P37: =IF(O37="","",IF(O37=0,"Healthy",IF(O37<=5,"Very low",IF(O37<=10,"Low",IF(O37<=25,"Moderate",IF(O37<=50,"High","Very high")))))) -> Healthy
A38: Flowering | B38: 03/03/2026 | C38: 26 | D38: 84 | E38: 5 | F38: D1V2 | G38: D1 | H38: V2 | I38: Control | J38: Healthy | K38: 9 | L38: Mustard00037.asd.sco | M38: Mustard00045.asd.sco | O38: 0 | P38: =IF(O38="","",IF(O38=0,"Healthy",IF(O38<=5,"Very low",IF(O38<=10,"Low",IF(O38<=25,"Moderate",IF(O38<=50,"High","Very high")))))) -> Healthy
A39: Flowering | B39: 03/03/2026 | C39: 26 | D39: 53 | E39: 6 | F39: D4V3 | G39: D4 | H39: V3 | I39: Control | J39: Healthy | K39: 9 | L39: Mustard00046.asd.sco | M39: Mustard00054.asd.sco | O39: 0 | P39: =IF(O39="","",IF(O39=0,"Healthy",IF(O39<=5,"Very low",IF(O39<=10,"Low",IF(O39<=25,"Moderate",IF(O39<=50,"High","Very high")))))) -> Healthy
A40: Flowering | B40: 03/03/2026 | C40: 26 | D40: 75 | E40: 8 | F40: D2V3 | G40: D2 | H40: V3 | I40: Control | J40: Healthy | K40: 9 | L40: Mustard00064.asd.sco | M40: Mustard00072.asd.sco | O40: 0 | P40: =IF(O40="","",IF(O40=0,"Healthy",IF(O40<=5,"Very low",IF(O40<=10,"Low",IF(O40<=25,"Moderate",IF(O40<=50,"High","Very high")))))) -> Healthy
A41: Flowering | B41: 03/03/2026 | C41: 26 | D41: 75 | E41: 9 | F41: D2V1 | G41: D2 | H41: V1 | I41: Control | J41: Healthy | K41: 9 | L41: Mustard00073.asd.sco | M41: Mustard00081.asd.sco | O41: 0 | P41: =IF(O41="","",IF(O41=0,"Healthy",IF(O41<=5,"Very low",IF(O41<=10,"Low",IF(O41<=25,"Moderate",IF(O41<=50,"High","Very high")))))) -> Healthy
A42: Flowering | B42: 03/03/2026 | C42: 26 | D42: 66 | E42: 10 | F42: D3V3 | G42: D3 | H42: V3 | I42: Control | J42: Healthy | K42: 9 | L42: Mustard00082.asd.sco | M42: Mustard00090.asd.sco | O42: 0 | P42: =IF(O42="","",IF(O42=0,"Healthy",IF(O42<=5,"Very low",IF(O42<=10,"Low",IF(O42<=25,"Moderate",IF(O42<=50,"High","Very high")))))) -> Healthy
A43: Flowering | B43: 03/03/2026 | C43: 26 | D43: 66 | E43: 11 | F43: D3V2 | G43: D3 | H43: V2 | I43: Control | J43: Healthy | K43: 9 | L43: Mustard00091.asd.sco | M43: Mustard00099.asd.sco | O43: 0 | P43: =IF(O43="","",IF(O43=0,"Healthy",IF(O43<=5,"Very low",IF(O43<=10,"Low",IF(O43<=25,"Moderate",IF(O43<=50,"High","Very high")))))) -> Healthy
A44: Flowering | B44: 03/03/2026 | C44: 26 | D44: 53 | E44: 12 | F44: D4V1 | G44: D4 | H44: V1 | I44: Control | J44: Healthy | K44: 9 | L44: Mustard00100.asd.sco | M44: Mustard00108.asd.sco | O44: 0 | P44: =IF(O44="","",IF(O44=0,"Healthy",IF(O44<=5,"Very low",IF(O44<=10,"Low",IF(O44<=25,"Moderate",IF(O44<=50,"High","Very high")))))) -> Healthy
A45: Flowering | B45: 03/03/2026 | C45: 26 | D45: 84 | E45: 13 | F45: D1V2 | G45: D1 | H45: V2 | I45: R3 | J45: Diseased | K45: 15 | L45: Mustard00109.asd.sco | M45: Mustard00123.asd.sco | P45: =IF(O45="","",IF(O45=0,"Healthy",IF(O45<=5,"Very low",IF(O45<=10,"Low",IF(O45<=25,"Moderate",IF(O45<=50,"High","Very high"))))))
A46: Flowering | B46: 03/03/2026 | C46: 26 | D46: 53 | E46: 14 | F46: D4V1 | G46: D4 | H46: V1 | I46: R3 | J46: Diseased | K46: 15 | L46: Mustard00124.asd.sco | M46: Mustard00138.asd.sco | P46: =IF(O46="","",IF(O46=0,"Healthy",IF(O46<=5,"Very low",IF(O46<=10,"Low",IF(O46<=25,"Moderate",IF(O46<=50,"High","Very high"))))))
A47: Flowering | B47: 03/03/2026 | C47: 26 | D47: 66 | E47: 15 | F47: D3V1 | G47: D3 | H47: V1 | I47: R3 | J47: Diseased | K47: 15 | L47: Mustard00139.asd.sco | M47: Mustard00153.asd.sco | P47: =IF(O47="","",IF(O47=0,"Healthy",IF(O47<=5,"Very low",IF(O47<=10,"Low",IF(O47<=25,"Moderate",IF(O47<=50,"High","Very high"))))))
A48: Flowering | B48: 03/03/2026 | C48: 26 | D48: 75 | E48: 16 | F48: D2V3 | G48: D2 | H48: V3 | I48: R3 | J48: Diseased | K48: 15 | L48: Mustard00154.asd.sco | M48: Mustard00168.asd.sco | P48: =IF(O48="","",IF(O48=0,"Healthy",IF(O48<=5,"Very low",IF(O48<=10,"Low",IF(O48<=25,"Moderate",IF(O48<=50,"High","Very high"))))))
...

Sheet Pod_formation
A1: Growth stage | B1: Assessment date | C1: DAI | D1: DAS | E1: Plot | F1: Treatment | G1: Sowing | H1: Variety | I1: Replication | J1: Healthy/Diseased | K1: Unique spectra | L1: First spectrum file | M1: Last spectrum file | N1: Note | O1: Plot DI (%) - enter | P1: DI class (auto)
A2: Pod formation | B2: 03/03/2026 | C2: 26 | D2: 84 | E2: 7 | F2: D1V1 | G2: D1 | H2: V1 | I2: Control | J2: Healthy | K2: 9 | L2: Mustard00055.asd.sco | M2: Mustard00063.asd.sco | O2: 0 | P2: =IF(O2="","",IF(O2=0,"Healthy",IF(O2<=5,"Very low",IF(O2<=10,"Low",IF(O2<=25,"Moderate",IF(O2<=50,"High","Very high")))))) -> Healthy
A3: Pod formation | B3: 03/03/2026 | C3: 26 | D3: 84 | E3: 24 | F3: D1V1 | G3: D1 | H3: V1 | I3: R3 | J3: Diseased | K3: 15 | L3: Mustard00274.asd.sco | M3: Mustard00288.asd.sco | P3: =IF(O3="","",IF(O3=0,"Healthy",IF(O3<=5,"Very low",IF(O3<=10,"Low",IF(O3<=25,"Moderate",IF(O3<=50,"High","Very high"))))))
A4: Pod formation | B4: 03/03/2026 | C4: 26 | D4: 84 | E4: 34 | F4: D1V1 | G4: D1 | H4: V1 | I4: R2 | J4: Diseased | K4: 15 | L4: Mustard00424.asd.sco | M4: Mustard00438.asd.sco | P4: =IF(O4="","",IF(O4=0,"Healthy",IF(O4<=5,"Very low",IF(O4<=10,"Low",IF(O4<=25,"Moderate",IF(O4<=50,"High","Very high"))))))
A5: Pod formation | B5: 03/03/2026 | C5: 26 | D5: 84 | E5: 41 | F5: D1V1 | G5: D1 | H5: V1 | I5: R1 | J5: Diseased | K5: 15 | L5: Mustard00529.asd.sco | M5: Mustard00543.asd.sco | P5: =IF(O5="","",IF(O5=0,"Healthy",IF(O5<=5,"Very low",IF(O5<=10,"Low",IF(O5<=25,"Moderate",IF(O5<=50,"High","Very high"))))))
A6: Pod formation | B6: 13/03/2026 | C6: 36 | D6: 85 | E6: 2 | F6: D2V2 | G6: D2 | H6: V2 | I6: Control | J6: Healthy | K6: 9 | L6: Mustard00010.asd.sco | M6: Mustard00018.asd.sco | O6: 0 | P6: =IF(O6="","",IF(O6=0,"Healthy",IF(O6<=5,"Very low",IF(O6<=10,"Low",IF(O6<=25,"Moderate",IF(O6<=50,"High","Very high")))))) -> Healthy
A7: Pod formation | B7: 13/03/2026 | C7: 36 | D7: 94 | E7: 3 | F7: D1V3 | G7: D1 | H7: V3 | I7: Control | J7: Healthy | K7: 9 | L7: Mustard00019.asd.sco | M7: Mustard00027.asd.sco | O7: 0 | P7: =IF(O7="","",IF(O7=0,"Healthy",IF(O7<=5,"Very low",IF(O7<=10,"Low",IF(O7<=25,"Moderate",IF(O7<=50,"High","Very high")))))) -> Healthy
A8: Pod formation | B8: 13/03/2026 | C8: 36 | D8: 76 | E8: 4 | F8: D3V1 | G8: D3 | H8: V1 | I8: Control | J8: Healthy | K8: 9 | L8: Mustard00028.asd.sco | M8: Mustard00036.asd.sco | O8: 0 | P8: =IF(O8="","",IF(O8=0,"Healthy",IF(O8<=5,"Very low",IF(O8<=10,"Low",IF(O8<=25,"Moderate",IF(O8<=50,"High","Very high")))))) -> Healthy
A9: Pod formation | B9: 13/03/2026 | C9: 36 | D9: 94 | E9: 5 | F9: D1V2 | G9: D1 | H9: V2 | I9: Control | J9: Healthy | K9: 9 | L9: Mustard00037.asd.sco | M9: Mustard00045.asd.sco | O9: 0 | P9: =IF(O9="","",IF(O9=0,"Healthy",IF(O9<=5,"Very low",IF(O9<=10,"Low",IF(O9<=25,"Moderate",IF(O9<=50,"High","Very high")))))) -> Healthy
A10: Pod formation | B10: 13/03/2026 | C10: 36 | D10: 94 | E10: 7 | F10: D1V1 | G10: D1 | H10: V1 | I10: Control | J10: Healthy | K10: 9 | L10: Mustard00055.asd.sco | M10: Mustard00063.asd.sco | O10: 0 | P10: =IF(O10="","",IF(O10=0,"Healthy",IF(O10<=5,"Very low",IF(O10<=10,"Low",IF(O10<=25,"Moderate",IF(O10<=50,"High","Very high")))))) -> Healthy
A11: Pod formation | B11: 13/03/2026 | C11: 36 | D11: 85 | E11: 8 | F11: D2V3 | G11: D2 | H11: V3 | I11: Control | J11: Healthy | K11: 9 | L11: Mustard00064.asd.sco | M11: Mustard00072.asd.sco | O11: 0 | P11: =IF(O11="","",IF(O11=0,"Healthy",IF(O11<=5,"Very low",IF(O11<=10,"Low",IF(O11<=25,"Moderate",IF(O11<=50,"High","Very high")))))) -> Healthy
A12: Pod formation | B12: 13/03/2026 | C12: 36 | D12: 85 | E12: 9 | F12: D2V1 | G12: D2 | H12: V1 | I12: Control | J12: Healthy | K12: 9 | L12: Mustard00073.asd.sco | M12: Mustard00081.asd.sco | O12: 0 | P12: =IF(O12="","",IF(O12=0,"Healthy",IF(O12<=5,"Very low",IF(O12<=10,"Low",IF(O12<=25,"Moderate",IF(O12<=50,"High","Very high")))))) -> Healthy
A13: Pod formation | B13: 13/03/2026 | C13: 36 | D13: 76 | E13: 10 | F13: D3V3 | G13: D3 | H13: V3 | I13: Control | J13: Healthy | K13: 9 | L13: Mustard00082.asd.sco | M13: Mustard00090.asd.sco | O13: 0 | P13: =IF(O13="","",IF(O13=0,"Healthy",IF(O13<=5,"Very low",IF(O13<=10,"Low",IF(O13<=25,"Moderate",IF(O13<=50,"High","Very high")))))) -> Healthy
A14: Pod formation | B14: 13/03/2026 | C14: 36 | D14: 76 | E14: 11 | F14: D3V2 | G14: D3 | H14: V2 | I14: Control | J14: Healthy | K14: 9 | L14: Mustard00091.asd.sco | M14: Mustard00099.asd.sco | O14: 0 | P14: =IF(O14="","",IF(O14=0,"Healthy",IF(O14<=5,"Very low",IF(O14<=10,"Low",IF(O14<=25,"Moderate",IF(O14<=50,"High","Very high")))))) -> Healthy
A15: Pod formation | B15: 13/03/2026 | C15: 36 | D15: 94 | E15: 13 | F15: D1V2 | G15: D1 | H15: V2 | I15: R3 | J15: Diseased | K15: 15 | L15: Mustard00001.asd.sco | M15: Mustard00015.asd.sco | N15: 15 spectra were duplicated in the file; copies removed | P15: =IF(O15="","",IF(O15=0,"Healthy",IF(O15<=5,"Very low",IF(O15<=10,"Low",IF(O15<=25,"Moderate",IF(O15<=50,"High","Very high"))))))
A16: Pod formation | B16: 13/03/2026 | C16: 36 | D16: 76 | E16: 15 | F16: D3V1 | G16: D3 | H16: V1 | I16: R3 | J16: Diseased | K16: 15 | L16: Mustard00124.asd.sco | M16: Mustard00138.asd.sco | P16: =IF(O16="","",IF(O16=0,"Healthy",IF(O16<=5,"Very low",IF(O16<=10,"Low",IF(O16<=25,"Moderate",IF(O16<=50,"High","Very high"))))))
A17: Pod formation | B17: 13/03/2026 | C17: 36 | D17: 85 | E17: 16 | F17: D2V3 | G17: D2 | H17: V3 | I17: R3 | J17: Diseased | K17: 15 | L17: Mustard00139.asd.sco | M17: Mustard00153.asd.sco | P17: =IF(O17="","",IF(O17=0,"Healthy",IF(O17<=5,"Very low",IF(O17<=10,"Low",IF(O17<=25,"Moderate",IF(O17<=50,"High","Very high"))))))
A18: Pod formation | B18: 13/03/2026 | C18: 36 | D18: 76 | E18: 17 | F18: D3V2 | G18: D3 | H18: V2 | I18: R3 | J18: Diseased | K18: 15 | L18: Mustard00154.asd.sco | M18: Mustard00168.asd.sco | P18: =IF(O18="","",IF(O18=0,"Healthy",IF(O18<=5,"Very low",IF(O18<=10,"Low",IF(O18<=25,"Moderate",IF(O18<=50,"High","Very high"))))))
A19: Pod formation | B19: 13/03/2026 | C19: 36 | D19: 85 | E19: 19 | F19: D2V2 | G19: D2 | H19: V2 | I19: R3 | J19: Diseased | K19: 15 | L19: Mustard00184.asd.sco | M19: Mustard00198.asd.sco | P19: =IF(O19="","",IF(O19=0,"Healthy",IF(O19<=5,"Very low",IF(O19<=10,"Low",IF(O19<=25,"Moderate",IF(O19<=50,"High","Very high"))))))
A20: Pod formation | B20: 13/03/2026 | C20: 36 | D20: 76 | E20: 21 | F20: D3V3 | G20: D3 | H20: V3 | I20: R3 | J20: Diseased | K20: 15 | L20: Mustard00214.asd.sco | M20: Mustard00228.asd.sco | P20: =IF(O20="","",IF(O20=0,"Healthy",IF(O20<=5,"Very low",IF(O20<=10,"Low",IF(O20<=25,"Moderate",IF(O20<=50,"High","Very high"))))))
A21: Pod formation | B21: 13/03/2026 | C21: 36 | D21: 85 | E21: 22 | F21: D2V1 | G21: D2 | H21: V1 | I21: R3 | J21: Diseased | K21: 15 | L21: Mustard00229.asd.sco | M21: Mustard00243.asd.sco | P21: =IF(O21="","",IF(O21=0,"Healthy",IF(O21<=5,"Very low",IF(O21<=10,"Low",IF(O21<=25,"Moderate",IF(O21<=50,"High","Very high"))))))
A22: Pod formation | B22: 13/03/2026 | C22: 36 | D22: 94 | E22: 23 | F22: D1V3 | G22: D1 | H22: V3 | I22: R3 | J22: Diseased | K22: 15 | L22: Mustard00244.asd.sco | M22: Mustard00258.asd.sco | P22: =IF(O22="","",IF(O22=0,"Healthy",IF(O22<=5,"Very low",IF(O22<=10,"Low",IF(O22<=25,"Moderate",IF(O22<=50,"High","Very high"))))))
A23: Pod formation | B23: 13/03/2026 | C23: 36 | D23: 94 | E23: 24 | F23: D1V1 | G23: D1 | H23: V1 | I23: R3 | J23: Diseased | K23: 15 | L23: Mustard00259.asd.sco | M23: Mustard00273.asd.sco | P23: =IF(O23="","",IF(O23=0,"Healthy",IF(O23<=5,"Very low",IF(O23<=10,"Low",IF(O23<=25,"Moderate",IF(O23<=50,"High","Very high"))))))
A24: Pod formation | B24: 13/03/2026 | C24: 36 | D24: 94 | E24: 25 | F24: D1V3 | G24: D1 | H24: V3 | I24: R2 | J24: Diseased | K24: 15 | L24: Mustard00274.asd.sco | M24: Mustard00288.asd.sco | P24: =IF(O24="","",IF(O24=0,"Healthy",IF(O24<=5,"Very low",IF(O24<=10,"Low",IF(O24<=25,"Moderate",IF(O24<=50,"High","Very high"))))))
A25: Pod formation | B25: 13/03/2026 | C25: 36 | D25: 85 | E25: 27 | F25: D2V3 | G25: D2 | H25: V3 | I25: R2 | J25: Diseased | K25: 15 | L25: Mustard00304.asd.sco | M25: Mustard00318.asd.sco | P25: =IF(O25="","",IF(O25=0,"Healthy",IF(O25<=5,"Very low",IF(O25<=10,"Low",IF(O25<=25,"Moderate",IF(O25<=50,"High","Very high"))))))
A26: Pod formation | B26: 13/03/2026 | C26: 36 | D26: 76 | E26: 29 | F26: D3V3 | G26: D3 | H26: V3 | I26: R2 | J26: Diseased | K26: 15 | L26: Mustard00334.asd.sco | M26: Mustard00348.asd.sco | P26: =IF(O26="","",IF(O26=0,"Healthy",IF(O26<=5,"Very low",IF(O26<=10,"Low",IF(O26<=25,"Moderate",IF(O26<=50,"High","Very high"))))))
A27: Pod formation | B27: 13/03/2026 | C27: 36 | D27: 94 | E27: 30 | F27: D1V2 | G27: D1 | H27: V2 | I27: R2 | J27: Diseased | K27: 15 | L27: Mustard00349.asd.sco | M27: Mustard00363.asd.sco | P27: =IF(O27="","",IF(O27=0,"Healthy",IF(O27<=5,"Very low",IF(O27<=10,"Low",IF(O27<=25,"Moderate",IF(O27<=50,"High","Very high"))))))
... A29: Pod formation | B29: 13/03/2026 | C29: 36 | D29: 76 | E29: 32 | F29: D3V2 | G29: D3 | H29: V2 | I29: R2 | J29: Diseased | K29: 15 | L29: Mustard00379.asd.sco | M29: Mustard00393.asd.sco | P29: =IF(O29="","",IF(O29=0,"Healthy",IF(O29<=5,"Very low",IF(O29<=10,"Low",IF(O29<=25,"Moderate",IF(O29<=50,"High","Very high"))))))
A30: Pod formation | B30: 13/03/2026 | C30: 36 | D30: 94 | E30: 34 | F30: D1V1 | G30: D1 | H30: V1 | I30: R2 | J30: Diseased | K30: 15 | L30: Mustard00016.asd.sco | M30: Mustard00030.asd.sco | N30: 15 spectra were duplicated in the file; copies removed | P30: =IF(O30="","",IF(O30=0,"Healthy",IF(O30<=5,"Very low",IF(O30<=10,"Low",IF(O30<=25,"Moderate",IF(O30<=50,"High","Very high"))))))
A31: Pod formation | B31: 13/03/2026 | C31: 36 | D31: 85 | E31: 35 | F31: D2V2 | G31: D2 | H31: V2 | I31: R2 | J31: Diseased | K31: 15 | L31: Mustard00409.asd.sco | M31: Mustard00423.asd.sco | P31: =IF(O31="","",IF(O31=0,"Healthy",IF(O31<=5,"Very low",IF(O31<=10,"Low",IF(O31<=25,"Moderate",IF(O31<=50,"High","Very high"))))))
A32: Pod formation | B32: 13/03/2026 | C32: 36 | D32: 76 | E32: 36 | F32: D3V1 | G32: D3 | H32: V1 | I32: R2 | J32: Diseased | K32: 15 | L32: Mustard00424.asd.sco | M32: Mustard00438.asd.sco | P32: =IF(O32="","",IF(O32=0,"Healthy",IF(O32<=5,"Very low",IF(O32<=10,"Low",IF(O32<=25,"Moderate",IF(O32<=50,"High","Very high"))))))
A33: Pod formation | B33: 13/03/2026 | C33: 36 | D33: 76 | E33: 37 | F33: D3V1 | G33: D3 | H33: V1 | I33: R1 | J33: Diseased | K33: 15 | L33: Mustard00439.asd.sco | M33: Mustard00453.asd.sco | P33: =IF(O33="","",IF(O33=0,"Healthy",IF(O33<=5,"Very low",IF(O33<=10,"Low",IF(O33<=25,"Moderate",IF(O33<=50,"High","Very high"))))))
A34: Pod formation | B34: 13/03/2026 | C34: 36 | D34: 94 | E34: 38 | F34: D1V3 | G34: D1 | H34: V3 | I34: R1 | J34: Diseased | K34: 15 | L34: Mustard00031.asd.sco | M34: Mustard00045.asd.sco | N34: 15 spectra were duplicated in the file; copies removed | P34: =IF(O34="","",IF(O34=0,"Healthy",IF(O34<=5,"Very low",IF(O34<=10,"Low",IF(O34<=25,"Moderate",IF(O34<=50,"High","Very high"))))))
A35: Pod formation | B35: 13/03/2026 | C35: 36 | D35: 85 | E35: 39 | F35: D2V2 | G35: D2 | H35: V2 | I35: R1 | J35: Diseased | K35: 15 | L35: Mustard00454.asd.sco | M35: Mustard00468.asd.sco | P35: =IF(O35="","",IF(O35=0,"Healthy",IF(O35<=5,"Very low",IF(O35<=10,"Low",IF(O35<=25,"Moderate",IF(O35<=50,"High","Very high"))))))
A36: Pod formation | B36: 13/03/2026 | C36: 36 | D36: 85 | E36: 40 | F36: D2V3 | G36: D2 | H36: V3 | I36: R1 | J36: Diseased | K36: 15 | L36: Mustard00469.asd.sco | M36: Mustard00483.asd.sco | P36: =IF(O36="","",IF(O36=0,"Healthy",IF(O36<=5,"Very low",IF(O36<=10,"Low",IF(O36<=25,"Moderate",IF(O36<=50,"High","Very high"))))))
A37: Pod formation | B37: 13/03/2026 | C37: 36 | D37: 94 | E37: 41 | F37: D1V1 | G37: D1 | H37: V1 | I37: R1 | J37: Diseased | K37: 15 | L37: Mustard00046.asd.sco | M37: Mustard00060.asd.sco | N37: 15 spectra were duplicated in the file; copies removed | P37: =IF(O37="","",IF(O37=0,"Healthy",IF(O37<=5,"Very low",IF(O37<=10,"Low",IF(O37<=25,"Moderate",IF(O37<=50,"High","Very high"))))))
A38: Pod formation | B38: 13/03/2026 | C38: 36 | D38: 94 | E38: 42 | F38: D1V2 | G38: D1 | H38: V2 | I38: R1 | J38: Diseased | K38: 15 | L38: Mustard00061.asd.sco | M38: Mustard00075.asd.sco | N38: 15 spectra were duplicated in the file; copies removed | P38: =IF(O38="","",IF(O38=0,"Healthy",IF(O38<=5,"Very low",IF(O38<=10,"Low",IF(O38<=25,"Moderate",IF(O38<=50,"High","Very high"))))))
A39: Pod formation | B39: 13/03/2026 | C39: 36 | D39: 85 | E39: 43 | F39: D2V1 | G39: D2 | H39: V1 | I39: R1 | J39: Diseased | K39: 15 | L39: Mustard00484.asd.sco | M39: Mustard00498.asd.sco | P39: =IF(O39="","",IF(O39=0,"Healthy",IF(O39<=5,"Very low",IF(O39<=10,"Low",IF(O39<=25,"Moderate",IF(O39<=50,"High","Very high"))))))
A40: Pod formation | B40: 13/03/2026 | C40: 36 | D40: 76 | E40: 44 | F40: D3V2 | G40: D3 | H40: V2 | I40: R1 | J40: Diseased | K40: 15 | L40: Mustard00499.asd.sco | M40: Mustard00513.asd.sco | P40: =IF(O40="","",IF(O40=0,"Healthy",IF(O40<=5,"Very low",IF(O40<=10,"Low",IF(O40<=25,"Moderate",IF(O40<=50,"High","Very high"))))))
A41: Pod formation | B41: 13/03/2026 | C41: 36 | D41: 76 | E41: 48 | F41: D3V3 | G41: D3 | H41: V3 | I41: R1 | J41: Diseased | K41: 15 | L41: Mustard00559.asd.sco | M41: Mustard00573.asd.sco | P41: =IF(O41="","",IF(O41=0,"Healthy",IF(O41<=5,"Very low",IF(O41<=10,"Low",IF(O41<=25,"Moderate",IF(O41<=50,"High","Very high"))))))

Sheet Summary
A1: Counts by formula from All_plot_dates
A3: Growth stage | B3: Assessment date | C3: Plots healthy | D3: Plots diseased | E3: Spectra healthy | F3: Spectra diseased | G3: Spectra total
A4: Vegetative | B4: 11/02/2026 | C4: =COUNTIFS(All_plot_dates!$A:$A,A4,All_plot_dates!$B:$B,B4,All_plot_dates!$J:$J,"Healthy") -> 11 | D4: =COUNTIFS(All_plot_dates!$A:$A,A4,All_plot_dates!$B:$B,B4,All_plot_dates!$J:$J,"Diseased") -> 33 | E4: =SUMIFS(All_plot_dates!$K:$K,All_plot_dates!$A:$A,A4,All_plot_dates!$B:$B,B4,All_plot_dates!$J:$J,"Healthy") -> 63 | F4: =SUMIFS(All_plot_dates!$K:$K,All_plot_dates!$A:$A,A4,All_plot_dates!$B:$B,B4,All_plot_dates!$J:$J,"Diseased") -> 311 | G4: =E4+F4 -> 374
A5: Vegetative | B5: 24/02/2026 | C5: =COUNTIFS(All_plot_dates!$A:$A,A5,All_plot_dates!$B:$B,B5,All_plot_dates!$J:$J,"Healthy") -> 5 | D5: =COUNTIFS(All_plot_dates!$A:$A,A5,All_plot_dates!$B:$B,B5,All_plot_dates!$J:$J,"Diseased") -> 15 | E5: =SUMIFS(All_plot_dates!$K:$K,All_plot_dates!$A:$A,A5,All_plot_dates!$B:$B,B5,All_plot_dates!$J:$J,"Healthy") -> 30 | F5: =SUMIFS(All_plot_dates!$K:$K,All_plot_dates!$A:$A,A5,All_plot_dates!$B:$B,B5,All_plot_dates!$J:$J,"Diseased") -> 160 | G5: =E5+F5 -> 190
A6: Flowering | B6: 11/02/2026 | C6: =COUNTIFS(All_plot_dates!$A:$A,A6,All_plot_dates!$B:$B,B6,All_plot_dates!$J:$J,"Healthy") -> 1 | D6: =COUNTIFS(All_plot_dates!$A:$A,A6,All_plot_dates!$B:$B,B6,All_plot_dates!$J:$J,"Diseased") -> 3 | E6: =SUMIFS(All_plot_dates!$K:$K,All_plot_dates!$A:$A,A6,All_plot_dates!$B:$B,B6,All_plot_dates!$J:$J,"Healthy") -> 9 | F6: =SUMIFS(All_plot_dates!$K:$K,All_plot_dates!$A:$A,A6,All_plot_dates!$B:$B,B6,All_plot_dates!$J:$J,"Diseased") -> 45 | G6: =E6+F6 -> 54
A7: Flowering | B7: 24/02/2026 | C7: =COUNTIFS(All_plot_dates!$A:$A,A7,All_plot_dates!$B:$B,B7,All_plot_dates!$J:$J,"Healthy") -> 7 | D7: =COUNTIFS(All_plot_dates!$A:$A,A7,All_plot_dates!$B:$B,B7,All_plot_dates!$J:$J,"Diseased") -> 21 | E7: =SUMIFS(All_plot_dates!$K:$K,All_plot_dates!$A:$A,A7,All_plot_dates!$B:$B,B7,All_plot_dates!$J:$J,"Healthy") -> 60 | F7: =SUMIFS(All_plot_dates!$K:$K,All_plot_dates!$A:$A,A7,All_plot_dates!$B:$B,B7,All_plot_dates!$J:$J,"Diseased") -> 290 | G7: =E7+F7 -> 350
A8: Flowering | B8: 03/03/2026 | C8: =COUNTIFS(All_plot_dates!$A:$A,A8,All_plot_dates!$B:$B,B8,All_plot_dates!$J:$J,"Healthy") -> 11 | D8: =COUNTIFS(All_plot_dates!$A:$A,A8,All_plot_dates!$B:$B,B8,All_plot_dates!$J:$J,"Diseased") -> 33 | E8: =SUMIFS(All_plot_dates!$K:$K,All_plot_dates!$A:$A,A8,All_plot_dates!$B:$B,B8,All_plot_dates!$J:$J,"Healthy") -> 99 | F8: =SUMIFS(All_plot_dates!$K:$K,All_plot_dates!$A:$A,A8,All_plot_dates!$B:$B,B8,All_plot_dates!$J:$J,"Diseased") -> 495 | G8: =E8+F8 -> 594
A9: Flowering | B9: 13/03/2026 | C9: =COUNTIFS(All_plot_dates!$A:$A,A9,All_plot_dates!$B:$B,B9,All_plot_dates!$J:$J,"Healthy") -> 3 | D9: =COUNTIFS(All_plot_dates!$A:$A,A9,All_plot_dates!$B:$B,B9,All_plot_dates!$J:$J,"Diseased") -> 9 | E9: =SUMIFS(All_plot_dates!$K:$K,All_plot_dates!$A:$A,A9,All_plot_dates!$B:$B,B9,All_plot_dates!$J:$J,"Healthy") -> 27 | F9: =SUMIFS(All_plot_dates!$K:$K,All_plot_dates!$A:$A,A9,All_plot_dates!$B:$B,B9,All_plot_dates!$J:$J,"Diseased") -> 135 | G9: =E9+F9 -> 162
A10: Pod formation | B10: 03/03/2026 | C10: =COUNTIFS(All_plot_dates!$A:$A,A10,All_plot_dates!$B:$B,B10,All_plot_dates!$J:$J,"Healthy") -> 1 | D10: =COUNTIFS(All_plot_dates!$A:$A,A10,All_plot_dates!$B:$B,B10,All_plot_dates!$J:$J,"Diseased") -> 3 | E10: =SUMIFS(All_plot_dates!$K:$K,All_plot_dates!$A:$A,A10,All_plot_dates!$B:$B,B10,All_plot_dates!$J:$J,"Healthy") -> 9 | F10: =SUMIFS(All_plot_dates!$K:$K,All_plot_dates!$A:$A,A10,All_plot_dates!$B:$B,B10,All_plot_dates!$J:$J,"Diseased") -> 45 | G10: =E10+F10 -> 54
A11: Pod formation | B11: 13/03/2026 | C11: =COUNTIFS(All_plot_dates!$A:$A,A11,All_plot_dates!$B:$B,B11,All_plot_dates!$J:$J,"Healthy") -> 9 | D11: =COUNTIFS(All_plot_dates!$A:$A,A11,All_plot_dates!$B:$B,B11,All_plot_dates!$J:$J,"Diseased") -> 27 | E11: =SUMIFS(All_plot_dates!$K:$K,All_plot_dates!$A:$A,A11,All_plot_dates!$B:$B,B11,All_plot_dates!$J:$J,"Healthy") -> 81 | F11: =SUMIFS(All_plot_dates!$K:$K,All_plot_dates!$A:$A,A11,All_plot_dates!$B:$B,B11,All_plot_dates!$J:$J,"Diseased") -> 405 | G11: =E11+F11 -> 486
A12: Total | C12: =SUM(C4:C11) -> 48 | D12: =SUM(D4:D11) -> 144 | E12: =SUM(E4:E11) -> 378 | F12: =SUM(F4:F11) -> 1886 | G12: =SUM(G4:G11) -> 2264
